Workbook

Sheet 食譜橫向排版
B2: {=XLOOKUP("拌拌咖哩",'食譜'!B:B,'食譜'!A:A,"")} | F2: {=XLOOKUP(F8,'食譜'!$B:$B,'食譜'!$F:$F,"")} -> 0.16 | J2: {=XLOOKUP(J8,'食譜'!$B:$B,'食譜'!$F:$F,"")} -> 0.19 | N2: {=XLOOKUP(N8,'食譜'!$B:$B,'食譜'!$F:$F,"")} -> 0.19 | R2: {=XLOOKUP(R8,'食譜'!$B:$B,'食譜'!$F:$F,"")} -> 0.19 | V2: {=XLOOKUP(V8,'食譜'!$B:$B,'食譜'!$F:$F,"")} -> 0.19 | Z2: {=XLOOKUP(Z8,'食譜'!$B:$B,'食譜'!$F:$F,"")} -> 0.19 | AD2: {=XLOOKUP(AD8,'食譜'!$B:$B,'食譜'!$F:$F,"")} -> 0.19 | AH2: {=XLOOKUP(AH8,'食譜'!$B:$B,'食譜'!$F:$F,"")} -> 0.19 | AL2: {=XLOOKUP(AL8,'食譜'!$B:$B,'食譜'!$F:$F,"")} -> 0.2 | AP2: {=XLOOKUP(AP8,'食譜'!$B:$B,'食譜'!$F:$F,"")} -> 0.21 | AT2: {=XLOOKUP(AT8,'食譜'!$B:$B,'食譜'!$F:$F,"")} -> 0.2 | AX2: {=XLOOKUP(AX8,'食譜'!$B:$B,'食譜'!$F:$F,"")} -> 0.25 | BB2: {=XLOOKUP(BB8,'食譜'!$B:$B,'食譜'!$F:$F,"")} -> 0.25 | BF2: {=XLOOKUP(BF8,'食譜'!$B:$B,'食譜'!$F:$F,"")} -> 0.35 | BJ2: {=XLOOKUP(BJ8,'食譜'!$B:$B,'食譜'!$F:$F,"")} -> 0.25 | BN2: {=XLOOKUP(BN8,'食譜'!$B:$B,'食譜'!$F:$F,"")} -> 0.25 | BR2: {=XLOOKUP(BR8,'食譜'!$B:$B,'食譜'!$F:$F,"")} -> 0.35 | BV2: {=XLOOKUP(BV8,'食譜'!$B:$B,'食譜'!$F:$F,"")} -> 0.48 | BZ2: {=XLOOKUP(BZ8,'食譜'!$B:$B,'食譜'!$F:$F,"")} -> 0.48 | CD2: {=XLOOKUP(CD8,'食譜'!$B:$B,'食譜'!$F:$F,"")} -> 0.48 | CH2: {=XLOOKUP(CH8,'食譜'!$B:$B,'食譜'!$F:$F,"")} -> 0.61 | CL2: {=XLOOKUP(CL8,'食譜'!$B:$B,'食譜'!$F:$F,"")} -> 0.61 | CP2: {=XLOOKUP(CP8,'食譜'!$B:$B,'食譜'!$F:$F,"")} -> 0.78 | DG2: {=XLOOKUP(DK2,'食材'!$B:$B,'食材'!$D:$D,"")} | DI2: {=XLOOKUP(DK2,'食材'!$B:$B,'食材'!$F:$F,"")} -> 90 | DK2: 特選蘋果
F4: {=XLOOKUP(F8,'食譜'!$B:$B,'食譜'!$H:$H,"")} -> 728 | J4: {=XLOOKUP(J8,'食譜'!$B:$B,'食譜'!$H:$H,"")} -> 814 | N4: {=XLOOKUP(N8,'食譜'!$B:$B,'食譜'!$H:$H,"")} -> 839 | R4: {=XLOOKUP(R8,'食譜'!$B:$B,'食譜'!$H:$H,"")} -> 856 | V4: {=XLOOKUP(V8,'食譜'!$B:$B,'食譜'!$H:$H,"")} -> 1910 | Z4: {=XLOOKUP(Z8,'食譜'!$B:$B,'食譜'!$H:$H,"")} -> 1942 | AD4: {=XLOOKUP(AD8,'食譜'!$B:$B,'食譜'!$H:$H,"")} -> 2078 | AH4: {=XLOOKUP(AH8,'食譜'!$B:$B,'食譜'!$H:$H,"")} -> 2150 | AL4: {=XLOOKUP(AL8,'食譜'!$B:$B,'食譜'!$H:$H,"")} -> 3181 | AP4: {=XLOOKUP(AP8,'食譜'!$B:$B,'食譜'!$H:$H,"")} -> 3372 | AT4: {=XLOOKUP(AT8,'食譜'!$B:$B,'食譜'!$H:$H,"")} -> 4162 | AX4: {=XLOOKUP(AX8,'食譜'!$B:$B,'食譜'!$H:$H,"")} -> 4523 | BB4: {=XLOOKUP(BB8,'食譜'!$B:$B,'食譜'!$H:$H,"")} -> 4670 | BF4: {=XLOOKUP(BF8,'食譜'!$B:$B,'食譜'!$H:$H,"")} -> 5702 | BJ4: {=XLOOKUP(BJ8,'食譜'!$B:$B,'食譜'!$H:$H,"")} -> 5900 | BN4: {=XLOOKUP(BN8,'食譜'!$B:$B,'食譜'!$H:$H,"")} -> 7483 | BR4: {=XLOOKUP(BR8,'食譜'!$B:$B,'食譜'!$H:$H,"")} -> 9010 | BV4: {=XLOOKUP(BV8,'食譜'!$B:$B,'食譜'!$H:$H,"")} -> 9445 | BZ4: {=XLOOKUP(BZ8,'食譜'!$B:$B,'食譜'!$H:$H,"")} -> 13690 | CD4: {=XLOOKUP(CD8,'食譜'!$B:$B,'食譜'!$H:$H,"")} -> 15621 | CH4: {=XLOOKUP(CH8,'食譜'!$B:$B,'食譜'!$H:$H,"")} -> 19061 | CL4: {=XLOOKUP(CL8,'食譜'!$B:$B,'食譜'!$H:$H,"")} -> 20655 | CP4: {=XLOOKUP(CP8,'食譜'!$B:$B,'食譜'!$H:$H,"")} -> 24802 | DG4: {=XLOOKUP(DK4,'食材'!$B:$B,'食材'!$D:$D,"")} | DI4: {=XLOOKUP(DK4,'食材'!$B:$B,'食材'!$F:$F,"")} -> 98 | DK4: 哞哞鮮奶
F5: {=XLOOKUP(F8,'食譜'!$B:$B,'食譜'!$A:$A,"")} | J5: {=XLOOKUP(J8,'食譜'!$B:$B,'食譜'!$A:$A,"")} | N5: {=XLOOKUP(N8,'食譜'!$B:$B,'食譜'!$A:$A,"")} | R5: {=XLOOKUP(R8,'食譜'!$B:$B,'食譜'!$A:$A,"")} | V5: {=XLOOKUP(V8,'食譜'!$B:$B,'食譜'!$A:$A,"")} | Z5: {=XLOOKUP(Z8,'食譜'!$B:$B,'食譜'!$A:$A,"")} | AD5: {=XLOOKUP(AD8,'食譜'!$B:$B,'食譜'!$A:$A,"")} | AH5: {=XLOOKUP(AH8,'食譜'!$B:$B,'食譜'!$A:$A,"")} | AL5: {=XLOOKUP(AL8,'食譜'!$B:$B,'食譜'!$A:$A,"")} | AP5: {=XLOOKUP(AP8,'食譜'!$B:$B,'食譜'!$A:$A,"")} | AT5: {=XLOOKUP(AT8,'食譜'!$B:$B,'食譜'!$A:$A,"")} | AX5: {=XLOOKUP(AX8,'食譜'!$B:$B,'食譜'!$A:$A,"")} | BB5: {=XLOOKUP(BB8,'食譜'!$B:$B,'食譜'!$A:$A,"")} | BF5: {=XLOOKUP(BF8,'食譜'!$B:$B,'食譜'!$A:$A,"")} | BJ5: {=XLOOKUP(BJ8,'食譜'!$B:$B,'食譜'!$A:$A,"")} | BN5: {=XLOOKUP(BN8,'食譜'!$B:$B,'食譜'!$A:$A,"")} | BR5: {=XLOOKUP(BR8,'食譜'!$B:$B,'食譜'!$A:$A,"")} | BV5: {=XLOOKUP(BV8,'食譜'!$B:$B,'食譜'!$A:$A,"")} | BZ5: {=XLOOKUP(BZ8,'食譜'!$B:$B,'食譜'!$A:$A,"")} | CD5: {=XLOOKUP(CD8,'食譜'!$B:$B,'食譜'!$A:$A,"")} | CH5: {=XLOOKUP(CH8,'食譜'!$B:$B,'食譜'!$A:$A,"")} | CL5: {=XLOOKUP(CL8,'食譜'!$B:$B,'食譜'!$A:$A,"")} | CP5: {=XLOOKUP(CP8,'食譜'!$B:$B,'食譜'!$A:$A,"")}
DG6: {=XLOOKUP(DK6,'食材'!$B:$B,'食材'!$D:$D,"")} | DI6: {=XLOOKUP(DK6,'食材'!$B:$B,'食材'!$F:$F,"")} -> 100 | DK6: 萌綠大豆
F8: =IFERROR(__xludf.DUMMYFUNCTION("SPLIT(TEXTJOIN("""",TRUE,TOROW(FILTER('食譜'!$B:$B&""----"", '食譜'!$E:$E=""咖哩、濃湯"",'食譜'!$B:$B<>""拌拌咖哩"")),"""","""",""""),""-"",TRUE,FALSE)"),"特選蘋果咖哩") -> 特選蘋果咖哩 | J8: =IFERROR(__xludf.DUMMYFUNCTION("""COMPUTED_VALUE"""),"單純白醬濃湯") -> 單純白醬濃湯 | N8: =IFERROR(__xludf.DUMMYFUNCTION("""COMPUTED_VALUE"""),"寶寶甜蜜咖哩") -> 寶寶甜蜜咖哩 | R8: =IFERROR(__xludf.DUMMYFUNCTION("""COMPUTED_VALUE"""),"豆製肉排咖哩") -> 豆製肉排咖哩 | V8: =IFERROR(__xludf.DUMMYFUNCTION("""COMPUTED_VALUE"""),"吃飽飽起司肉排咖哩") -> 吃飽飽起司肉排咖哩 | Z8: =IFERROR(__xludf.DUMMYFUNCTION("""COMPUTED_VALUE"""),"日照炸肉排咖哩") -> 日照炸肉排咖哩 | AD8: =IFERROR(__xludf.DUMMYFUNCTION("""COMPUTED_VALUE"""),"太陽之力番茄咖哩") -> 太陽之力番茄咖哩 | AH8: =IFERROR(__xludf.DUMMYFUNCTION("""COMPUTED_VALUE"""),"入口即化蛋捲咖哩") -> 入口即化蛋捲咖哩 | AL8: =IFERROR(__xludf.DUMMYFUNCTION("""COMPUTED_VALUE"""),"窩心白醬濃湯") -> 窩心白醬濃湯 | AP8: =IFERROR(__xludf.DUMMYFUNCTION("""COMPUTED_VALUE"""),"健美豆子咖哩") -> 健美豆子咖哩 | AT8: =IFERROR(__xludf.DUMMYFUNCTION("""COMPUTED_VALUE"""),"蘑菇孢子咖哩") -> 蘑菇孢子咖哩 | AX8: =IFERROR(__xludf.DUMMYFUNCTION("""COMPUTED_VALUE"""),"親子愛咖哩") -> 親子愛咖哩 | BB8: =IFERROR(__xludf.DUMMYFUNCTION("""COMPUTED_VALUE"""),"柔軟玉米濃湯") -> 柔軟玉米濃湯 | BF8: =IFERROR(__xludf.DUMMYFUNCTION("""COMPUTED_VALUE"""),"迷昏拳辣味咖哩") -> 迷昏拳辣味咖哩 | BJ8: =IFERROR(__xludf.DUMMYFUNCTION("""COMPUTED_VALUE"""),"辣味蔥勁十足咖哩") -> 辣味蔥勁十足咖哩 | BN8: =IFERROR(__xludf.DUMMYFUNCTION("""COMPUTED_VALUE"""),"炙燒尾肉咖哩") -> 炙燒尾肉咖哩 | BR8: =IFERROR(__xludf.DUMMYFUNCTION("""COMPUTED_VALUE"""),"絕對睡眠奶油咖哩") -> 絕對睡眠奶油咖哩 | BV8: =IFERROR(__xludf.DUMMYFUNCTION("""COMPUTED_VALUE"""),"忍者咖哩") -> 忍者咖哩 | BZ8: =IFERROR(__xludf.DUMMYFUNCTION("""COMPUTED_VALUE"""),"煉獄玉米乾咖哩") -> 煉獄玉米乾咖哩 | CD8: =IFERROR(__xludf.DUMMYFUNCTION("""COMPUTED_VALUE"""),"扮演南瓜精濃湯") -> 扮演南瓜精濃湯 | CH8: =IFERROR(__xludf.DUMMYFUNCTION("""COMPUTED_VALUE"""),"覺醒力量濃湯") -> 覺醒力量濃湯 | CL8: =IFERROR(__xludf.DUMMYFUNCTION("""COMPUTED_VALUE"""),"居合斬壽喜燒咖哩") -> 居合斬壽喜燒咖哩 | CP8: =IFERROR(__xludf.DUMMYFUNCTION("""COMPUTED_VALUE"""),"茂盛焗烤酪梨") -> 茂盛焗烤酪梨 | DG8: {=XLOOKUP(DK8,'食材'!$B:$B,'食材'!$D:$D,"")} | DI8: {=XLOOKUP(DK8,'食材'!$B:$B,'食材'!$F:$F,"")} -> 101 | DK8: 甜甜蜜
F10: {=XLOOKUP(XLOOKUP(F8,'食譜'!$B:$B,'食譜'!$J:$J,""),'食材'!$B:$B,'食材'!$D:$D,"")} | H10: {=XLOOKUP(F8,'食譜'!$B:$B,'食譜'!$K:$K,"")} -> 7 | J10: {=XLOOKUP(XLOOKUP(J8,'食譜'!$B:$B,'食譜'!$J:$J,""),'食材'!$B:$B,'食材'!$D:$D,"")} | L10: {=XLOOKUP(J8,'食譜'!$B:$B,'食譜'!$K:$K,"")} -> 7 | N10: {=XLOOKUP(XLOOKUP(N8,'食譜'!$B:$B,'食譜'!$J:$J,""),'食材'!$B:$B,'食材'!$D:$D,"")} | P10: {=XLOOKUP(N8,'食譜'!$B:$B,'食譜'!$K:$K,"")} -> 7 | R10: {=XLOOKUP(XLOOKUP(R8,'食譜'!$B:$B,'食譜'!$J:$J,""),'食材'!$B:$B,'食材'!$D:$D,"")} | T10: {=XLOOKUP(R8,'食譜'!$B:$B,'食譜'!$K:$K,"")} -> 7 | V10: {=XLOOKUP(XLOOKUP(V8,'食譜'!$B:$B,'食譜'!$J:$J,""),'食材'!$B:$B,'食材'!$D:$D,"")} | X10: {=XLOOKUP(V8,'食譜'!$B:$B,'食譜'!$K:$K,"")} -> 8 | Z10: {=XLOOKUP(XLOOKUP(Z8,'食譜'!$B:$B,'食譜'!$J:$J,""),'食材'!$B:$B,'食材'!$D:$D,"")} | AB10: {=XLOOKUP(Z8,'食譜'!$B:$B,'食譜'!$K:$K,"")} -> 10 | AD10: {=XLOOKUP(XLOOKUP(AD8,'食譜'!$B:$B,'食譜'!$J:$J,""),'食材'!$B:$B,'食材'!$D:$D,"")} | AF10: {=XLOOKUP(AD8,'食譜'!$B:$B,'食譜'!$K:$K,"")} -> 10 | AH10: {=XLOOKUP(XLOOKUP(AH8,'食譜'!$B:$B,'食譜'!$J:$J,""),'食材'!$B:$B,'食材'!$D:$D,"")} | AJ10: {=XLOOKUP(AH8,'食譜'!$B:$B,'食譜'!$K:$K,"")} -> 10 | AL10: {=XLOOKUP(XLOOKUP(AL8,'食譜'!$B:$B,'食譜'!$J:$J,""),'食材'!$B:$B,'食材'!$D:$D,"")} | AN10: {=XLOOKUP(AL8,'食譜'!$B:$B,'食譜'!$K:$K,"")} -> 10 | AP10: {=XLOOKUP(XLOOKUP(AP8,'食譜'!$B:$B,'食譜'!$J:$J,""),'食材'!$B:$B,'食材'!$D:$D,"")} | AR10: {=XLOOKUP(AP8,'食譜'!$B:$B,'食譜'!$K:$K,"")} -> 12 | AT10: {=XLOOKUP(XLOOKUP(AT8,'食譜'!$B:$B,'食譜'!$J:$J,""),'食材'!$B:$B,'食材'!$D:$D,"")} | AV10: {=XLOOKUP(AT8,'食譜'!$B:$B,'食譜'!$K:$K,"")} -> 14 | AX10: {=XLOOKUP(XLOOKUP(AX8,'食譜'!$B:$B,'食譜'!$J:$J,""),'食材'!$B:$B,'食材'!$D:$D,"")} | AZ10: {=XLOOKUP(AX8,'食譜'!$B:$B,'食譜'!$K:$K,"")} -> 12 | BB10: {=XLOOKUP(XLOOKUP(BB8,'食譜'!$B:$B,'食譜'!$J:$J,""),'食材'!$B:$B,'食材'!$D:$D,"")} | BD10: {=XLOOKUP(BB8,'食譜'!$B:$B,'食譜'!$K:$K,"")} -> 14 | BF10: {=XLOOKUP(XLOOKUP(BF8,'食譜'!$B:$B,'食譜'!$J:$J,""),'食材'!$B:$B,'食材'!$D:$D,"")} | BH10: {=XLOOKUP(BF8,'食譜'!$B:$B,'食譜'!$K:$K,"")} -> 11 | BJ10: {=XLOOKUP(XLOOKUP(BJ8,'食譜'!$B:$B,'食譜'!$J:$J,""),'食材'!$B:$B,'食材'!$D:$D,"")} | BL10: {=XLOOKUP(BJ8,'食譜'!$B:$B,'食譜'!$K:$K,"")} -> 14 | BN10: {=XLOOKUP(XLOOKUP(BN8,'食譜'!$B:$B,'食譜'!$J:$J,""),'食材'!$B:$B,'食材'!$D:$D,"")} | BP10: {=XLOOKUP(BN8,'食譜'!$B:$B,'食譜'!$K:$K,"")} -> 25 | BR10: {=XLOOKUP(XLOOKUP(BR8,'食譜'!$B:$B,'食譜'!$J:$J,""),'食材'!$B:$B,'食材'!$D:$D,"")} | BT10: {=XLOOKUP(BR8,'食譜'!$B:$B,'食譜'!$K:$K,"")} -> 18 | BV10: {=XLOOKUP(XLOOKUP(BV8,'食譜'!$B:$B,'食譜'!$J:$J,""),'食材'!$B:$B,'食材'!$D:$D,"")} | BX10: {=XLOOKUP(BV8,'食譜'!$B:$B,'食譜'!$K:$K,"")} -> 24 | BZ10: {=XLOOKUP(XLOOKUP(BZ8,'食譜'!$B:$B,'食譜'!$J:$J,""),'食材'!$B:$B,'食材'!$D:$D,"")} | CB10: {=XLOOKUP(BZ8,'食譜'!$B:$B,'食譜'!$K:$K,"")} -> 27 | CD10: {=XLOOKUP(XLOOKUP(CD8,'食譜'!$B:$B,'食譜'!$J:$J,""),'食材'!$B:$B,'食材'!$D:$D,"")} | CF10: {=XLOOKUP(CD8,'食譜'!$B:$B,'食譜'!$K:$K,"")} -> 10 | CH10: {=XLOOKUP(XLOOKUP(CH8,'食譜'!$B:$B,'食譜'!$J:$J,""),'食材'!$B:$B,'食材'!$D:$D,"")} | CJ10: {=XLOOKUP(CH8,'食譜'!$B:$B,'食譜'!$K:$K,"")} -> 28 | CL10: {=XLOOKUP(XLOOKUP(CL8,'食譜'!$B:$B,'食譜'!$J:$J,""),'食材'!$B:$B,'食材'!$D:$D,"")} | CN10: {=XLOOKUP(CL8,'食譜'!$B:$B,'食譜'!$K:$K,"")} -> 27 | CP10: {=XLOOKUP(XLOOKUP(CP8,'食譜'!$B:$B,'食譜'!$J:$J,""),'食材'!$B:$B,'食材'!$D:$D,"")} | CR10: {=XLOOKUP(CP8,'食譜'!$B:$B,'食譜'!$K:$K,"")} -> 22 | DG10: {=XLOOKUP(DK10,'食材'!$B:$B,'食材'!$D:$D,"")} | DI10: {=XLOOKUP(DK10,'食材'!$B:$B,'食材'!$F:$F,"")} -> 103 | DK10: 豆製肉
F12: {=XLOOKUP(XLOOKUP(F8,'食譜'!$B:$B,'食譜'!$L:$L,""),'食材'!$B:$B,'食材'!$D:$D,"")} | H12: {=XLOOKUP(F8,'食譜'!$B:$B,'食譜'!$M:$M,"")} | J12: {=XLOOKUP(XLOOKUP(J8,'食譜'!$B:$B,'食譜'!$L:$L,""),'食材'!$B:$B,'食材'!$D:$D,"")} | L12: {=XLOOKUP(J8,'食譜'!$B:$B,'食譜'!$M:$M,"")} | N12: {=XLOOKUP(XLOOKUP(N8,'食譜'!$B:$B,'食譜'!$L:$L,""),'食材'!$B:$B,'食材'!$D:$D,"")} | P12: {=XLOOKUP(N8,'食譜'!$B:$B,'食譜'!$M:$M,"")} | R12: {=XLOOKUP(XLOOKUP(R8,'食譜'!$B:$B,'食譜'!$L:$L,""),'食材'!$B:$B,'食材'!$D:$D,"")} | T12: {=XLOOKUP(R8,'食譜'!$B:$B,'食譜'!$M:$M,"")} | V12: {=XLOOKUP(XLOOKUP(V8,'食譜'!$B:$B,'食譜'!$L:$L,""),'食材'!$B:$B,'食材'!$D:$D,"")} | X12: {=XLOOKUP(V8,'食譜'!$B:$B,'食譜'!$M:$M,"")} -> 8 | Z12: {=XLOOKUP(XLOOKUP(Z8,'食譜'!$B:$B,'食譜'!$L:$L,""),'食材'!$B:$B,'食材'!$D:$D,"")} | AB12: {=XLOOKUP(Z8,'食譜'!$B:$B,'食譜'!$M:$M,"")} -> 5 | AD12: {=XLOOKUP(XLOOKUP(AD8,'食譜'!$B:$B,'食譜'!$L:$L,""),'食材'!$B:$B,'食材'!$D:$D,"")} | AF12: {=XLOOKUP(AD8,'食譜'!$B:$B,'食譜'!$M:$M,"")} -> 5 | AH12: {=XLOOKUP(XLOOKUP(AH8,'食譜'!$B:$B,'食譜'!$L:$L,""),'食材'!$B:$B,'食材'!$D:$D,"")} | AJ12: {=XLOOKUP(AH8,'食譜'!$B:$B,'食譜'!$M:$M,"")} -> 6 | AL12: {=XLOOKUP(XLOOKUP(AL8,'食譜'!$B:$B,'食譜'!$L:$L,""),'食材'!$B:$B,'食材'!$D:$D,"")} | AN12: {=XLOOKUP(AL8,'食譜'!$B:$B,'食譜'!$M:$M,"")} -> 8 | AP12: {=XLOOKUP(XLOOKUP(AP8,'食譜'!$B:$B,'食譜'!$L:$L,""),'食材'!$B:$B,'食材'!$D:$D,"")} | AR12: {=XLOOKUP(AP8,'食譜'!$B:$B,'食譜'!$M:$M,"")} -> 6 | AT12: {=XLOOKUP(XLOOKUP(AT8,'食譜'!$B:$B,'食譜'!$L:$L,""),'食材'!$B:$B,'食材'!$D:$D,"")} | AV12: {=XLOOKUP(AT8,'食譜'!$B:$B,'食譜'!$M:$M,"")} -> 9 | AX12: {=XLOOKUP(XLOOKUP(AX8,'食譜'!$B:$B,'食譜'!$L:$L,""),'食材'!$B:$B,'食材'!$D:$D,"")} | AZ12: {=XLOOKUP(AX8,'食譜'!$B:$B,'食譜'!$M:$M,"")} -> 11 | BB12: {=XLOOKUP(XLOOKUP(BB8,'食譜'!$B:$B,'食譜'!$L:$L,""),'食材'!$B:$B,'食材'!$D:$D,"")} | BD12: {=XLOOKUP(BB8,'食譜'!$B:$B,'食譜'!$M:$M,"")} -> 8 | BF12: {=XLOOKUP(XLOOKUP(BF8,'食譜'!$B:$B,'食譜'!$L:$L,""),'食材'!$B:$B,'食材'!$D:$D,"")} | BH12: {=XLOOKUP(BF8,'食譜'!$B:$B,'食譜'!$M:$M,"")} -> 11 | BJ12: {=XLOOKUP(XLOOKUP(BJ8,'食譜'!$B:$B,'食譜'!$L:$L,""),'食材'!$B:$B,'食材'!$D:$D,"")} | BL12: {=XLOOKUP(BJ8,'食譜'!$B:$B,'食譜'!$M:$M,"")} -> 10 | BN12: {=XLOOKUP(XLOOKUP(BN8,'食譜'!$B:$B,'食譜'!$L:$L,""),'食材'!$B:$B,'食材'!$D:$D,"")} | BP12: {=XLOOKUP(BN8,'食譜'!$B:$B,'食譜'!$M:$M,"")} -> 8 | BR12: {=XLOOKUP(XLOOKUP(BR8,'食譜'!$B:$B,'食譜'!$L:$L,""),'食材'!$B:$B,'食材'!$D:$D,"")} | BT12: {=XLOOKUP(BR8,'食譜'!$B:$B,'食譜'!$M:$M,"")} -> 15 | BV12: {=XLOOKUP(XLOOKUP(BV8,'食譜'!$B:$B,'食譜'!$L:$L,""),'食材'!$B:$B,'食材'!$D:$D,"")} | BX12: {=XLOOKUP(BV8,'食譜'!$B:$B,'食譜'!$M:$M,"")} -> 12 | BZ12: {=XLOOKUP(XLOOKUP(BZ8,'食譜'!$B:$B,'食譜'!$L:$L,""),'食材'!$B:$B,'食材'!$D:$D,"")} | CB12: {=XLOOKUP(BZ8,'食譜'!$B:$B,'食譜'!$M:$M,"")} -> 24 | CD12: {=XLOOKUP(XLOOKUP(CD8,'食譜'!$B:$B,'食譜'!$L:$L,""),'食材'!$B:$B,'食材'!$D:$D,"")} | CF12: {=XLOOKUP(CD8,'食譜'!$B:$B,'食譜'!$M:$M,"")} -> 16 | CH12: {=XLOOKUP(XLOOKUP(CH8,'食譜'!$B:$B,'食譜'!$L:$L,""),'食材'!$B:$B,'食材'!$D:$D,"")} | CJ12: {=XLOOKUP(CH8,'食譜'!$B:$B,'食譜'!$M:$M,"")} -> 25 | CL12: {=XLOOKUP(XLOOKUP(CL8,'食譜'!$B:$B,'食譜'!$L:$L,""),'食材'!$B:$B,'食材'!$D:$D,"")} | CN12: {=XLOOKUP(CL8,'食譜'!$B:$B,'食譜'!$M:$M,"")} -> 26 | CP12: {=XLOOKUP(XLOOKUP(CP8,'食譜'!$B:$B,'食譜'!$L:$L,""),'食材'!$B:$B,'食材'!$D:$D,"")} | CR12: {=XLOOKUP(CP8,'食譜'!$B:$B,'食譜'!$M:$M,"")} -> 20 | DG12: {=XLOOKUP(DK12,'食材'!$B:$B,'食材'!$D:$D,"")} | DI12: {=XLOOKUP(DK12,'食材'!$B:$B,'食材'!$F:$F,"")} -> 109 | DK12: 暖暖薑
F14: {=XLOOKUP(XLOOKUP(F8,'食譜'!$B:$B,'食譜'!$N:$N,""),'食材'!$B:$B,'食材'!$D:$D,"")} | H14: {=XLOOKUP(F8,'食譜'!$B:$B,'食譜'!$O:$O,"")} | J14: {=XLOOKUP(XLOOKUP(J8,'食譜'!$B:$B,'食譜'!$N:$N,""),'食材'!$B:$B,'食材'!$D:$D,"")} | L14: {=XLOOKUP(J8,'食譜'!$B:$B,'食譜'!$O:$O,"")} | N14: {=XLOOKUP(XLOOKUP(N8,'食譜'!$B:$B,'食譜'!$N:$N,""),'食材'!$B:$B,'食材'!$D:$D,"")} | P14: {=XLOOKUP(N8,'食譜'!$B:$B,'食譜'!$O:$O,"")} | R14: {=XLOOKUP(XLOOKUP(R8,'食譜'!$B:$B,'食譜'!$N:$N,""),'食材'!$B:$B,'食材'!$D:$D,"")} | T14: {=XLOOKUP(R8,'食譜'!$B:$B,'食譜'!$O:$O,"")} | V14: {=XLOOKUP(XLOOKUP(V8,'食譜'!$B:$B,'食譜'!$N:$N,""),'食材'!$B:$B,'食材'!$D:$D,"")} | X14: {=XLOOKUP(V8,'食譜'!$B:$B,'食譜'!$O:$O,"")} | Z14: {=XLOOKUP(XLOOKUP(Z8,'食譜'!$B:$B,'食譜'!$N:$N,""),'食材'!$B:$B,'食材'!$D:$D,"")} | AB14: {=XLOOKUP(Z8,'食譜'!$B:$B,'食譜'!$O:$O,"")} | AD14: {=XLOOKUP(XLOOKUP(AD8,'食譜'!$B:$B,'食譜'!$N:$N,""),'食材'!$B:$B,'食材'!$D:$D,"")} | AF14: {=XLOOKUP(AD8,'食譜'!$B:$B,'食譜'!$O:$O,"")} | AH14: {=XLOOKUP(XLOOKUP(AH8,'食譜'!$B:$B,'食譜'!$N:$N,""),'食材'!$B:$B,'食材'!$D:$D,"")} | AJ14: {=XLOOKUP(AH8,'食譜'!$B:$B,'食譜'!$O:$O,"")} | AL14: {=XLOOKUP(XLOOKUP(AL8,'食譜'!$B:$B,'食譜'!$N:$N,""),'食材'!$B:$B,'食材'!$D:$D,"")} | AN14: {=XLOOKUP(AL8,'食譜'!$B:$B,'食譜'!$O:$O,"")} -> 4 | AP14: {=XLOOKUP(XLOOKUP(AP8,'食譜'!$B:$B,'食譜'!$N:$N,""),'食材'!$B:$B,'食材'!$D:$D,"")} | AR14: {=XLOOKUP(AP8,'食譜'!$B:$B,'食譜'!$O:$O,"")} -> 4 | AT14: {=XLOOKUP(XLOOKUP(AT8,'食譜'!$B:$B,'食譜'!$N:$N,""),'食材'!$B:$B,'食材'!$D:$D,"")} | AV14: {=XLOOKUP(AT8,'食譜'!$B:$B,'食譜'!$O:$O,"")} | AX14: {=XLOOKUP(XLOOKUP(AX8,'食譜'!$B:$B,'食譜'!$N:$N,""),'食材'!$B:$B,'食材'!$D:$D,"")} | AZ14: {=XLOOKUP(AX8,'食譜'!$B:$B,'食譜'!$O:$O,"")} -> 8 | BB14: {=XLOOKUP(XLOOKUP(BB8,'食譜'!$B:$B,'食譜'!$N:$N,""),'食材'!$B:$B,'食材'!$D:$D,"")} | BD14: {=XLOOKUP(BB8,'食譜'!$B:$B,'食譜'!$O:$O,"")} -> 8 | BF14: {=XLOOKUP(XLOOKUP(BF8,'食譜'!$B:$B,'食譜'!$N:$N,""),'食材'!$B:$B,'食材'!$D:$D,"")} | BH14: {=XLOOKUP(BF8,'食譜'!$B:$B,'食譜'!$O:$O,"")} -> 11 | BJ14: {=XLOOKUP(XLOOKUP(BJ8,'食譜'!$B:$B,'食譜'!$N:$N,""),'食材'!$B:$B,'食材'!$D:$D,"")} | BL14: {=XLOOKUP(BJ8,'食譜'!$B:$B,'食譜'!$O:$O,"")} -> 8 | BN14: {=XLOOKUP(XLOOKUP(BN8,'食譜'!$B:$B,'食譜'!$N:$N,""),'食材'!$B:$B,'食材'!$D:$D,"")} | BP14: {=XLOOKUP(BN8,'食譜'!$B:$B,'食譜'!$O:$O,"")} | BR14: {=XLOOKUP(XLOOKUP(BR8,'食譜'!$B:$B,'食譜'!$N:$N,""),'食材'!$B:$B,'食材'!$D:$D,"")} | BT14: {=XLOOKUP(BR8,'食譜'!$B:$B,'食譜'!$O:$O,"")} -> 12 | BV14: {=XLOOKUP(XLOOKUP(BV8,'食譜'!$B:$B,'食譜'!$N:$N,""),'食材'!$B:$B,'食材'!$D:$D,"")} | BX14: {=XLOOKUP(BV8,'食譜'!$B:$B,'食譜'!$O:$O,"")} -> 9 | BZ14: {=XLOOKUP(XLOOKUP(BZ8,'食譜'!$B:$B,'食譜'!$N:$N,""),'食材'!$B:$B,'食材'!$D:$D,"")} | CB14: {=XLOOKUP(BZ8,'食譜'!$B:$B,'食譜'!$O:$O,"")} -> 14 | CD14: {=XLOOKUP(XLOOKUP(CD8,'食譜'!$B:$B,'食譜'!$N:$N,""),'食材'!$B:$B,'食材'!$D:$D,"")} | CF14: {=XLOOKUP(CD8,'食譜'!$B:$B,'食譜'!$O:$O,"")} -> 18 | CH14: {=XLOOKUP(XLOOKUP(CH8,'食譜'!$B:$B,'食譜'!$N:$N,""),'食材'!$B:$B,'食材'!$D:$D,"")} | CJ14: {=XLOOKUP(CH8,'食譜'!$B:$B,'食譜'!$O:$O,"")} -> 23 | CL14: {=XLOOKUP(XLOOKUP(CL8,'食譜'!$B:$B,'食譜'!$N:$N,""),'食材'!$B:$B,'食材'!$D:$D,"")} | CN14: {=XLOOKUP(CL8,'食譜'!$B:$B,'食譜'!$O:$O,"")} -> 26 | CP14: {=XLOOKUP(XLOOKUP(CP8,'食譜'!$B:$B,'食譜'!$N:$N,""),'食材'!$B:$B,'食材'!$D:$D,"")} | CR14: {=XLOOKUP(CP8,'食譜'!$B:$B,'食譜'!$O:$O,"")} -> 41 | DG14: {=XLOOKUP(DK14,'食材'!$B:$B,'食材'!$D:$D,"")} | DI14: {=XLOOKUP(DK14,'食材'!$B:$B,'食材'!$F:$F,"")} -> 110 | DK14: 好眠番茄
F16: {=XLOOKUP(XLOOKUP(F8,'食譜'!$B:$B,'食譜'!$P:$P,""),'食材'!$B:$B,'食材'!$D:$D,"")} | H16: {=XLOOKUP(F8,'食譜'!$B:$B,'食譜'!$Q:$Q,"")} | J16: {=XLOOKUP(XLOOKUP(J8,'食譜'!$B:$B,'食譜'!$P:$P,""),'食材'!$B:$B,'食材'!$D:$D,"")} | L16: {=XLOOKUP(J8,'食譜'!$B:$B,'食譜'!$Q:$Q,"")} | N16: {=XLOOKUP(XLOOKUP(N8,'食譜'!$B:$B,'食譜'!$P:$P,""),'食材'!$B:$B,'食材'!$D:$D,"")} | P16: {=XLOOKUP(N8,'食譜'!$B:$B,'食譜'!$Q:$Q,"")} | R16: {=XLOOKUP(XLOOKUP(R8,'食譜'!$B:$B,'食譜'!$P:$P,""),'食材'!$B:$B,'食材'!$D:$D,"")} | T16: {=XLOOKUP(R8,'食譜'!$B:$B,'食譜'!$Q:$Q,"")} | V16: {=XLOOKUP(XLOOKUP(V8,'食譜'!$B:$B,'食譜'!$P:$P,""),'食材'!$B:$B,'食材'!$D:$D,"")} | X16: {=XLOOKUP(V8,'食譜'!$B:$B,'食譜'!$Q:$Q,"")} | Z16: {=XLOOKUP(XLOOKUP(Z8,'食譜'!$B:$B,'食譜'!$P:$P,""),'食材'!$B:$B,'食材'!$D:$D,"")} | AB16: {=XLOOKUP(Z8,'食譜'!$B:$B,'食譜'!$Q:$Q,"")} | AD16: {=XLOOKUP(XLOOKUP(AD8,'食譜'!$B:$B,'食譜'!$P:$P,""),'食材'!$B:$B,'食材'!$D:$D,"")} | AF16: {=XLOOKUP(AD8,'食譜'!$B:$B,'食譜'!$Q:$Q,"")} | AH16: {=XLOOKUP(XLOOKUP(AH8,'食譜'!$B:$B,'食譜'!$P:$P,""),'食材'!$B:$B,'食材'!$D:$D,"")} | AJ16: {=XLOOKUP(AH8,'食譜'!$B:$B,'食譜'!$Q:$Q,"")} | AL16: {=XLOOKUP(XLOOKUP(AL8,'食譜'!$B:$B,'食譜'!$P:$P,""),'食材'!$B:$B,'食材'!$D:$D,"")} | AN16: {=XLOOKUP(AL8,'食譜'!$B:$B,'食譜'!$Q:$Q,"")} | AP16: {=XLOOKUP(XLOOKUP(AP8,'食譜'!$B:$B,'食譜'!$P:$P,""),'食材'!$B:$B,'食材'!$D:$D,"")} | AR16: {=XLOOKUP(AP8,'食譜'!$B:$B,'食譜'!$Q:$Q,"")} -> 4 | AT16: {=XLOOKUP(XLOOKUP(AT8,'食譜'!$B:$B,'食譜'!$P:$P,""),'食材'!$B:$B,'食材'!$D:$D,"")} | AV16: {=XLOOKUP(AT8,'食譜'!$B:$B,'食譜'!$Q:$Q,"")} | AX16: {=XLOOKUP(XLOOKUP(AX8,'食譜'!$B:$B,'食譜'!$P:$P,""),'食材'!$B:$B,'食材'!$D:$D,"")} | AZ16: {=XLOOKUP(AX8,'食譜'!$B:$B,'食譜'!$Q:$Q,"")} -> 4 | BB16: {=XLOOKUP(XLOOKUP(BB8,'食譜'!$B:$B,'食譜'!$P:$P,""),'食材'!$B:$B,'食材'!$D:$D,"")} | BD16: {=XLOOKUP(BB8,'食譜'!$B:$B,'食譜'!$Q:$Q,"")} | BF16: {=XLOOKUP(XLOOKUP(BF8,'食譜'!$B:$B,'食譜'!$P:$P,""),'食材'!$B:$B,'食材'!$D:$D,"")} | BH16: {=XLOOKUP(BF8,'食譜'!$B:$B,'食譜'!$Q:$Q,"")} | BJ16: {=XLOOKUP(XLOOKUP(BJ8,'食譜'!$B:$B,'食譜'!$P:$P,""),'食材'!$B:$B,'食材'!$D:$D,"")} | BL16: {=XLOOKUP(BJ8,'食譜'!$B:$B,'食譜'!$Q:$Q,"")} | BN16: {=XLOOKUP(XLOOKUP(BN8,'食譜'!$B:$B,'食譜'!$P:$P,""),'食材'!$B:$B,'食材'!$D:$D,"")} | BP16: {=XLOOKUP(BN8,'食譜'!$B:$B,'食譜'!$Q:$Q,"")} | BR16: {=XLOOKUP(XLOOKUP(BR8,'食譜'!$B:$B,'食譜'!$P:$P,""),'食材'!$B:$B,'食材'!$D:$D,"")} | BT16: {=XLOOKUP(BR8,'食譜'!$B:$B,'食譜'!$Q:$Q,"")} -> 10 | BV16: {=XLOOKUP(XLOOKUP(BV8,'食譜'!$B:$B,'食譜'!$P:$P,""),'食材'!$B:$B,'食材'!$D:$D,"")} | BX16: {=XLOOKUP(BV8,'食譜'!$B:$B,'食譜'!$Q:$Q,"")} -> 5 | BZ16: {=XLOOKUP(XLOOKUP(BZ8,'食譜'!$B:$B,'食譜'!$P:$P,""),'食材'!$B:$B,'食材'!$D:$D,"")} | CB16: {=XLOOKUP(BZ8,'食譜'!$B:$B,'食譜'!$Q:$Q,"")} -> 12 | CD16: {=XLOOKUP(XLOOKUP(CD8,'食譜'!$B:$B,'食譜'!$P:$P,""),'食材'!$B:$B,'食材'!$D:$D,"")} | CF16: {=XLOOKUP(CD8,'食譜'!$B:$B,'食譜'!$Q:$Q,"")} -> 25 | CH16: {=XLOOKUP(XLOOKUP(CH8,'食譜'!$B:$B,'食譜'!$P:$P,""),'食材'!$B:$B,'食材'!$D:$D,"")} | CJ16: {=XLOOKUP(CH8,'食譜'!$B:$B,'食譜'!$Q:$Q,"")} -> 16 | CL16: {=XLOOKUP(XLOOKUP(CL8,'食譜'!$B:$B,'食譜'!$P:$P,""),'食材'!$B:$B,'食材'!$D:$D,"")} | CN16: {=XLOOKUP(CL8,'食譜'!$B:$B,'食譜'!$Q:$Q,"")} -> 22 | CP16: {=XLOOKUP(XLOOKUP(CP8,'食譜'!$B:$B,'食譜'!$P:$P,""),'食材'!$B:$B,'食材'!$D:$D,"")} | CR16: {=XLOOKUP(CP8,'食譜'!$B:$B,'食譜'!$Q:$Q,"")} -> 32 | DG16: {=XLOOKUP(DK16,'食材'!$B:$B,'食材'!$D:$D,"")} | DI16: {=XLOOKUP(DK16,'食材'!$B:$B,'食材'!$F:$F,"")} -> 115 | DK16: 特選蛋
F18: {=XLOOKUP(F8,'食譜'!$B:$B,'食譜'!$D:$D,"")} -> 7 | J18: {=XLOOKUP(J8,'食譜'!$B:$B,'食譜'!$D:$D,"")} -> 7 | N18: {=XLOOKUP(N8,'食譜'!$B:$B,'食譜'!$D:$D,"")} -> 7 | R18: {=XLOOKUP(R8,'食譜'!$B:$B,'食譜'!$D:$D,"")} -> 7 | V18: {=XLOOKUP(V8,'食譜'!$B:$B,'食譜'!$D:$D,"")} -> 16 | Z18: {=XLOOKUP(Z8,'食譜'!$B:$B,'食譜'!$D:$D,"")} -> 15 | AD18: {=XLOOKUP(AD8,'食譜'!$B:$B,'食譜'!$D:$D,"")} -> 15 | AH18: {=XLOOKUP(AH8,'食譜'!$B:$B,'食譜'!$D:$D,"")} -> 16 | AL18: {=XLOOKUP(AL8,'食譜'!$B:$B,'食譜'!$D:$D,"")} -> 22 | AP18: {=XLOOKUP(AP8,'食譜'!$B:$B,'食譜'!$D:$D,"")} -> 26 | AT18: {=XLOOKUP(AT8,'食譜'!$B:$B,'食譜'!$D:$D,"")} -> 23 | AX18: {=XLOOKUP(AX8,'食譜'!$B:$B,'食譜'!$D:$D,"")} -> 35 | BB18: {=XLOOKUP(BB8,'食譜'!$B:$B,'食譜'!$D:$D,"")} -> 30 | BF18: {=XLOOKUP(BF8,'食譜'!$B:$B,'食譜'!$D:$D,"")} -> 33 | BJ18: {=XLOOKUP(BJ8,'食譜'!$B:$B,'食譜'!$D:$D,"")} -> 32 | BN18: {=XLOOKUP(BN8,'食譜'!$B:$B,'食譜'!$D:$D,"")} -> 33 | BR18: {=XLOOKUP(BR8,'食譜'!$B:$B,'食譜'!$D:$D,"")} -> 55 | BV18: {=XLOOKUP(BV8,'食譜'!$B:$B,'食譜'!$D:$D,"")} -> 50 | BZ18: {=XLOOKUP(BZ8,'食譜'!$B:$B,'食譜'!$D:$D,"")} -> 77 | CD18: {=XLOOKUP(CD8,'食譜'!$B:$B,'食譜'!$D:$D,"")} -> 69 | CH18: {=XLOOKUP(CH8,'食譜'!$B:$B,'食譜'!$D:$D,"")} -> 92 | CL18: {=XLOOKUP(CL8,'食譜'!$B:$B,'食譜'!$D:$D,"")} -> 101 | CP18: {=XLOOKUP(CP8,'食譜'!$B:$B,'食譜'!$D:$D,"")} -> 115 | DG18: {=XLOOKUP(DK18,'食材'!$B:$B,'食材'!$D:$D,"")} | DI18: {=XLOOKUP(DK18,'食材'!$B:$B,'食材'!$F:$F,"")} -> 121 | DK18: 純粹油
DG20: {=XLOOKUP(DK20,'食材'!$B:$B,'食材'!$D:$D,"")} | DI20: {=XLOOKUP(DK20,'食材'!$B:$B,'食材'!$F:$F,"")} -> 124 | DK20: 窩心洋芋
B22: {=XLOOKUP("拌拌沙拉",'食譜'!B:B,'食譜'!A:A,"")} | F22: {=XLOOKUP(F28,'食譜'!$B:$B,'食譜'!$F:$F,"")} -> 0.19 | J22: {=XLOOKUP(J28,'食譜'!$B:$B,'食譜'!$F:$F,"")} -> 0.19 | N22: {=XLOOKUP(N28,'食譜'!$B:$B,'食譜'!$F:$F,"")} -> 0.19 | R22: {=XLOOKUP(R28,'食譜'!$B:$B,'食譜'!$F:$F,"")} -> 0.19 | V22: {=XLOOKUP(V28,'食譜'!$B:$B,'食譜'!$F:$F,"")} -> 0.19 | Z22: {=XLOOKUP(Z28,'食譜'!$B:$B,'食譜'!$F:$F,"")} -> 0.21 | AD22: {=XLOOKUP(AD28,'食譜'!$B:$B,'食譜'!$F:$F,"")} -> 0.25 | AH22: {=XLOOKUP(AH28,'食譜'!$B:$B,'食譜'!$F:$F,"")} -> 0.19 | AL22: {=XLOOKUP(AL28,'食譜'!$B:$B,'食譜'!$F:$F,"")} -> 0.21 | AP22: {=XLOOKUP(AP28,'食譜'!$B:$B,'食譜'!$F:$F,"")} -> 0.2 | AT22: {=XLOOKUP(AT28,'食譜'!$B:$B,'食譜'!$F:$F,"")} -> 0.25 | AX22: {=XLOOKUP(AX28,'食譜'!$B:$B,'食譜'!$F:$F,"")} -> 0.21 | BB22: {=XLOOKUP(BB28,'食譜'!$B:$B,'食譜'!$F:$F,"")} -> 0.25 | BF22: {=XLOOKUP(BF28,'食譜'!$B:$B,'食譜'!$F:$F,"")} -> 0.25 | BJ22: {=XLOOKUP(BJ28,'食譜'!$B:$B,'食譜'!$F:$F,"")} -> 0.25 | BN22: {=XLOOKUP(BN28,'食譜'!$B:$B,'食譜'!$F:$F,"")} -> 0.35 | BR22: {=XLOOKUP(BR28,'食譜'!$B:$B,'食譜'!$F:$F,"")} -> 0.48 | BV22: {=XLOOKUP(BV28,'食譜'!$B:$B,'食譜'!$F:$F,"")} -> 0.25 | BZ22: {=XLOOKUP(BZ28,'食譜'!$B:$B,'食譜'!$F:$F,"")} -> 0.35 | CD22: {=XLOOKUP(CD28,'食譜'!$B:$B,'食譜'!$F:$F,"")} -> 0.48 | CH22: {=XLOOKUP(CH28,'食譜'!$B:$B,'食譜'!$F:$F,"")} -> 0.48 | CL22: {=XLOOKUP(CL28,'食譜'!$B:$B,'食譜'!$F:$F,"")} -> 0.48 | CP22: {=XLOOKUP(CP28,'食譜'!$B:$B,'食譜'!$F:$F,"")} -> 0.78 | CT22: {=XLOOKUP(CT28,'食譜'!$B:$B,'食譜'!$F:$F,"")} -> 0.61 | CX22: {=XLOOKUP(CX28,'食譜'!$B:$B,'食譜'!$F:$F,"")} -> 0.78 | DB22: {=XLOOKUP(DB28,'食譜'!$B:$B,'食譜'!$F:$F,"")} -> 0.61 | DG22: {=XLOOKUP(DK22,'食材'!$B:$B,'食材'!$D:$D,"")} | DI22: {=XLOOKUP(DK22,'食材'!$B:$B,'食材'!$F:$F,"")} -> 130 | DK22: 火辣香草
F24: {=XLOOKUP(F28,'食譜'!$B:$B,'食譜'!$H:$H,"")} -> 855 | J24: {=XLOOKUP(J28,'食譜'!$B:$B,'食譜'!$H:$H,"")} -> 978 | N24: {=XLOOKUP(N28,'食譜'!$B:$B,'食譜'!$H:$H,"")} -> 1045 | R24: {=XLOOKUP(R28,'食譜'!$B:$B,'食譜'!$H:$H,"")} -> 1898 | V24: {=XLOOKUP(V28,'食譜'!$B:$B,'食譜'!$H:$H,"")} -> 2114 | Z24: {=XLOOKUP(Z28,'食譜'!$B:$B,'食譜'!$H:$H,"")} -> 2655 | AD24: {=XLOOKUP(AD28,'食譜'!$B:$B,'食譜'!$H:$H,"")} -> 2785 | AH24: {=XLOOKUP(AH28,'食譜'!$B:$B,'食譜'!$H:$H,"")} -> 2845 | AL24: {=XLOOKUP(AL28,'食譜'!$B:$B,'食譜'!$H:$H,"")} -> 2942 | AP24: {=XLOOKUP(AP28,'食譜'!$B:$B,'食譜'!$H:$H,"")} -> 3046 | AT24: {=XLOOKUP(AT28,'食譜'!$B:$B,'食譜'!$H:$H,"")} -> 3113 | AX24: {=XLOOKUP(AX28,'食譜'!$B:$B,'食譜'!$H:$H,"")} -> 3665 | BB24: {=XLOOKUP(BB28,'食譜'!$B:$B,'食譜'!$H:$H,"")} -> 5040 | BF24: {=XLOOKUP(BF28,'食譜'!$B:$B,'食譜'!$H:$H,"")} -> 5225 | BJ24: {=XLOOKUP(BJ28,'食譜'!$B:$B,'食譜'!$H:$H,"")} -> 5859 | BN24: {=XLOOKUP(BN28,'食譜'!$B:$B,'食譜'!$H:$H,"")} -> 7125 | BR24: {=XLOOKUP(BR28,'食譜'!$B:$B,'食譜'!$H:$H,"")} -> 7675 | BV24: {=XLOOKUP(BV28,'食譜'!$B:$B,'食譜'!$H:$H,"")} -> 8169 | BZ24: {=XLOOKUP(BZ28,'食譜'!$B:$B,'食譜'!$H:$H,"")} -> 8755 | CD24: {=XLOOKUP(CD28,'食譜'!$B:$B,'食譜'!$H:$H,"")} -> 11393 | CH24: {=XLOOKUP(CH28,'食譜'!$B:$B,'食譜'!$H:$H,"")} -> 11659 | CL24: {=XLOOKUP(CL28,'食譜'!$B:$B,'食譜'!$H:$H,"")} -> 11881 | CP24: {=XLOOKUP(CP28,'食譜'!$B:$B,'食譜'!$H:$H,"")} -> 19293 | CT24: {=XLOOKUP(CT28,'食譜'!$B:$B,'食譜'!$H:$H,"")} -> 20218 | CX24: {=XLOOKUP(CX28,'食譜'!$B:$B,'食譜'!$H:$H,"")} -> 25162 | DB24: {=XLOOKUP(DB28,'食譜'!$B:$B,'食譜'!$H:$H,"")} -> 25356 | DG24: {=XLOOKUP(DK24,'食材'!$B:$B,'食材'!$D:$D,"")} | DI24: {=XLOOKUP(DK24,'食材'!$B:$B,'食材'!$F:$F,"")} -> 140 | DK24: 萌綠玉米
F25: {=XLOOKUP(F28,'食譜'!$B:$B,'食譜'!$A:$A,"")} | J25: {=XLOOKUP(J28,'食譜'!$B:$B,'食譜'!$A:$A,"")} | N25: {=XLOOKUP(N28,'食譜'!$B:$B,'食譜'!$A:$A,"")} | R25: {=XLOOKUP(R28,'食譜'!$B:$B,'食譜'!$A:$A,"")} | V25: {=XLOOKUP(V28,'食譜'!$B:$B,'食譜'!$A:$A,"")} | Z25: {=XLOOKUP(Z28,'食譜'!$B:$B,'食譜'!$A:$A,"")} | AD25: {=XLOOKUP(AD28,'食譜'!$B:$B,'食譜'!$A:$A,"")} | AH25: {=XLOOKUP(AH28,'食譜'!$B:$B,'食譜'!$A:$A,"")} | AL25: {=XLOOKUP(AL28,'食譜'!$B:$B,'食譜'!$A:$A,"")} | AP25: {=XLOOKUP(AP28,'食譜'!$B:$B,'食譜'!$A:$A,"")} | AT25: {=XLOOKUP(AT28,'食譜'!$B:$B,'食譜'!$A:$A,"")} | AX25: {=XLOOKUP(AX28,'食譜'!$B:$B,'食譜'!$A:$A,"")} | BB25: {=XLOOKUP(BB28,'食譜'!$B:$B,'食譜'!$A:$A,"")} | BF25: {=XLOOKUP(BF28,'食譜'!$B:$B,'食譜'!$A:$A,"")} | BJ25: {=XLOOKUP(BJ28,'食譜'!$B:$B,'食譜'!$A:$A,"")} | BN25: {=XLOOKUP(BN28,'食譜'!$B:$B,'食譜'!$A:$A,"")} | BR25: {=XLOOKUP(BR28,'食譜'!$B:$B,'食譜'!$A:$A,"")} | BV25: {=XLOOKUP(BV28,'食譜'!$B:$B,'食譜'!$A:$A,"")} | BZ25: {=XLOOKUP(BZ28,'食譜'!$B:$B,'食譜'!$A:$A,"")} | CD25: {=XLOOKUP(CD28,'食譜'!$B:$B,'食譜'!$A:$A,"")} | CH25: {=XLOOKUP(CH28,'食譜'!$B:$B,'食譜'!$A:$A,"")} | CL25: {=XLOOKUP(CL28,'食譜'!$B:$B,'食譜'!$A:$A,"")} | CP25: {=XLOOKUP(CP28,'食譜'!$B:$B,'食譜'!$A:$A,"")} | CT25: {=XLOOKUP(CT28,'食譜'!$B:$B,'食譜'!$A:$A,"")} | CX25: {=XLOOKUP(CX28,'食譜'!$B:$B,'食譜'!$A:$A,"")} | DB25: {=XLOOKUP(DB28,'食譜'!$B:$B,'食譜'!$A:$A,"")}
DG26: {=XLOOKUP(DK26,'食材'!$B:$B,'食材'!$D:$D,"")} | DI26: {=XLOOKUP(DK26,'食材'!$B:$B,'食材'!$F:$F,"")} -> 151 | DK26: 放鬆可可
F28: =IFERROR(__xludf.DUMMYFUNCTION("SPLIT(TEXTJOIN("""",TRUE,TOROW(FILTER('食譜'!$B:$B&""----"", '食譜'!$E:$E=""沙拉"",'食譜'!$B:$B<>""拌拌沙拉"")),"""","""",""""),""-"",TRUE,FALSE)"),"特選蘋果沙拉") -> 特選蘋果沙拉 | J28: =IFERROR(__xludf.DUMMYFUNCTION("""COMPUTED_VALUE"""),"豆製火腿沙拉") -> 豆製火腿沙拉 | N28: =IFERROR(__xludf.DUMMYFUNCTION("""COMPUTED_VALUE"""),"好眠番茄沙拉") -> 好眠番茄沙拉 | R28: =IFERROR(__xludf.DUMMYFUNCTION("""COMPUTED_VALUE"""),"撥雪凱薩沙拉") -> 撥雪凱薩沙拉 | V28: =IFERROR(__xludf.DUMMYFUNCTION("""COMPUTED_VALUE"""),"熱風豆腐沙拉") -> 熱風豆腐沙拉 | Z28: =IFERROR(__xludf.DUMMYFUNCTION("""COMPUTED_VALUE"""),"迷人蘋果起司沙拉") -> 迷人蘋果起司沙拉 | AD28: =IFERROR(__xludf.DUMMYFUNCTION("""COMPUTED_VALUE"""),"亂擊玉米沙拉") -> 亂擊玉米沙拉 | AH28: =IFERROR(__xludf.DUMMYFUNCTION("""COMPUTED_VALUE"""),"免疫蔥花沙拉") -> 免疫蔥花沙拉 | AL28: =IFERROR(__xludf.DUMMYFUNCTION("""COMPUTED_VALUE"""),"哞哞起司番茄沙拉") -> 哞哞起司番茄沙拉 | AP28: =IFERROR(__xludf.DUMMYFUNCTION("""COMPUTED_VALUE"""),"蠻力豪邁沙拉") -> 蠻力豪邁沙拉 | AT28: =IFERROR(__xludf.DUMMYFUNCTION("""COMPUTED_VALUE"""),"濕潤豆腐沙拉") -> 濕潤豆腐沙拉 | AX28: =IFERROR(__xludf.DUMMYFUNCTION("""COMPUTED_VALUE"""),"心情不定肉沙拉淋巧克力醬") -> 心情不定肉沙拉淋巧克力醬 | BB28: =IFERROR(__xludf.DUMMYFUNCTION("""COMPUTED_VALUE"""),"貪吃鬼洋芋沙拉") -> 貪吃鬼洋芋沙拉 | BF28: =IFERROR(__xludf.DUMMYFUNCTION("""COMPUTED_VALUE"""),"過熱沙拉") -> 過熱沙拉 | BJ28: =IFERROR(__xludf.DUMMYFUNCTION("""COMPUTED_VALUE"""),"蘑菇孢子沙拉") -> 蘑菇孢子沙拉 | BN28: =IFERROR(__xludf.DUMMYFUNCTION("""COMPUTED_VALUE"""),"碎裂酪梨沙拉") -> 碎裂酪梨沙拉 | BR28: =IFERROR(__xludf.DUMMYFUNCTION("""COMPUTED_VALUE"""),"冥想香甜沙拉") -> 冥想香甜沙拉 | BV28: =IFERROR(__xludf.DUMMYFUNCTION("""COMPUTED_VALUE"""),"呆呆獸尾巴的胡椒沙拉") -> 呆呆獸尾巴的胡椒沙拉 | BZ28: =IFERROR(__xludf.DUMMYFUNCTION("""COMPUTED_VALUE"""),"十字切碎丁沙拉") -> 十字切碎丁沙拉 | CD28: =IFERROR(__xludf.DUMMYFUNCTION("""COMPUTED_VALUE"""),"萌綠沙拉") -> 萌綠沙拉 | CH28: =IFERROR(__xludf.DUMMYFUNCTION("""COMPUTED_VALUE"""),"忍者沙拉") -> 忍者沙拉 | CL28: =IFERROR(__xludf.DUMMYFUNCTION("""COMPUTED_VALUE"""),"落英繽紛含羞草蛋沙拉") -> 落英繽紛含羞草蛋沙拉 | CP28: =IFERROR(__xludf.DUMMYFUNCTION("""COMPUTED_VALUE"""),"蘋果酸優格沙拉") -> 蘋果酸優格沙拉 | CT28: =IFERROR(__xludf.DUMMYFUNCTION("""COMPUTED_VALUE"""),"不服輸咖啡沙拉") -> 不服輸咖啡沙拉 | CX28: =IFERROR(__xludf.DUMMYFUNCTION("""COMPUTED_VALUE"""),"重踏酪梨醬脆片") -> 重踏酪梨醬脆片 | DB28: =IFERROR(__xludf.DUMMYFUNCTION("""COMPUTED_VALUE"""),"大塊滿滿熱水沙拉") -> 大塊滿滿熱水沙拉 | DG28: {=XLOOKUP(DK28,'食材'!$B:$B,'食材'!$D:$D,"")} | DI28: {=XLOOKUP(DK28,'食材'!$B:$B,'食材'!$F:$F,"")} -> 153 | DK28: 醒腦咖啡豆
F30: {=XLOOKUP(XLOOKUP(F28,'食譜'!$B:$B,'食譜'!$J:$J,""),'食材'!$B:$B,'食材'!$D:$D,"")} | H30: {=XLOOKUP(F28,'食譜'!$B:$B,'食譜'!$K:$K,"")} -> 8 | J30: {=XLOOKUP(XLOOKUP(J28,'食譜'!$B:$B,'食譜'!$J:$J,""),'食材'!$B:$B,'食材'!$D:$D,"")} | L30: {=XLOOKUP(J28,'食譜'!$B:$B,'食譜'!$K:$K,"")} -> 8 | N30: {=XLOOKUP(XLOOKUP(N28,'食譜'!$B:$B,'食譜'!$J:$J,""),'食材'!$B:$B,'食材'!$D:$D,"")} | P30: {=XLOOKUP(N28,'食譜'!$B:$B,'食譜'!$K:$K,"")} -> 8 | R30: {=XLOOKUP(XLOOKUP(R28,'食譜'!$B:$B,'食譜'!$J:$J,""),'食材'!$B:$B,'食材'!$D:$D,"")} | T30: {=XLOOKUP(R28,'食譜'!$B:$B,'食譜'!$K:$K,"")} -> 10 | V30: {=XLOOKUP(XLOOKUP(V28,'食譜'!$B:$B,'食譜'!$J:$J,""),'食材'!$B:$B,'食材'!$D:$D,"")} | X30: {=XLOOKUP(V28,'食譜'!$B:$B,'食譜'!$K:$K,"")} -> 10 | Z30: {=XLOOKUP(XLOOKUP(Z28,'食譜'!$B:$B,'食譜'!$J:$J,""),'食材'!$B:$B,'食材'!$D:$D,"")} | AB30: {=XLOOKUP(Z28,'食譜'!$B:$B,'食譜'!$K:$K,"")} -> 15 | AD30: {=XLOOKUP(XLOOKUP(AD28,'食譜'!$B:$B,'食譜'!$J:$J,""),'食材'!$B:$B,'食材'!$D:$D,"")} | AF30: {=XLOOKUP(AD28,'食譜'!$B:$B,'食譜'!$K:$K,"")} -> 9 | AH30: {=XLOOKUP(XLOOKUP(AH28,'食譜'!$B:$B,'食譜'!$J:$J,""),'食材'!$B:$B,'食材'!$D:$D,"")} | AJ30: {=XLOOKUP(AH28,'食譜'!$B:$B,'食譜'!$K:$K,"")} -> 10 | AL30: {=XLOOKUP(XLOOKUP(AL28,'食譜'!$B:$B,'食譜'!$J:$J,""),'食材'!$B:$B,'食材'!$D:$D,"")} | AN30: {=XLOOKUP(AL28,'食譜'!$B:$B,'食譜'!$K:$K,"")} -> 12 | AP30: {=XLOOKUP(XLOOKUP(AP28,'食譜'!$B:$B,'食譜'!$J:$J,""),'食材'!$B:$B,'食材'!$D:$D,"")} | AR30: {=XLOOKUP(AP28,'食譜'!$B:$B,'食譜'!$K:$K,"")} -> 9 | AT30: {=XLOOKUP(XLOOKUP(AT28,'食譜'!$B:$B,'食譜'!$J:$J,""),'食材'!$B:$B,'食材'!$D:$D,"")} | AV30: {=XLOOKUP(AT28,'食譜'!$B:$B,'食譜'!$K:$K,"")} -> 15 | AX30: {=XLOOKUP(XLOOKUP(AX28,'食譜'!$B:$B,'食譜'!$J:$J,""),'食材'!$B:$B,'食材'!$D:$D,"")} | AZ30: {=XLOOKUP(AX28,'食譜'!$B:$B,'食譜'!$K:$K,"")} -> 14 | BB30: {=XLOOKUP(XLOOKUP(BB28,'食譜'!$B:$B,'食譜'!$J:$J,""),'食材'!$B:$B,'食材'!$D:$D,"")} | BD30: {=XLOOKUP(BB28,'食譜'!$B:$B,'食譜'!$K:$K,"")} -> 14 | BF30: {=XLOOKUP(XLOOKUP(BF28,'食譜'!$B:$B,'食譜'!$J:$J,""),'食材'!$B:$B,'食材'!$D:$D,"")} | BH30: {=XLOOKUP(BF28,'食譜'!$B:$B,'食譜'!$K:$K,"")} -> 17 | BJ30: {=XLOOKUP(XLOOKUP(BJ28,'食譜'!$B:$B,'食譜'!$J:$J,""),'食材'!$B:$B,'食材'!$D:$D,"")} | BL30: {=XLOOKUP(BJ28,'食譜'!$B:$B,'食譜'!$K:$K,"")} -> 17 | BN30: {=XLOOKUP(XLOOKUP(BN28,'食譜'!$B:$B,'食譜'!$J:$J,""),'食材'!$B:$B,'食材'!$D:$D,"")} | BP30: {=XLOOKUP(BN28,'食譜'!$B:$B,'食譜'!$K:$K,"")} -> 14 | BR30: {=XLOOKUP(XLOOKUP(BR28,'食譜'!$B:$B,'食譜'!$J:$J,""),'食材'!$B:$B,'食材'!$D:$D,"")} | BT30: {=XLOOKUP(BR28,'食譜'!$B:$B,'食譜'!$K:$K,"")} -> 21 | BV30: {=XLOOKUP(XLOOKUP(BV28,'食譜'!$B:$B,'食譜'!$J:$J,""),'食材'!$B:$B,'食材'!$D:$D,"")} | BX30: {=XLOOKUP(BV28,'食譜'!$B:$B,'食譜'!$K:$K,"")} -> 15 | BZ30: {=XLOOKUP(XLOOKUP(BZ28,'食譜'!$B:$B,'食譜'!$J:$J,""),'食材'!$B:$B,'食材'!$D:$D,"")} | CB30: {=XLOOKUP(BZ28,'食譜'!$B:$B,'食譜'!$K:$K,"")} -> 20 | CD30: {=XLOOKUP(XLOOKUP(CD28,'食譜'!$B:$B,'食譜'!$J:$J,""),'食材'!$B:$B,'食材'!$D:$D,"")} | CF30: {=XLOOKUP(CD28,'食譜'!$B:$B,'食譜'!$K:$K,"")} -> 22 | CH30: {=XLOOKUP(XLOOKUP(CH28,'食譜'!$B:$B,'食譜'!$J:$J,""),'食材'!$B:$B,'食材'!$D:$D,"")} | CJ30: {=XLOOKUP(CH28,'食譜'!$B:$B,'食譜'!$K:$K,"")} -> 19 | CL30: {=XLOOKUP(XLOOKUP(CL28,'食譜'!$B:$B,'食譜'!$J:$J,""),'食材'!$B:$B,'食材'!$D:$D,"")} | CN30: {=XLOOKUP(CL28,'食譜'!$B:$B,'食譜'!$K:$K,"")} -> 25 | CP30: {=XLOOKUP(XLOOKUP(CP28,'食譜'!$B:$B,'食譜'!$J:$J,""),'食材'!$B:$B,'食材'!$D:$D,"")} | CR30: {=XLOOKUP(CP28,'食譜'!$B:$B,'食譜'!$K:$K,"")} -> 35 | CT30: {=XLOOKUP(XLOOKUP(CT28,'食譜'!$B:$B,'食譜'!$J:$J,""),'食材'!$B:$B,'食材'!$D:$D,"")} | CV30: {=XLOOKUP(CT28,'食譜'!$B:$B,'食譜'!$K:$K,"")} -> 28 | CX30: {=XLOOKUP(XLOOKUP(CX28,'食譜'!$B:$B,'食譜'!$J:$J,""),'食材'!$B:$B,'食材'!$D:$D,"")} | CZ30: {=XLOOKUP(CX28,'食譜'!$B:$B,'食譜'!$K:$K,"")} -> 28 | DB30: {=XLOOKUP(XLOOKUP(DB28,'食譜'!$B:$B,'食譜'!$J:$J,""),'食材'!$B:$B,'食材'!$D:$D,"")} | DD30: {=XLOOKUP(DB28,'食譜'!$B:$B,'食譜'!$K:$K,"")} -> 20 | DG30: {=XLOOKUP(DK30,'食材'!$B:$B,'食材'!$D:$D,"")} | DI30: {=XLOOKUP(DK30,'食材'!$B:$B,'食材'!$F:$F,"")} -> 162 | DK30: 嫩亮酪梨
F32: {=XLOOKUP(XLOOKUP(F28,'食譜'!$B:$B,'食譜'!$L:$L,""),'食材'!$B:$B,'食材'!$D:$D,"")} | H32: {=XLOOKUP(F28,'食譜'!$B:$B,'食譜'!$M:$M,"")} | J32: {=XLOOKUP(XLOOKUP(J28,'食譜'!$B:$B,'食譜'!$L:$L,""),'食材'!$B:$B,'食材'!$D:$D,"")} | L32: {=XLOOKUP(J28,'食譜'!$B:$B,'食譜'!$M:$M,"")} | N32: {=XLOOKUP(XLOOKUP(N28,'食譜'!$B:$B,'食譜'!$L:$L,""),'食材'!$B:$B,'食材'!$D:$D,"")} | P32: {=XLOOKUP(N28,'食譜'!$B:$B,'食譜'!$M:$M,"")} | R32: {=XLOOKUP(XLOOKUP(R28,'食譜'!$B:$B,'食譜'!$L:$L,""),'食材'!$B:$B,'食材'!$D:$D,"")} | T32: {=XLOOKUP(R28,'食譜'!$B:$B,'食譜'!$M:$M,"")} -> 6 | V32: {=XLOOKUP(XLOOKUP(V28,'食譜'!$B:$B,'食譜'!$L:$L,""),'食材'!$B:$B,'食材'!$D:$D,"")} | X32: {=XLOOKUP(V28,'食譜'!$B:$B,'食譜'!$M:$M,"")} -> 6 | Z32: {=XLOOKUP(XLOOKUP(Z28,'食譜'!$B:$B,'食譜'!$L:$L,""),'食材'!$B:$B,'食材'!$D:$D,"")} | AB32: {=XLOOKUP(Z28,'食譜'!$B:$B,'食譜'!$M:$M,"")} -> 5 | AD32: {=XLOOKUP(XLOOKUP(AD28,'食譜'!$B:$B,'食譜'!$L:$L,""),'食材'!$B:$B,'食材'!$D:$D,"")} | AF32: {=XLOOKUP(AD28,'食譜'!$B:$B,'食譜'!$M:$M,"")} -> 8 | AH32: {=XLOOKUP(XLOOKUP(AH28,'食譜'!$B:$B,'食譜'!$L:$L,""),'食材'!$B:$B,'食材'!$D:$D,"")} | AJ32: {=XLOOKUP(AH28,'食譜'!$B:$B,'食譜'!$M:$M,"")} -> 5 | AL32: {=XLOOKUP(XLOOKUP(AL28,'食譜'!$B:$B,'食譜'!$L:$L,""),'食材'!$B:$B,'食材'!$D:$D,"")} | AN32: {=XLOOKUP(AL28,'食譜'!$B:$B,'食譜'!$M:$M,"")} -> 6 | AP32: {=XLOOKUP(XLOOKUP(AP28,'食譜'!$B:$B,'食譜'!$L:$L,""),'食材'!$B:$B,'食材'!$D:$D,"")} | AR32: {=XLOOKUP(AP28,'食譜'!$B:$B,'食譜'!$M:$M,"")} -> 6 | AT32: {=XLOOKUP(XLOOKUP(AT28,'食譜'!$B:$B,'食譜'!$L:$L,""),'食材'!$B:$B,'食材'!$D:$D,"")} | AV32: {=XLOOKUP(AT28,'食譜'!$B:$B,'食譜'!$M:$M,"")} -> 9 | AX32: {=XLOOKUP(XLOOKUP(AX28,'食譜'!$B:$B,'食譜'!$L:$L,""),'食材'!$B:$B,'食材'!$D:$D,"")} | AZ32: {=XLOOKUP(AX28,'食譜'!$B:$B,'食譜'!$M:$M,"")} -> 9 | BB32: {=XLOOKUP(XLOOKUP(BB28,'食譜'!$B:$B,'食譜'!$L:$L,""),'食材'!$B:$B,'食材'!$D:$D,"")} | BD32: {=XLOOKUP(BB28,'食譜'!$B:$B,'食譜'!$M:$M,"")} -> 9 | BF32: {=XLOOKUP(XLOOKUP(BF28,'食譜'!$B:$B,'食譜'!$L:$L,""),'食材'!$B:$B,'食材'!$D:$D,"")} | BH32: {=XLOOKUP(BF28,'食譜'!$B:$B,'食譜'!$M:$M,"")} -> 10 | BJ32: {=XLOOKUP(XLOOKUP(BJ28,'食譜'!$B:$B,'食譜'!$L:$L,""),'食材'!$B:$B,'食材'!$D:$D,"")} | BL32: {=XLOOKUP(BJ28,'食譜'!$B:$B,'食譜'!$M:$M,"")} -> 8 | BN32: {=XLOOKUP(XLOOKUP(BN28,'食譜'!$B:$B,'食譜'!$L:$L,""),'食材'!$B:$B,'食材'!$D:$D,"")} | BP32: {=XLOOKUP(BN28,'食譜'!$B:$B,'食譜'!$M:$M,"")} -> 18 | BR32: {=XLOOKUP(XLOOKUP(BR28,'食譜'!$B:$B,'食譜'!$L:$L,""),'食材'!$B:$B,'食材'!$D:$D,"")} | BT32: {=XLOOKUP(BR28,'食譜'!$B:$B,'食譜'!$M:$M,"")} -> 16 | BV32: {=XLOOKUP(XLOOKUP(BV28,'食譜'!$B:$B,'食譜'!$L:$L,""),'食材'!$B:$B,'食材'!$D:$D,"")} | BX32: {=XLOOKUP(BV28,'食譜'!$B:$B,'食譜'!$M:$M,"")} -> 10 | BZ32: {=XLOOKUP(XLOOKUP(BZ28,'食譜'!$B:$B,'食譜'!$L:$L,""),'食材'!$B:$B,'食材'!$D:$D,"")} | CB32: {=XLOOKUP(BZ28,'食譜'!$B:$B,'食譜'!$M:$M,"")} -> 15 | CD32: {=XLOOKUP(XLOOKUP(CD28,'食譜'!$B:$B,'食譜'!$L:$L,""),'食材'!$B:$B,'食材'!$D:$D,"")} | CF32: {=XLOOKUP(CD28,'食譜'!$B:$B,'食譜'!$M:$M,"")} -> 17 | CH32: {=XLOOKUP(XLOOKUP(CH28,'食譜'!$B:$B,'食譜'!$L:$L,""),'食材'!$B:$B,'食材'!$D:$D,"")} | CJ32: {=XLOOKUP(CH28,'食譜'!$B:$B,'食譜'!$M:$M,"")} -> 15 | CL32: {=XLOOKUP(XLOOKUP(CL28,'食譜'!$B:$B,'食譜'!$L:$L,""),'食材'!$B:$B,'食材'!$D:$D,"")} | CN32: {=XLOOKUP(CL28,'食譜'!$B:$B,'食譜'!$M:$M,"")} -> 17 | CP32: {=XLOOKUP(XLOOKUP(CP28,'食譜'!$B:$B,'食譜'!$L:$L,""),'食材'!$B:$B,'食材'!$D:$D,"")} | CR32: {=XLOOKUP(CP28,'食譜'!$B:$B,'食譜'!$M:$M,"")} -> 28 | CT32: {=XLOOKUP(XLOOKUP(CT28,'食譜'!$B:$B,'食譜'!$L:$L,""),'食材'!$B:$B,'食材'!$D:$D,"")} | CV32: {=XLOOKUP(CT28,'食譜'!$B:$B,'食譜'!$M:$M,"")} -> 28 | CX32: {=XLOOKUP(XLOOKUP(CX28,'食譜'!$B:$B,'食譜'!$L:$L,""),'食材'!$B:$B,'食材'!$D:$D,"")} | CZ32: {=XLOOKUP(CX28,'食譜'!$B:$B,'食譜'!$M:$M,"")} -> 25 | DB32: {=XLOOKUP(XLOOKUP(DB28,'食譜'!$B:$B,'食譜'!$L:$L,""),'食材'!$B:$B,'食材'!$D:$D,"")} | DD32: {=XLOOKUP(DB28,'食譜'!$B:$B,'食譜'!$M:$M,"")} -> 30 | DG32: {=XLOOKUP(DK32,'食材'!$B:$B,'食材'!$D:$D,"")} | DI32: {=XLOOKUP(DK32,'食材'!$B:$B,'食材'!$F:$F,"")} -> 167 | DK32: 品鮮蘑菇
F34: {=XLOOKUP(XLOOKUP(F28,'食譜'!$B:$B,'食譜'!$N:$N,""),'食材'!$B:$B,'食材'!$D:$D,"")} | H34: {=XLOOKUP(F28,'食譜'!$B:$B,'食譜'!$O:$O,"")} | J34: {=XLOOKUP(XLOOKUP(J28,'食譜'!$B:$B,'食譜'!$N:$N,""),'食材'!$B:$B,'食材'!$D:$D,"")} | L34: {=XLOOKUP(J28,'食譜'!$B:$B,'食譜'!$O:$O,"")} | N34: {=XLOOKUP(XLOOKUP(N28,'食譜'!$B:$B,'食譜'!$N:$N,""),'食材'!$B:$B,'食材'!$D:$D,"")} | P34: {=XLOOKUP(N28,'食譜'!$B:$B,'食譜'!$O:$O,"")} | R34: {=XLOOKUP(XLOOKUP(R28,'食譜'!$B:$B,'食譜'!$N:$N,""),'食材'!$B:$B,'食材'!$D:$D,"")} | T34: {=XLOOKUP(R28,'食譜'!$B:$B,'食譜'!$O:$O,"")} | V34: {=XLOOKUP(XLOOKUP(V28,'食譜'!$B:$B,'食譜'!$N:$N,""),'食材'!$B:$B,'食材'!$D:$D,"")} | X34: {=XLOOKUP(V28,'食譜'!$B:$B,'食譜'!$O:$O,"")} | Z34: {=XLOOKUP(XLOOKUP(Z28,'食譜'!$B:$B,'食譜'!$N:$N,""),'食材'!$B:$B,'食材'!$D:$D,"")} | AB34: {=XLOOKUP(Z28,'食譜'!$B:$B,'食譜'!$O:$O,"")} -> 3 | AD34: {=XLOOKUP(XLOOKUP(AD28,'食譜'!$B:$B,'食譜'!$N:$N,""),'食材'!$B:$B,'食材'!$D:$D,"")} | AF34: {=XLOOKUP(AD28,'食譜'!$B:$B,'食譜'!$O:$O,"")} | AH34: {=XLOOKUP(XLOOKUP(AH28,'食譜'!$B:$B,'食譜'!$N:$N,""),'食材'!$B:$B,'食材'!$D:$D,"")} | AJ34: {=XLOOKUP(AH28,'食譜'!$B:$B,'食譜'!$O:$O,"")} | AL34: {=XLOOKUP(XLOOKUP(AL28,'食譜'!$B:$B,'食譜'!$N:$N,""),'食材'!$B:$B,'食材'!$D:$D,"")} | AN34: {=XLOOKUP(AL28,'食譜'!$B:$B,'食譜'!$O:$O,"")} -> 5 | AP34: {=XLOOKUP(XLOOKUP(AP28,'食譜'!$B:$B,'食譜'!$N:$N,""),'食材'!$B:$B,'食材'!$D:$D,"")} | AR34: {=XLOOKUP(AP28,'食譜'!$B:$B,'食譜'!$O:$O,"")} -> 5 | AT34: {=XLOOKUP(XLOOKUP(AT28,'食譜'!$B:$B,'食譜'!$N:$N,""),'食材'!$B:$B,'食材'!$D:$D,"")} | AV34: {=XLOOKUP(AT28,'食譜'!$B:$B,'食譜'!$O:$O,"")} | AX34: {=XLOOKUP(XLOOKUP(AX28,'食譜'!$B:$B,'食譜'!$N:$N,""),'食材'!$B:$B,'食材'!$D:$D,"")} | AZ34: {=XLOOKUP(AX28,'食譜'!$B:$B,'食譜'!$O:$O,"")} | BB34: {=XLOOKUP(XLOOKUP(BB28,'食譜'!$B:$B,'食譜'!$N:$N,""),'食材'!$B:$B,'食材'!$D:$D,"")} | BD34: {=XLOOKUP(BB28,'食譜'!$B:$B,'食譜'!$O:$O,"")} -> 7 | BF34: {=XLOOKUP(XLOOKUP(BF28,'食譜'!$B:$B,'食譜'!$N:$N,""),'食材'!$B:$B,'食材'!$D:$D,"")} | BH34: {=XLOOKUP(BF28,'食譜'!$B:$B,'食譜'!$O:$O,"")} -> 8 | BJ34: {=XLOOKUP(XLOOKUP(BJ28,'食譜'!$B:$B,'食譜'!$N:$N,""),'食材'!$B:$B,'食材'!$D:$D,"")} | BL34: {=XLOOKUP(BJ28,'食譜'!$B:$B,'食譜'!$O:$O,"")} -> 8 | BN34: {=XLOOKUP(XLOOKUP(BN28,'食譜'!$B:$B,'食譜'!$N:$N,""),'食材'!$B:$B,'食材'!$D:$D,"")} | BP34: {=XLOOKUP(BN28,'食譜'!$B:$B,'食譜'!$O:$O,"")} -> 10 | BR34: {=XLOOKUP(XLOOKUP(BR28,'食譜'!$B:$B,'食譜'!$N:$N,""),'食材'!$B:$B,'食材'!$D:$D,"")} | BT34: {=XLOOKUP(BR28,'食譜'!$B:$B,'食譜'!$O:$O,"")} -> 12 | BV34: {=XLOOKUP(XLOOKUP(BV28,'食譜'!$B:$B,'食譜'!$N:$N,""),'食材'!$B:$B,'食材'!$D:$D,"")} | BX34: {=XLOOKUP(BV28,'食譜'!$B:$B,'食譜'!$O:$O,"")} -> 10 | BZ34: {=XLOOKUP(XLOOKUP(BZ28,'食譜'!$B:$B,'食譜'!$N:$N,""),'食材'!$B:$B,'食材'!$D:$D,"")} | CB34: {=XLOOKUP(BZ28,'食譜'!$B:$B,'食譜'!$O:$O,"")} -> 11 | CD34: {=XLOOKUP(XLOOKUP(CD28,'食譜'!$B:$B,'食譜'!$N:$N,""),'食材'!$B:$B,'食材'!$D:$D,"")} | CF34: {=XLOOKUP(CD28,'食譜'!$B:$B,'食譜'!$O:$O,"")} -> 14 | CH34: {=XLOOKUP(XLOOKUP(CH28,'食譜'!$B:$B,'食譜'!$N:$N,""),'食材'!$B:$B,'食材'!$D:$D,"")} | CJ34: {=XLOOKUP(CH28,'食譜'!$B:$B,'食譜'!$O:$O,"")} -> 12 | CL34: {=XLOOKUP(XLOOKUP(CL28,'食譜'!$B:$B,'食譜'!$N:$N,""),'食材'!$B:$B,'食材'!$D:$D,"")} | CN34: {=XLOOKUP(CL28,'食譜'!$B:$B,'食譜'!$O:$O,"")} -> 15 | CP34: {=XLOOKUP(XLOOKUP(CP28,'食譜'!$B:$B,'食譜'!$N:$N,""),'食材'!$B:$B,'食材'!$D:$D,"")} | CR34: {=XLOOKUP(CP28,'食譜'!$B:$B,'食譜'!$O:$O,"")} -> 23 | CT34: {=XLOOKUP(XLOOKUP(CT28,'食譜'!$B:$B,'食譜'!$N:$N,""),'食材'!$B:$B,'食材'!$D:$D,"")} | CV34: {=XLOOKUP(CT28,'食譜'!$B:$B,'食譜'!$O:$O,"")} -> 22 | CX34: {=XLOOKUP(XLOOKUP(CX28,'食譜'!$B:$B,'食譜'!$N:$N,""),'食材'!$B:$B,'食材'!$D:$D,"")} | CZ34: {=XLOOKUP(CX28,'食譜'!$B:$B,'食譜'!$O:$O,"")} -> 30 | DB34: {=XLOOKUP(XLOOKUP(DB28,'食譜'!$B:$B,'食譜'!$N:$N,""),'食材'!$B:$B,'食材'!$D:$D,"")} | DD34: {=XLOOKUP(DB28,'食譜'!$B:$B,'食譜'!$O:$O,"")} -> 18 | DG34: {=XLOOKUP(DK34,'食材'!$B:$B,'食材'!$D:$D,"")} | DI34: {=XLOOKUP(DK34,'食材'!$B:$B,'食材'!$F:$F,"")} -> 185 | DK34: 粗枝大蔥
F36: {=XLOOKUP(XLOOKUP(F28,'食譜'!$B:$B,'食譜'!$P:$P,""),'食材'!$B:$B,'食材'!$D:$D,"")} | H36: {=XLOOKUP(F28,'食譜'!$B:$B,'食譜'!$Q:$Q,"")} | J36: {=XLOOKUP(XLOOKUP(J28,'食譜'!$B:$B,'食譜'!$P:$P,""),'食材'!$B:$B,'食材'!$D:$D,"")} | L36: {=XLOOKUP(J28,'食譜'!$B:$B,'食譜'!$Q:$Q,"")} | N36: {=XLOOKUP(XLOOKUP(N28,'食譜'!$B:$B,'食譜'!$P:$P,""),'食材'!$B:$B,'食材'!$D:$D,"")} | P36: {=XLOOKUP(N28,'食譜'!$B:$B,'食譜'!$Q:$Q,"")} | R36: {=XLOOKUP(XLOOKUP(R28,'食譜'!$B:$B,'食譜'!$P:$P,""),'食材'!$B:$B,'食材'!$D:$D,"")} | T36: {=XLOOKUP(R28,'食譜'!$B:$B,'食譜'!$Q:$Q,"")} | V36: {=XLOOKUP(XLOOKUP(V28,'食譜'!$B:$B,'食譜'!$P:$P,""),'食材'!$B:$B,'食材'!$D:$D,"")} | X36: {=XLOOKUP(V28,'食譜'!$B:$B,'食譜'!$Q:$Q,"")} | Z36: {=XLOOKUP(XLOOKUP(Z28,'食譜'!$B:$B,'食譜'!$P:$P,""),'食材'!$B:$B,'食材'!$D:$D,"")} | AB36: {=XLOOKUP(Z28,'食譜'!$B:$B,'食譜'!$Q:$Q,"")} | AD36: {=XLOOKUP(XLOOKUP(AD28,'食譜'!$B:$B,'食譜'!$P:$P,""),'食材'!$B:$B,'食材'!$D:$D,"")} | AF36: {=XLOOKUP(AD28,'食譜'!$B:$B,'食譜'!$Q:$Q,"")} | AH36: {=XLOOKUP(XLOOKUP(AH28,'食譜'!$B:$B,'食譜'!$P:$P,""),'食材'!$B:$B,'食材'!$D:$D,"")} | AJ36: {=XLOOKUP(AH28,'食譜'!$B:$B,'食譜'!$Q:$Q,"")} | AL36: {=XLOOKUP(XLOOKUP(AL28,'食譜'!$B:$B,'食譜'!$P:$P,""),'食材'!$B:$B,'食材'!$D:$D,"")} | AN36: {=XLOOKUP(AL28,'食譜'!$B:$B,'食譜'!$Q:$Q,"")} | AP36: {=XLOOKUP(XLOOKUP(AP28,'食譜'!$B:$B,'食譜'!$P:$P,""),'食材'!$B:$B,'食材'!$D:$D,"")} | AR36: {=XLOOKUP(AP28,'食譜'!$B:$B,'食譜'!$Q:$Q,"")} -> 3 | AT36: {=XLOOKUP(XLOOKUP(AT28,'食譜'!$B:$B,'食譜'!$P:$P,""),'食材'!$B:$B,'食材'!$D:$D,"")} | AV36: {=XLOOKUP(AT28,'食譜'!$B:$B,'食譜'!$Q:$Q,"")} | AX36: {=XLOOKUP(XLOOKUP(AX28,'食譜'!$B:$B,'食譜'!$P:$P,""),'食材'!$B:$B,'食材'!$D:$D,"")} | AZ36: {=XLOOKUP(AX28,'食譜'!$B:$B,'食譜'!$Q:$Q,"")} | BB36: {=XLOOKUP(XLOOKUP(BB28,'食譜'!$B:$B,'食譜'!$P:$P,""),'食材'!$B:$B,'食材'!$D:$D,"")} | BD36: {=XLOOKUP(BB28,'食譜'!$B:$B,'食譜'!$Q:$Q,"")} -> 6 | BF36: {=XLOOKUP(XLOOKUP(BF28,'食譜'!$B:$B,'食譜'!$P:$P,""),'食材'!$B:$B,'食材'!$D:$D,"")} | BH36: {=XLOOKUP(BF28,'食譜'!$B:$B,'食譜'!$Q:$Q,"")} | BJ36: {=XLOOKUP(XLOOKUP(BJ28,'食譜'!$B:$B,'食譜'!$P:$P,""),'食材'!$B:$B,'食材'!$D:$D,"")} | BL36: {=XLOOKUP(BJ28,'食譜'!$B:$B,'食譜'!$Q:$Q,"")} | BN36: {=XLOOKUP(XLOOKUP(BN28,'食譜'!$B:$B,'食譜'!$P:$P,""),'食材'!$B:$B,'食材'!$D:$D,"")} | BP36: {=XLOOKUP(BN28,'食譜'!$B:$B,'食譜'!$Q:$Q,"")} | BR36: {=XLOOKUP(XLOOKUP(BR28,'食譜'!$B:$B,'食譜'!$P:$P,""),'食材'!$B:$B,'食材'!$D:$D,"")} | BT36: {=XLOOKUP(BR28,'食譜'!$B:$B,'食譜'!$Q:$Q,"")} | BV36: {=XLOOKUP(XLOOKUP(BV28,'食譜'!$B:$B,'食譜'!$P:$P,""),'食材'!$B:$B,'食材'!$D:$D,"")} | BX36: {=XLOOKUP(BV28,'食譜'!$B:$B,'食譜'!$Q:$Q,"")} | BZ36: {=XLOOKUP(XLOOKUP(BZ28,'食譜'!$B:$B,'食譜'!$P:$P,""),'食材'!$B:$B,'食材'!$D:$D,"")} | CB36: {=XLOOKUP(BZ28,'食譜'!$B:$B,'食譜'!$Q:$Q,"")} -> 10 | CD36: {=XLOOKUP(XLOOKUP(CD28,'食譜'!$B:$B,'食譜'!$P:$P,""),'食材'!$B:$B,'食材'!$D:$D,"")} | CF36: {=XLOOKUP(CD28,'食譜'!$B:$B,'食譜'!$Q:$Q,"")} -> 9 | CH36: {=XLOOKUP(XLOOKUP(CH28,'食譜'!$B:$B,'食譜'!$P:$P,""),'食材'!$B:$B,'食材'!$D:$D,"")} | CJ36: {=XLOOKUP(CH28,'食譜'!$B:$B,'食譜'!$Q:$Q,"")} -> 11 | CL36: {=XLOOKUP(XLOOKUP(CL28,'食譜'!$B:$B,'食譜'!$P:$P,""),'食材'!$B:$B,'食材'!$D:$D,"")} | CN36: {=XLOOKUP(CL28,'食譜'!$B:$B,'食譜'!$Q:$Q,"")} -> 12 | CP36: {=XLOOKUP(XLOOKUP(CP28,'食譜'!$B:$B,'食譜'!$P:$P,""),'食材'!$B:$B,'食材'!$D:$D,"")} | CR36: {=XLOOKUP(CP28,'食譜'!$B:$B,'食譜'!$Q:$Q,"")} -> 18 | CT36: {=XLOOKUP(XLOOKUP(CT28,'食譜'!$B:$B,'食譜'!$P:$P,""),'食材'!$B:$B,'食材'!$D:$D,"")} | CV36: {=XLOOKUP(CT28,'食譜'!$B:$B,'食譜'!$Q:$Q,"")} -> 22 | CX36: {=XLOOKUP(XLOOKUP(CX28,'食譜'!$B:$B,'食譜'!$P:$P,""),'食材'!$B:$B,'食材'!$D:$D,"")} | CZ36: {=XLOOKUP(CX28,'食譜'!$B:$B,'食譜'!$Q:$Q,"")} -> 22 | DB36: {=XLOOKUP(XLOOKUP(DB28,'食譜'!$B:$B,'食譜'!$P:$P,""),'食材'!$B:$B,'食材'!$D:$D,"")} | DD36: {=XLOOKUP(DB28,'食譜'!$B:$B,'食譜'!$Q:$Q,"")} -> 27 | DG36: {=XLOOKUP(DK36,'食材'!$B:$B,'食材'!$D:$D,"")} | DI36: {=XLOOKUP(DK36,'食材'!$B:$B,'食材'!$F:$F,"")} -> 250 | DK36: 沉甸甸南瓜
F38: {=XLOOKUP(F28,'食譜'!$B:$B,'食譜'!$D:$D,"")} -> 8 | J38: {=XLOOKUP(J28,'食譜'!$B:$B,'食譜'!$D:$D,"")} -> 8 | N38: {=XLOOKUP(N28,'食譜'!$B:$B,'食譜'!$D:$D,"")} -> 8 | R38: {=XLOOKUP(R28,'食譜'!$B:$B,'食譜'!$D:$D,"")} -> 16 | V38: {=XLOOKUP(V28,'食譜'!$B:$B,'食譜'!$D:$D,"")} -> 16 | Z38: {=XLOOKUP(Z28,'食譜'!$B:$B,'食譜'!$D:$D,"")} -> 23 | AD38: {=XLOOKUP(AD28,'食譜'!$B:$B,'食譜'!$D:$D,"")} -> 17 | AH38: {=XLOOKUP(AH28,'食譜'!$B:$B,'食譜'!$D:$D,"")} -> 15 | AL38: {=XLOOKUP(AL28,'食譜'!$B:$B,'食譜'!$D:$D,"")} -> 23 | AP38: {=XLOOKUP(AP28,'食譜'!$B:$B,'食譜'!$D:$D,"")} -> 23 | AT38: {=XLOOKUP(AT28,'食譜'!$B:$B,'食譜'!$D:$D,"")} -> 24 | AX38: {=XLOOKUP(AX28,'食譜'!$B:$B,'食譜'!$D:$D,"")} -> 23 | BB38: {=XLOOKUP(BB28,'食譜'!$B:$B,'食譜'!$D:$D,"")} -> 36 | BF38: {=XLOOKUP(BF28,'食譜'!$B:$B,'食譜'!$D:$D,"")} -> 35 | BJ38: {=XLOOKUP(BJ28,'食譜'!$B:$B,'食譜'!$D:$D,"")} -> 33 | BN38: {=XLOOKUP(BN28,'食譜'!$B:$B,'食譜'!$D:$D,"")} -> 42 | BR38: {=XLOOKUP(BR28,'食譜'!$B:$B,'食譜'!$D:$D,"")} -> 49 | BV38: {=XLOOKUP(BV28,'食譜'!$B:$B,'食譜'!$D:$D,"")} -> 35 | BZ38: {=XLOOKUP(BZ28,'食譜'!$B:$B,'食譜'!$D:$D,"")} -> 56 | CD38: {=XLOOKUP(CD28,'食譜'!$B:$B,'食譜'!$D:$D,"")} -> 62 | CH38: {=XLOOKUP(CH28,'食譜'!$B:$B,'食譜'!$D:$D,"")} -> 57 | CL38: {=XLOOKUP(CL28,'食譜'!$B:$B,'食譜'!$D:$D,"")} -> 69 | CP38: {=XLOOKUP(CP28,'食譜'!$B:$B,'食譜'!$D:$D,"")} -> 104 | CT38: {=XLOOKUP(CT28,'食譜'!$B:$B,'食譜'!$D:$D,"")} -> 100 | CX38: {=XLOOKUP(CX28,'食譜'!$B:$B,'食譜'!$D:$D,"")} -> 105 | DB38: {=XLOOKUP(DB28,'食譜'!$B:$B,'食譜'!$D:$D,"")} -> 95 | DG38: {=XLOOKUP(DK38,'食材'!$B:$B,'食材'!$D:$D,"")} | DI38: {=XLOOKUP(DK38,'食材'!$B:$B,'食材'!$F:$F,"")} -> 342 | DK38: 美味尾巴
B42: {=XLOOKUP("拌拌果汁",'食譜'!B:B,'食譜'!A:A,"")} | F42: {=XLOOKUP(F48,'食譜'!$B:$B,'食譜'!$F:$F,"")} -> 0.19 | J42: {=XLOOKUP(J48,'食譜'!$B:$B,'食譜'!$F:$F,"")} -> 0.19 | N42: {=XLOOKUP(N48,'食譜'!$B:$B,'食譜'!$F:$F,"")} -> 0.19 | R42: {=XLOOKUP(R48,'食譜'!$B:$B,'食譜'!$F:$F,"")} -> 0.19 | V42: {=XLOOKUP(V48,'食譜'!$B:$B,'食譜'!$F:$F,"")} -> 0.19 | Z42: {=XLOOKUP(Z48,'食譜'!$B:$B,'食譜'!$F:$F,"")} -> 0.19 | AD42: {=XLOOKUP(AD48,'食譜'!$B:$B,'食譜'!$F:$F,"")} -> 0.19 | AH42: {=XLOOKUP(AH48,'食譜'!$B:$B,'食譜'!$F:$F,"")} -> 0.19 | AL42: {=XLOOKUP(AL48,'食譜'!$B:$B,'食譜'!$F:$F,"")} -> 0.21 | AP42: {=XLOOKUP(AP48,'食譜'!$B:$B,'食譜'!$F:$F,"")} -> 0.2 | AT42: {=XLOOKUP(AT48,'食譜'!$B:$B,'食譜'!$F:$F,"")} -> 0.25 | AX42: {=XLOOKUP(AX48,'食譜'!$B:$B,'食譜'!$F:$F,"")} -> 0.21 | BB42: {=XLOOKUP(BB48,'食譜'!$B:$B,'食譜'!$F:$F,"")} -> 0.25 | BF42: {=XLOOKUP(BF48,'食譜'!$B:$B,'食譜'!$F:$F,"")} -> 0.25 | BJ42: {=XLOOKUP(BJ48,'食譜'!$B:$B,'食譜'!$F:$F,"")} -> 0.25 | BN42: {=XLOOKUP(BN48,'食譜'!$B:$B,'食譜'!$F:$F,"")} -> 0.35 | BR42: {=XLOOKUP(BR48,'食譜'!$B:$B,'食譜'!$F:$F,"")} -> 0.35 | BV42: {=XLOOKUP(BV48,'食譜'!$B:$B,'食譜'!$F:$F,"")} -> 0.35 | BZ42: {=XLOOKUP(BZ48,'食譜'!$B:$B,'食譜'!$F:$F,"")} -> 0.35 | CD42: {=XLOOKUP(CD48,'食譜'!$B:$B,'食譜'!$F:$F,"")} -> 0.35 | CH42: {=XLOOKUP(CH48,'食譜'!$B:$B,'食譜'!$F:$F,"")} -> 0.35 | CL42: {=XLOOKUP(CL48,'食譜'!$B:$B,'食譜'!$F:$F,"")} -> 0.48 | CP42: {=XLOOKUP(CP48,'食譜'!$B:$B,'食譜'!$F:$F,"")} -> 0.48 | CT42: {=XLOOKUP(CT48,'食譜'!$B:$B,'食譜'!$F:$F,"")} -> 0.61 | CX42: {=XLOOKUP(CX48,'食譜'!$B:$B,'食譜'!$F:$F,"")} -> 0.61 | DB42: {=XLOOKUP(DB48,'食譜'!$B:$B,'食譜'!$F:$F,"")} -> 0.78 | DF42: {=XLOOKUP(DF48,'食譜'!$B:$B,'食譜'!$F:$F,"")} -> 0.78
F44: {=XLOOKUP(F48,'食譜'!$B:$B,'食譜'!$H:$H,"")} -> 814 | J44: {=XLOOKUP(J48,'食譜'!$B:$B,'食譜'!$H:$H,"")} -> 855 | N44: {=XLOOKUP(N48,'食譜'!$B:$B,'食譜'!$H:$H,"")} -> 1079 | R44: {=XLOOKUP(R48,'食譜'!$B:$B,'食譜'!$H:$H,"")} -> 1748 | V44: {=XLOOKUP(V48,'食譜'!$B:$B,'食譜'!$H:$H,"")} -> 1907 | Z44: {=XLOOKUP(Z48,'食譜'!$B:$B,'食譜'!$H:$H,"")} -> 1913 | AD44: {=XLOOKUP(AD48,'食譜'!$B:$B,'食譜'!$H:$H,"")} -> 1924 | AH44: {=XLOOKUP(AH48,'食譜'!$B:$B,'食譜'!$H:$H,"")} -> 1924 | AL44: {=XLOOKUP(AL48,'食譜'!$B:$B,'食譜'!$H:$H,"")} -> 3015 | AP44: {=XLOOKUP(AP48,'食譜'!$B:$B,'食譜'!$H:$H,"")} -> 3263 | AT44: {=XLOOKUP(AT48,'食譜'!$B:$B,'食譜'!$H:$H,"")} -> 3314 | AX44: {=XLOOKUP(AX48,'食譜'!$B:$B,'食譜'!$H:$H,"")} -> 3378 | BB44: {=XLOOKUP(BB48,'食譜'!$B:$B,'食譜'!$H:$H,"")} -> 4734 | BF44: {=XLOOKUP(BF48,'食譜'!$B:$B,'食譜'!$H:$H,"")} -> 4921 | BJ44: {=XLOOKUP(BJ48,'食譜'!$B:$B,'食譜'!$H:$H,"")} -> 5065 | BN44: {=XLOOKUP(BN48,'食譜'!$B:$B,'食譜'!$H:$H,"")} -> 5547 | BR44: {=XLOOKUP(BR48,'食譜'!$B:$B,'食譜'!$H:$H,"")} -> 6048 | BV44: {=XLOOKUP(BV48,'食譜'!$B:$B,'食譜'!$H:$H,"")} -> 6793 | BZ44: {=XLOOKUP(BZ48,'食譜'!$B:$B,'食譜'!$H:$H,"")} -> 7125 | CD44: {=XLOOKUP(CD48,'食譜'!$B:$B,'食譜'!$H:$H,"")} -> 7594 | CH44: {=XLOOKUP(CH48,'食譜'!$B:$B,'食譜'!$H:$H,"")} -> 8165 | CL44: {=XLOOKUP(CL48,'食譜'!$B:$B,'食譜'!$H:$H,"")} -> 10925 | CP44: {=XLOOKUP(CP48,'食譜'!$B:$B,'食譜'!$H:$H,"")} -> 13834 | CT44: {=XLOOKUP(CT48,'食譜'!$B:$B,'食譜'!$H:$H,"")} -> 17494 | CX44: {=XLOOKUP(CX48,'食譜'!$B:$B,'食譜'!$H:$H,"")} -> 20885 | DB44: {=XLOOKUP(DB48,'食譜'!$B:$B,'食譜'!$H:$H,"")} -> 24354 | DF44: {=XLOOKUP(DF48,'食譜'!$B:$B,'食譜'!$H:$H,"")} -> 25484
F45: {=XLOOKUP(F48,'食譜'!$B:$B,'食譜'!$A:$A,"")} | J45: {=XLOOKUP(J48,'食譜'!$B:$B,'食譜'!$A:$A,"")} | N45: {=XLOOKUP(N48,'食譜'!$B:$B,'食譜'!$A:$A,"")} | R45: {=XLOOKUP(R48,'食譜'!$B:$B,'食譜'!$A:$A,"")} | V45: {=XLOOKUP(V48,'食譜'!$B:$B,'食譜'!$A:$A,"")} | Z45: {=XLOOKUP(Z48,'食譜'!$B:$B,'食譜'!$A:$A,"")} | AD45: {=XLOOKUP(AD48,'食譜'!$B:$B,'食譜'!$A:$A,"")} | AH45: {=XLOOKUP(AH48,'食譜'!$B:$B,'食譜'!$A:$A,"")} | AL45: {=XLOOKUP(AL48,'食譜'!$B:$B,'食譜'!$A:$A,"")} | AP45: {=XLOOKUP(AP48,'食譜'!$B:$B,'食譜'!$A:$A,"")} | AT45: {=XLOOKUP(AT48,'食譜'!$B:$B,'食譜'!$A:$A,"")} | AX45: {=XLOOKUP(AX48,'食譜'!$B:$B,'食譜'!$A:$A,"")} | BB45: {=XLOOKUP(BB48,'食譜'!$B:$B,'食譜'!$A:$A,"")} | BF45: {=XLOOKUP(BF48,'食譜'!$B:$B,'食譜'!$A:$A,"")} | BJ45: {=XLOOKUP(BJ48,'食譜'!$B:$B,'食譜'!$A:$A,"")} | BN45: {=XLOOKUP(BN48,'食譜'!$B:$B,'食譜'!$A:$A,"")} | BR45: {=XLOOKUP(BR48,'食譜'!$B:$B,'食譜'!$A:$A,"")} | BV45: {=XLOOKUP(BV48,'食譜'!$B:$B,'食譜'!$A:$A,"")} | BZ45: {=XLOOKUP(BZ48,'食譜'!$B:$B,'食譜'!$A:$A,"")} | CD45: {=XLOOKUP(CD48,'食譜'!$B:$B,'食譜'!$A:$A,"")} | CH45: {=XLOOKUP(CH48,'食譜'!$B:$B,'食譜'!$A:$A,"")} | CL45: {=XLOOKUP(CL48,'食譜'!$B:$B,'食譜'!$A:$A,"")} | CP45: {=XLOOKUP(CP48,'食譜'!$B:$B,'食譜'!$A:$A,"")} | CT45: {=XLOOKUP(CT48,'食譜'!$B:$B,'食譜'!$A:$A,"")} | CX45: {=XLOOKUP(CX48,'食譜'!$B:$B,'食譜'!$A:$A,"")} | DB45: {=XLOOKUP(DB48,'食譜'!$B:$B,'食譜'!$A:$A,"")} | DF45: {=XLOOKUP(DF48,'食譜'!$B:$B,'食譜'!$A:$A,"")}
F48: =IFERROR(__xludf.DUMMYFUNCTION("SPLIT(TEXTJOIN("""",TRUE,TOROW(FILTER('食譜'!$B:$B&""----"", '食譜'!$E:$E=""點心、飲料"",'食譜'!$B:$B<>""拌拌果汁"")),"""","""",""""),""-"",TRUE,FALSE)"),"哞哞熱鮮奶") -> 哞哞熱鮮奶 | J48: =IFERROR(__xludf.DUMMYFUNCTION("""COMPUTED_VALUE"""),"特選蘋果汁") -> 特選蘋果汁 | N48: =IFERROR(__xludf.DUMMYFUNCTION("""COMPUTED_VALUE"""),"手製勁爽汽水") -> 手製勁爽汽水 | R48: =IFERROR(__xludf.DUMMYFUNCTION("""COMPUTED_VALUE"""),"祈願蘋果派") -> 祈願蘋果派 | V48: =IFERROR(__xludf.DUMMYFUNCTION("""COMPUTED_VALUE"""),"熟成甜薯燒") -> 熟成甜薯燒 | Z48: =IFERROR(__xludf.DUMMYFUNCTION("""COMPUTED_VALUE"""),"火花薑茶") -> 火花薑茶 | AD48: =IFERROR(__xludf.DUMMYFUNCTION("""COMPUTED_VALUE"""),"輕裝豆香蛋糕") -> 輕裝豆香蛋糕 | AH48: =IFERROR(__xludf.DUMMYFUNCTION("""COMPUTED_VALUE"""),"我行我素蔬菜汁") -> 我行我素蔬菜汁 | AL48: =IFERROR(__xludf.DUMMYFUNCTION("""COMPUTED_VALUE"""),"大馬拉薩達") -> 大馬拉薩達 | AP48: =IFERROR(__xludf.DUMMYFUNCTION("""COMPUTED_VALUE"""),"活力蛋白飲") -> 活力蛋白飲 | AT48: =IFERROR(__xludf.DUMMYFUNCTION("""COMPUTED_VALUE"""),"花瓣舞巧克力塔") -> 花瓣舞巧克力塔 | AX48: =IFERROR(__xludf.DUMMYFUNCTION("""COMPUTED_VALUE"""),"甜甜香氣巧克力蛋糕") -> 甜甜香氣巧克力蛋糕 | BB48: =IFERROR(__xludf.DUMMYFUNCTION("""COMPUTED_VALUE"""),"惡魔之吻水果牛奶") -> 惡魔之吻水果牛奶 | BF48: =IFERROR(__xludf.DUMMYFUNCTION("""COMPUTED_VALUE"""),"不屈薑餅") -> 不屈薑餅 | BJ48: =IFERROR(__xludf.DUMMYFUNCTION("""COMPUTED_VALUE"""),"橙夢的排毒茶") -> 橙夢的排毒茶 | BN48: =IFERROR(__xludf.DUMMYFUNCTION("""COMPUTED_VALUE"""),"大力士豆香甜甜圈") -> 大力士豆香甜甜圈 | BR48: =IFERROR(__xludf.DUMMYFUNCTION("""COMPUTED_VALUE"""),"大爆炸爆米花") -> 大爆炸爆米花 | BV48: =IFERROR(__xludf.DUMMYFUNCTION("""COMPUTED_VALUE"""),"早起咖啡凍") -> 早起咖啡凍 | BZ48: =IFERROR(__xludf.DUMMYFUNCTION("""COMPUTED_VALUE"""),"破格玉米香提拉米蘇") -> 破格玉米香提拉米蘇 | CD48: =IFERROR(__xludf.DUMMYFUNCTION("""COMPUTED_VALUE"""),"胖丁百匯布丁") -> 胖丁百匯布丁 | CH48: =IFERROR(__xludf.DUMMYFUNCTION("""COMPUTED_VALUE"""),"青草攪拌器冰沙") -> 青草攪拌器冰沙 | CL48: =IFERROR(__xludf.DUMMYFUNCTION("""COMPUTED_VALUE"""),"茶會玉米司康") -> 茶會玉米司康 | CP48: =IFERROR(__xludf.DUMMYFUNCTION("""COMPUTED_VALUE"""),"花之禮馬卡龍") -> 花之禮馬卡龍 | CT48: =IFERROR(__xludf.DUMMYFUNCTION("""COMPUTED_VALUE"""),"電光香料可樂") -> 電光香料可樂 | CX48: =IFERROR(__xludf.DUMMYFUNCTION("""COMPUTED_VALUE"""),"土王閃電泡芙") -> 土王閃電泡芙 | DB48: =IFERROR(__xludf.DUMMYFUNCTION("""COMPUTED_VALUE"""),"心跳加速鬼面鬆餅") -> 心跳加速鬼面鬆餅 | DF48: =IFERROR(__xludf.DUMMYFUNCTION("""COMPUTED_VALUE"""),"採蜜巧克力格子鬆餅") -> 採蜜巧克力格子鬆餅
F50: {=XLOOKUP(XLOOKUP(F48,'食譜'!$B:$B,'食譜'!$J:$J,""),'食材'!$B:$B,'食材'!$D:$D,"")} | H50: {=XLOOKUP(F48,'食譜'!$B:$B,'食譜'!$K:$K,"")} -> 7 | J50: {=XLOOKUP(XLOOKUP(J48,'食譜'!$B:$B,'食譜'!$J:$J,""),'食材'!$B:$B,'食材'!$D:$D,"")} | L50: {=XLOOKUP(J48,'食譜'!$B:$B,'食譜'!$K:$K,"")} -> 8 | N50: {=XLOOKUP(XLOOKUP(N48,'食譜'!$B:$B,'食譜'!$J:$J,""),'食材'!$B:$B,'食材'!$D:$D,"")} | P50: {=XLOOKUP(N48,'食譜'!$B:$B,'食譜'!$K:$K,"")} -> 9 | R50: {=XLOOKUP(XLOOKUP(R48,'食譜'!$B:$B,'食譜'!$J:$J,""),'食材'!$B:$B,'食材'!$D:$D,"")} | T50: {=XLOOKUP(R48,'食譜'!$B:$B,'食譜'!$K:$K,"")} -> 12 | V50: {=XLOOKUP(XLOOKUP(V48,'食譜'!$B:$B,'食譜'!$J:$J,""),'食材'!$B:$B,'食材'!$D:$D,"")} | X50: {=XLOOKUP(V48,'食譜'!$B:$B,'食譜'!$K:$K,"")} -> 9 | Z50: {=XLOOKUP(XLOOKUP(Z48,'食譜'!$B:$B,'食譜'!$J:$J,""),'食材'!$B:$B,'食材'!$D:$D,"")} | AB50: {=XLOOKUP(Z48,'食譜'!$B:$B,'食譜'!$K:$K,"")} -> 9 | AD50: {=XLOOKUP(XLOOKUP(AD48,'食譜'!$B:$B,'食譜'!$J:$J,""),'食材'!$B:$B,'食材'!$D:$D,"")} | AF50: {=XLOOKUP(AD48,'食譜'!$B:$B,'食譜'!$K:$K,"")} -> 8 | AH50: {=XLOOKUP(XLOOKUP(AH48,'食譜'!$B:$B,'食譜'!$J:$J,""),'食材'!$B:$B,'食材'!$D:$D,"")} | AJ50: {=XLOOKUP(AH48,'食譜'!$B:$B,'食譜'!$K:$K,"")} -> 9 | AL50: {=XLOOKUP(XLOOKUP(AL48,'食譜'!$B:$B,'食譜'!$J:$J,""),'食材'!$B:$B,'食材'!$D:$D,"")} | AN50: {=XLOOKUP(AL48,'食譜'!$B:$B,'食譜'!$K:$K,"")} -> 10 | AP50: {=XLOOKUP(XLOOKUP(AP48,'食譜'!$B:$B,'食譜'!$J:$J,""),'食材'!$B:$B,'食材'!$D:$D,"")} | AR50: {=XLOOKUP(AP48,'食譜'!$B:$B,'食譜'!$K:$K,"")} -> 15 | AT50: {=XLOOKUP(XLOOKUP(AT48,'食譜'!$B:$B,'食譜'!$J:$J,""),'食材'!$B:$B,'食材'!$D:$D,"")} | AV50: {=XLOOKUP(AT48,'食譜'!$B:$B,'食譜'!$K:$K,"")} -> 11 | AX50: {=XLOOKUP(XLOOKUP(AX48,'食譜'!$B:$B,'食譜'!$J:$J,""),'食材'!$B:$B,'食材'!$D:$D,"")} | AZ50: {=XLOOKUP(AX48,'食譜'!$B:$B,'食譜'!$K:$K,"")} -> 9 | BB50: {=XLOOKUP(XLOOKUP(BB48,'食譜'!$B:$B,'食譜'!$J:$J,""),'食材'!$B:$B,'食材'!$D:$D,"")} | BD50: {=XLOOKUP(BB48,'食譜'!$B:$B,'食譜'!$K:$K,"")} -> 11 | BF50: {=XLOOKUP(XLOOKUP(BF48,'食譜'!$B:$B,'食譜'!$J:$J,""),'食材'!$B:$B,'食材'!$D:$D,"")} | BH50: {=XLOOKUP(BF48,'食譜'!$B:$B,'食譜'!$K:$K,"")} -> 14 | BJ50: {=XLOOKUP(XLOOKUP(BJ48,'食譜'!$B:$B,'食譜'!$J:$J,""),'食材'!$B:$B,'食材'!$D:$D,"")} | BL50: {=XLOOKUP(BJ48,'食譜'!$B:$B,'食譜'!$K:$K,"")} -> 15 | BN50: {=XLOOKUP(XLOOKUP(BN48,'食譜'!$B:$B,'食譜'!$J:$J,""),'食材'!$B:$B,'食材'!$D:$D,"")} | BP50: {=XLOOKUP(BN48,'食譜'!$B:$B,'食譜'!$K:$K,"")} -> 16 | BR50: {=XLOOKUP(XLOOKUP(BR48,'食譜'!$B:$B,'食譜'!$J:$J,""),'食材'!$B:$B,'食材'!$D:$D,"")} | BT50: {=XLOOKUP(BR48,'食譜'!$B:$B,'食譜'!$K:$K,"")} -> 15 | BV50: {=XLOOKUP(XLOOKUP(BV48,'食譜'!$B:$B,'食譜'!$J:$J,""),'食材'!$B:$B,'食材'!$D:$D,"")} | BX50: {=XLOOKUP(BV48,'食譜'!$B:$B,'食譜'!$K:$K,"")} -> 16 | BZ50: {=XLOOKUP(XLOOKUP(BZ48,'食譜'!$B:$B,'食譜'!$J:$J,""),'食材'!$B:$B,'食材'!$D:$D,"")} | CB50: {=XLOOKUP(BZ48,'食譜'!$B:$B,'食譜'!$K:$K,"")} -> 14 | CD50: {=XLOOKUP(XLOOKUP(CD48,'食譜'!$B:$B,'食譜'!$J:$J,""),'食材'!$B:$B,'食材'!$D:$D,"")} | CF50: {=XLOOKUP(CD48,'食譜'!$B:$B,'食譜'!$K:$K,"")} -> 20 | CH50: {=XLOOKUP(XLOOKUP(CH48,'食譜'!$B:$B,'食譜'!$J:$J,""),'食材'!$B:$B,'食材'!$D:$D,"")} | CJ50: {=XLOOKUP(CH48,'食譜'!$B:$B,'食譜'!$K:$K,"")} -> 18 | CL50: {=XLOOKUP(XLOOKUP(CL48,'食譜'!$B:$B,'食譜'!$J:$J,""),'食材'!$B:$B,'食材'!$D:$D,"")} | CN50: {=XLOOKUP(CL48,'食譜'!$B:$B,'食譜'!$K:$K,"")} -> 20 | CP50: {=XLOOKUP(XLOOKUP(CP48,'食譜'!$B:$B,'食譜'!$J:$J,""),'食材'!$B:$B,'食材'!$D:$D,"")} | CR50: {=XLOOKUP(CP48,'食譜'!$B:$B,'食譜'!$K:$K,"")} -> 25 | CT50: {=XLOOKUP(XLOOKUP(CT48,'食譜'!$B:$B,'食譜'!$J:$J,""),'食材'!$B:$B,'食材'!$D:$D,"")} | CV50: {=XLOOKUP(CT48,'食譜'!$B:$B,'食譜'!$K:$K,"")} -> 35 | CX50: {=XLOOKUP(XLOOKUP(CX48,'食譜'!$B:$B,'食譜'!$J:$J,""),'食材'!$B:$B,'食材'!$D:$D,"")} | CZ50: {=XLOOKUP(CX48,'食譜'!$B:$B,'食譜'!$K:$K,"")} -> 30 | DB50: {=XLOOKUP(XLOOKUP(DB48,'食譜'!$B:$B,'食譜'!$J:$J,""),'食材'!$B:$B,'食材'!$D:$D,"")} | DD50: {=XLOOKUP(DB48,'食譜'!$B:$B,'食譜'!$K:$K,"")} -> 18 | DF50: {=XLOOKUP(XLOOKUP(DF48,'食譜'!$B:$B,'食譜'!$J:$J,""),'食材'!$B:$B,'食材'!$D:$D,"")} | DH50: {=XLOOKUP(DF48,'食譜'!$B:$B,'食譜'!$K:$K,"")} -> 38
F52: {=XLOOKUP(XLOOKUP(F48,'食譜'!$B:$B,'食譜'!$L:$L,""),'食材'!$B:$B,'食材'!$D:$D,"")} | H52: {=XLOOKUP(F48,'食譜'!$B:$B,'食譜'!$M:$M,"")} | J52: {=XLOOKUP(XLOOKUP(J48,'食譜'!$B:$B,'食譜'!$L:$L,""),'食材'!$B:$B,'食材'!$D:$D,"")} | L52: {=XLOOKUP(J48,'食譜'!$B:$B,'食譜'!$M:$M,"")} | N52: {=XLOOKUP(XLOOKUP(N48,'食譜'!$B:$B,'食譜'!$L:$L,""),'食材'!$B:$B,'食材'!$D:$D,"")} | P52: {=XLOOKUP(N48,'食譜'!$B:$B,'食譜'!$M:$M,"")} | R52: {=XLOOKUP(XLOOKUP(R48,'食譜'!$B:$B,'食譜'!$L:$L,""),'食材'!$B:$B,'食材'!$D:$D,"")} | T52: {=XLOOKUP(R48,'食譜'!$B:$B,'食譜'!$M:$M,"")} -> 4 | V52: {=XLOOKUP(XLOOKUP(V48,'食譜'!$B:$B,'食譜'!$L:$L,""),'食材'!$B:$B,'食材'!$D:$D,"")} | X52: {=XLOOKUP(V48,'食譜'!$B:$B,'食譜'!$M:$M,"")} -> 5 | Z52: {=XLOOKUP(XLOOKUP(Z48,'食譜'!$B:$B,'食譜'!$L:$L,""),'食材'!$B:$B,'食材'!$D:$D,"")} | AB52: {=XLOOKUP(Z48,'食譜'!$B:$B,'食譜'!$M:$M,"")} -> 7 | AD52: {=XLOOKUP(XLOOKUP(AD48,'食譜'!$B:$B,'食譜'!$L:$L,""),'食材'!$B:$B,'食材'!$D:$D,"")} | AF52: {=XLOOKUP(AD48,'食譜'!$B:$B,'食譜'!$M:$M,"")} -> 7 | AH52: {=XLOOKUP(XLOOKUP(AH48,'食譜'!$B:$B,'食譜'!$L:$L,""),'食材'!$B:$B,'食材'!$D:$D,"")} | AJ52: {=XLOOKUP(AH48,'食譜'!$B:$B,'食譜'!$M:$M,"")} -> 7 | AL52: {=XLOOKUP(XLOOKUP(AL48,'食譜'!$B:$B,'食譜'!$L:$L,""),'食材'!$B:$B,'食材'!$D:$D,"")} | AN52: {=XLOOKUP(AL48,'食譜'!$B:$B,'食譜'!$M:$M,"")} -> 7 | AP52: {=XLOOKUP(XLOOKUP(AP48,'食譜'!$B:$B,'食譜'!$L:$L,""),'食材'!$B:$B,'食材'!$D:$D,"")} | AR52: {=XLOOKUP(AP48,'食譜'!$B:$B,'食譜'!$M:$M,"")} -> 8 | AT52: {=XLOOKUP(XLOOKUP(AT48,'食譜'!$B:$B,'食譜'!$L:$L,""),'食材'!$B:$B,'食材'!$D:$D,"")} | AV52: {=XLOOKUP(AT48,'食譜'!$B:$B,'食譜'!$M:$M,"")} -> 11 | AX52: {=XLOOKUP(XLOOKUP(AX48,'食譜'!$B:$B,'食譜'!$L:$L,""),'食材'!$B:$B,'食材'!$D:$D,"")} | AZ52: {=XLOOKUP(AX48,'食譜'!$B:$B,'食譜'!$M:$M,"")} -> 8 | BB52: {=XLOOKUP(XLOOKUP(BB48,'食譜'!$B:$B,'食譜'!$L:$L,""),'食材'!$B:$B,'食材'!$D:$D,"")} | BD52: {=XLOOKUP(BB48,'食譜'!$B:$B,'食譜'!$M:$M,"")} -> 9 | BF52: {=XLOOKUP(XLOOKUP(BF48,'食譜'!$B:$B,'食譜'!$L:$L,""),'食材'!$B:$B,'食材'!$D:$D,"")} | BH52: {=XLOOKUP(BF48,'食譜'!$B:$B,'食譜'!$M:$M,"")} -> 12 | BJ52: {=XLOOKUP(XLOOKUP(BJ48,'食譜'!$B:$B,'食譜'!$L:$L,""),'食材'!$B:$B,'食材'!$D:$D,"")} | BL52: {=XLOOKUP(BJ48,'食譜'!$B:$B,'食譜'!$M:$M,"")} -> 11 | BN52: {=XLOOKUP(XLOOKUP(BN48,'食譜'!$B:$B,'食譜'!$L:$L,""),'食材'!$B:$B,'食材'!$D:$D,"")} | BP52: {=XLOOKUP(BN48,'食譜'!$B:$B,'食譜'!$M:$M,"")} -> 12 | BR52: {=XLOOKUP(XLOOKUP(BR48,'食譜'!$B:$B,'食譜'!$L:$L,""),'食材'!$B:$B,'食材'!$D:$D,"")} | BT52: {=XLOOKUP(BR48,'食譜'!$B:$B,'食譜'!$M:$M,"")} -> 14 | BV52: {=XLOOKUP(XLOOKUP(BV48,'食譜'!$B:$B,'食譜'!$L:$L,""),'食材'!$B:$B,'食材'!$D:$D,"")} | BX52: {=XLOOKUP(BV48,'食譜'!$B:$B,'食譜'!$M:$M,"")} -> 14 | BZ52: {=XLOOKUP(XLOOKUP(BZ48,'食譜'!$B:$B,'食譜'!$L:$L,""),'食材'!$B:$B,'食材'!$D:$D,"")} | CB52: {=XLOOKUP(BZ48,'食譜'!$B:$B,'食譜'!$M:$M,"")} -> 14 | CD52: {=XLOOKUP(XLOOKUP(CD48,'食譜'!$B:$B,'食譜'!$L:$L,""),'食材'!$B:$B,'食材'!$D:$D,"")} | CF52: {=XLOOKUP(CD48,'食譜'!$B:$B,'食譜'!$M:$M,"")} -> 15 | CH52: {=XLOOKUP(XLOOKUP(CH48,'食譜'!$B:$B,'食譜'!$L:$L,""),'食材'!$B:$B,'食材'!$D:$D,"")} | CJ52: {=XLOOKUP(CH48,'食譜'!$B:$B,'食譜'!$M:$M,"")} -> 16 | CL52: {=XLOOKUP(XLOOKUP(CL48,'食譜'!$B:$B,'食譜'!$L:$L,""),'食材'!$B:$B,'食材'!$D:$D,"")} | CN52: {=XLOOKUP(CL48,'食譜'!$B:$B,'食譜'!$M:$M,"")} -> 20 | CP52: {=XLOOKUP(XLOOKUP(CP48,'食譜'!$B:$B,'食譜'!$L:$L,""),'食材'!$B:$B,'食材'!$D:$D,"")} | CR52: {=XLOOKUP(CP48,'食譜'!$B:$B,'食譜'!$M:$M,"")} -> 25 | CT52: {=XLOOKUP(XLOOKUP(CT48,'食譜'!$B:$B,'食譜'!$L:$L,""),'食材'!$B:$B,'食材'!$D:$D,"")} | CV52: {=XLOOKUP(CT48,'食譜'!$B:$B,'食譜'!$M:$M,"")} -> 20 | CX52: {=XLOOKUP(XLOOKUP(CX48,'食譜'!$B:$B,'食譜'!$L:$L,""),'食材'!$B:$B,'食材'!$D:$D,"")} | CZ52: {=XLOOKUP(CX48,'食譜'!$B:$B,'食譜'!$M:$M,"")} -> 26 | DB52: {=XLOOKUP(XLOOKUP(DB48,'食譜'!$B:$B,'食譜'!$L:$L,""),'食材'!$B:$B,'食材'!$D:$D,"")} | DD52: {=XLOOKUP(DB48,'食譜'!$B:$B,'食譜'!$M:$M,"")} -> 24 | DF52: {=XLOOKUP(XLOOKUP(DF48,'食譜'!$B:$B,'食譜'!$L:$L,""),'食材'!$B:$B,'食材'!$D:$D,"")} | DH52: {=XLOOKUP(DF48,'食譜'!$B:$B,'食譜'!$M:$M,"")} -> 28
