Workbook
Name ing_ico: '我的食材隊檔案'!$E$2:$E$30
Name my_prod: '我的食材隊檔案'!$F$2:$F$30
Name ing_table: '我的食材隊檔案'!$A$2:$F$30
Name ing_name: '我的食材隊檔案'!$D$2:$D$30
Name applied_prod: '應用日產（AP）'!$C$2:$C$30
Name ing_energy: '我的食材隊檔案'!$A$2:$A$30

Sheet 我的食材隊檔案
A1: =IFERROR(__xludf.DUMMYFUNCTION("QUERY(IMPORTRANGE(""https://docs.google.com/spreadsheets/d/1byb9bvFcmGc6Kf1LTvm48va0vCE1WjTAE5QN3bReSFU/edit?gid=1761317581#gid=1761317581"", ""食材!A:ZZZ""),""SELECT Col6, Col3, Col1, Col2"",1)"),"食材基礎分") -> 食材基礎分 | B1: =IFERROR(__xludf.DUMMYFUNCTION("""COMPUTED_VALUE"""),"英文名") -> 英文名 | C1: =IFERROR(__xludf.DUMMYFUNCTION("""COMPUTED_VALUE"""),"ID") -> ID | D1: =IFERROR(__xludf.DUMMYFUNCTION("""COMPUTED_VALUE"""),"食材名") -> 食材名 | E1: 食材圖 | F1: 我的日產（不計幫獎） | G1: 幫獎？ | I1: 暫缺 | J1: 目的
A2: =IFERROR(__xludf.DUMMYFUNCTION("""COMPUTED_VALUE"""),185.0) -> 185 | B2: =IFERROR(__xludf.DUMMYFUNCTION("""COMPUTED_VALUE"""),"Large Leek") -> Large Leek | C2: =IFERROR(__xludf.DUMMYFUNCTION("""COMPUTED_VALUE"""),1.0) -> 1 | D2: =IFERROR(__xludf.DUMMYFUNCTION("""COMPUTED_VALUE"""),"粗枝大蔥") -> 粗枝大蔥 | E2: =IMAGE("https://www.serebii.net/pokemonsleep/ingredients/"&SUBSTITUTE(LOWER(B2)," ","",)&".png") | F2: 54.58 | G2: Y | I2: 爆擊公式 | J2: 求空置隊伍位與料理總能量之換算，以兩技咚為基準，此為上限，公式應有衰減。
A3: =IFERROR(__xludf.DUMMYFUNCTION("""COMPUTED_VALUE"""),167.0) -> 167 | B3: =IFERROR(__xludf.DUMMYFUNCTION("""COMPUTED_VALUE"""),"Tasty Mushroom") -> Tasty Mushroom | C3: =IFERROR(__xludf.DUMMYFUNCTION("""COMPUTED_VALUE"""),2.0) -> 2 | D3: =IFERROR(__xludf.DUMMYFUNCTION("""COMPUTED_VALUE"""),"品鮮蘑菇") -> 品鮮蘑菇 | E3: =IMAGE("https://www.serebii.net/pokemonsleep/ingredients/"&SUBSTITUTE(LOWER(B3)," ","",)&".png") | F3: 46.76 | I3: 基準樹果充能手 | J3: 同上，求空置隊伍與總能量（料理＋其他）的換算，此為下限，更多用於助新手對比低階食譜。
A4: =IFERROR(__xludf.DUMMYFUNCTION("""COMPUTED_VALUE"""),115.0) -> 115 | B4: =IFERROR(__xludf.DUMMYFUNCTION("""COMPUTED_VALUE"""),"Fancy Egg") -> Fancy Egg | C4: =IFERROR(__xludf.DUMMYFUNCTION("""COMPUTED_VALUE"""),3.0) -> 3 | D4: =IFERROR(__xludf.DUMMYFUNCTION("""COMPUTED_VALUE"""),"特選蛋") -> 特選蛋 | E4: =IMAGE("https://www.serebii.net/pokemonsleep/ingredients/"&SUBSTITUTE(LOWER(B4)," ","",)&".png") | F4: 91.73 | I4: 更好的排板 | J4: 能不能外包啊？實在缺乏美術細胞
A5: =IFERROR(__xludf.DUMMYFUNCTION("""COMPUTED_VALUE"""),124.0) -> 124 | B5: =IFERROR(__xludf.DUMMYFUNCTION("""COMPUTED_VALUE"""),"Soft Potato") -> Soft Potato | C5: =IFERROR(__xludf.DUMMYFUNCTION("""COMPUTED_VALUE"""),4.0) -> 4 | D5: =IFERROR(__xludf.DUMMYFUNCTION("""COMPUTED_VALUE"""),"窩心洋芋") -> 窩心洋芋 | E5: =IMAGE("https://www.serebii.net/pokemonsleep/ingredients/"&SUBSTITUTE(LOWER(B5)," ","",)&".png") | F5: 90.57 | G5: Y
A6: =IFERROR(__xludf.DUMMYFUNCTION("""COMPUTED_VALUE"""),90.0) -> 90 | B6: =IFERROR(__xludf.DUMMYFUNCTION("""COMPUTED_VALUE"""),"Fancy Apple") -> Fancy Apple | C6: =IFERROR(__xludf.DUMMYFUNCTION("""COMPUTED_VALUE"""),5.0) -> 5 | D6: =IFERROR(__xludf.DUMMYFUNCTION("""COMPUTED_VALUE"""),"特選蘋果") -> 特選蘋果 | E6: =IMAGE("https://www.serebii.net/pokemonsleep/ingredients/"&SUBSTITUTE(LOWER(B6)," ","",)&".png") | F6: 82.96 | G6: Y | I6: 島加成 | J6: 有必要嗎？能幫到人，但是也怕和網頁一樣，大家貼圖時忘了移除加成耶。
A7: =IFERROR(__xludf.DUMMYFUNCTION("""COMPUTED_VALUE"""),130.0) -> 130 | B7: =IFERROR(__xludf.DUMMYFUNCTION("""COMPUTED_VALUE"""),"Fiery Herb") -> Fiery Herb | C7: =IFERROR(__xludf.DUMMYFUNCTION("""COMPUTED_VALUE"""),6.0) -> 6 | D7: =IFERROR(__xludf.DUMMYFUNCTION("""COMPUTED_VALUE"""),"火辣香草") -> 火辣香草 | E7: =IMAGE("https://www.serebii.net/pokemonsleep/ingredients/"&SUBSTITUTE(LOWER(B7)," ","",)&".png") | F7: 112.91 | I7: 補師是否持幫獎 | J7: 毫無作用。但相信有人和我一樣，看到隊伍已有幫獎為5就覺得身心舒暢。
A8: =IFERROR(__xludf.DUMMYFUNCTION("""COMPUTED_VALUE"""),103.0) -> 103 | B8: =IFERROR(__xludf.DUMMYFUNCTION("""COMPUTED_VALUE"""),"Bean Sausage") -> Bean Sausage | C8: =IFERROR(__xludf.DUMMYFUNCTION("""COMPUTED_VALUE"""),7.0) -> 7 | D8: =IFERROR(__xludf.DUMMYFUNCTION("""COMPUTED_VALUE"""),"豆製肉") -> 豆製肉 | E8: =IMAGE("https://www.serebii.net/pokemonsleep/ingredients/"&SUBSTITUTE(LOWER(B8)," ","",)&".png") | F8: 105.53 | G8: Y
A9: =IFERROR(__xludf.DUMMYFUNCTION("""COMPUTED_VALUE"""),98.0) -> 98 | B9: =IFERROR(__xludf.DUMMYFUNCTION("""COMPUTED_VALUE"""),"Moomoo Milk") -> Moomoo Milk | C9: =IFERROR(__xludf.DUMMYFUNCTION("""COMPUTED_VALUE"""),8.0) -> 8 | D9: =IFERROR(__xludf.DUMMYFUNCTION("""COMPUTED_VALUE"""),"哞哞鮮奶") -> 哞哞鮮奶 | E9: =IMAGE("https://www.serebii.net/pokemonsleep/ingredients/"&SUBSTITUTE(LOWER(B9)," ","",)&".png") | F9: 120.82
A10: =IFERROR(__xludf.DUMMYFUNCTION("""COMPUTED_VALUE"""),101.0) -> 101 | B10: =IFERROR(__xludf.DUMMYFUNCTION("""COMPUTED_VALUE"""),"Honey") -> Honey | C10: =IFERROR(__xludf.DUMMYFUNCTION("""COMPUTED_VALUE"""),9.0) -> 9 | D10: =IFERROR(__xludf.DUMMYFUNCTION("""COMPUTED_VALUE"""),"甜甜蜜") -> 甜甜蜜 | E10: =IMAGE("https://www.serebii.net/pokemonsleep/ingredients/"&SUBSTITUTE(LOWER(B10)," ","",)&".png") | F10: 146.31 | I10: 日後或能期待 | J10: 目的
A11: =IFERROR(__xludf.DUMMYFUNCTION("""COMPUTED_VALUE"""),121.0) -> 121 | B11: =IFERROR(__xludf.DUMMYFUNCTION("""COMPUTED_VALUE"""),"Pure Oil") -> Pure Oil | C11: =IFERROR(__xludf.DUMMYFUNCTION("""COMPUTED_VALUE"""),10.0) -> 10 | D11: =IFERROR(__xludf.DUMMYFUNCTION("""COMPUTED_VALUE"""),"純粹油") -> 純粹油 | E11: =IMAGE("https://www.serebii.net/pokemonsleep/ingredients/"&SUBSTITUTE(LOWER(B11)," ","",)&".png") | F11: 56.61 | I11: 一週計算 | J11: 以加入備料系統（800）、ABB/ABA的多餘食材（週佔位*週副產）、週日三倍料理能量、平滑爆擊曲線等等⋯日計算我實在想不到怎麼硬爆。
A12: =IFERROR(__xludf.DUMMYFUNCTION("""COMPUTED_VALUE"""),109.0) -> 109 | B12: =IFERROR(__xludf.DUMMYFUNCTION("""COMPUTED_VALUE"""),"Warming Ginger") -> Warming Ginger | C12: =IFERROR(__xludf.DUMMYFUNCTION("""COMPUTED_VALUE"""),11.0) -> 11 | D12: =IFERROR(__xludf.DUMMYFUNCTION("""COMPUTED_VALUE"""),"暖暖薑") -> 暖暖薑 | E12: =IMAGE("https://www.serebii.net/pokemonsleep/ingredients/"&SUBSTITUTE(LOWER(B12)," ","",)&".png") | F12: 115.87 | I12: 個人檔案VS | J12: 不確定群友有沒有玩這麼大，所以搞不起，想對比強度還是很簡單的：全料理計算幫獎環境後的總佔位相除即可
A13: =IFERROR(__xludf.DUMMYFUNCTION("""COMPUTED_VALUE"""),110.0) -> 110 | B13: =IFERROR(__xludf.DUMMYFUNCTION("""COMPUTED_VALUE"""),"Snoozy Tomato") -> Snoozy Tomato | C13: =IFERROR(__xludf.DUMMYFUNCTION("""COMPUTED_VALUE"""),12.0) -> 12 | D13: =IFERROR(__xludf.DUMMYFUNCTION("""COMPUTED_VALUE"""),"好眠番茄") -> 好眠番茄 | E13: =IMAGE("https://www.serebii.net/pokemonsleep/ingredients/"&SUBSTITUTE(LOWER(B13)," ","",)&".png") | F13: 98.54 | I13: 食材手主技能 | J13: 古月鳥爆鍋、貓擴鍋、食材精選（週計算）等。其中只有爆鍋和精選這些類型能直接量化為數值。
A14: =IFERROR(__xludf.DUMMYFUNCTION("""COMPUTED_VALUE"""),151.0) -> 151 | B14: =IFERROR(__xludf.DUMMYFUNCTION("""COMPUTED_VALUE"""),"Soothing Cacao") -> Soothing Cacao | C14: =IFERROR(__xludf.DUMMYFUNCTION("""COMPUTED_VALUE"""),13.0) -> 13 | D14: =IFERROR(__xludf.DUMMYFUNCTION("""COMPUTED_VALUE"""),"放鬆可可") -> 放鬆可可 | E14: =IMAGE("https://www.serebii.net/pokemonsleep/ingredients/"&SUBSTITUTE(LOWER(B14)," ","",)&".png") | F14: 76.86
A15: =IFERROR(__xludf.DUMMYFUNCTION("""COMPUTED_VALUE"""),342.0) -> 342 | B15: =IFERROR(__xludf.DUMMYFUNCTION("""COMPUTED_VALUE"""),"Slowpoke Tail") -> Slowpoke Tail | C15: =IFERROR(__xludf.DUMMYFUNCTION("""COMPUTED_VALUE"""),14.0) -> 14 | D15: =IFERROR(__xludf.DUMMYFUNCTION("""COMPUTED_VALUE"""),"美味尾巴") -> 美味尾巴 | E15: =IMAGE("https://www.serebii.net/pokemonsleep/ingredients/"&SUBSTITUTE(LOWER(B15)," ","",)&".png") | F15: 1 | I15: Version
A16: =IFERROR(__xludf.DUMMYFUNCTION("""COMPUTED_VALUE"""),100.0) -> 100 | B16: =IFERROR(__xludf.DUMMYFUNCTION("""COMPUTED_VALUE"""),"Greengrass Soybeans") -> Greengrass Soybeans | C16: =IFERROR(__xludf.DUMMYFUNCTION("""COMPUTED_VALUE"""),15.0) -> 15 | D16: =IFERROR(__xludf.DUMMYFUNCTION("""COMPUTED_VALUE"""),"萌綠大豆") -> 萌綠大豆 | E16: =IMAGE("https://www.serebii.net/pokemonsleep/ingredients/"&SUBSTITUTE(LOWER(B16)," ","",)&".png") | F16: 109.12 | G16: Y | I16: 1.41 | J16: Debug完成。Outsource給社群。我好想有人搞美化啊。
A17: =IFERROR(__xludf.DUMMYFUNCTION("""COMPUTED_VALUE"""),140.0) -> 140 | B17: =IFERROR(__xludf.DUMMYFUNCTION("""COMPUTED_VALUE"""),"Greengrass Corn") -> Greengrass Corn | C17: =IFERROR(__xludf.DUMMYFUNCTION("""COMPUTED_VALUE"""),16.0) -> 16 | D17: =IFERROR(__xludf.DUMMYFUNCTION("""COMPUTED_VALUE"""),"萌綠玉米") -> 萌綠玉米 | E17: =IMAGE("https://www.serebii.net/pokemonsleep/ingredients/"&SUBSTITUTE(LOWER(B17)," ","",)&".png") | F17: 120.13 | G17: Y | I17: 1.4 | J17: 分割食材效率和料理效率頁面。純粹基於美觀考量。食材效率和料理效率的自定義欄寬差太多了啦。
A18: =IFERROR(__xludf.DUMMYFUNCTION("""COMPUTED_VALUE"""),153.0) -> 153 | B18: =IFERROR(__xludf.DUMMYFUNCTION("""COMPUTED_VALUE"""),"Rousing Coffee") -> Rousing Coffee | C18: =IFERROR(__xludf.DUMMYFUNCTION("""COMPUTED_VALUE"""),17.0) -> 17 | D18: =IFERROR(__xludf.DUMMYFUNCTION("""COMPUTED_VALUE"""),"醒腦咖啡豆") -> 醒腦咖啡豆 | E18: =IMAGE("https://www.serebii.net/pokemonsleep/ingredients/"&SUBSTITUTE(LOWER(B18)," ","",)&".png") | F18: 82.13 | I18: 1.3 | J18: 創建以AP（應用日產）評估料理的總效率的頁面。公式簡化為（一日料理總能量*爆擊倍率）/一日需佔隊伍位置數。由此可得量化的排行榜。
A19: =IFERROR(__xludf.DUMMYFUNCTION("""COMPUTED_VALUE"""),250.0) -> 250 | B19: =IFERROR(__xludf.DUMMYFUNCTION("""COMPUTED_VALUE"""),"Plump Pumpkin") -> Plump Pumpkin | C19: =IFERROR(__xludf.DUMMYFUNCTION("""COMPUTED_VALUE"""),18.0) -> 18 | D19: =IFERROR(__xludf.DUMMYFUNCTION("""COMPUTED_VALUE"""),"沉甸甸南瓜") -> 沉甸甸南瓜 | E19: =IMAGE("https://www.serebii.net/pokemonsleep/ingredients/"&SUBSTITUTE(LOWER(B19)," ","",)&".png") | F19: 1 | I19: 1.2 | J19: 創建以個人檔案計算一日料理的總效率的頁面。理論上，用戶輸入自定義，和計算頁面分割，能夠允許頁面美化和導出一個玩家的"個體值"——但我實在不會頁面設計。
A20: =IFERROR(__xludf.DUMMYFUNCTION("""COMPUTED_VALUE"""),162.0) -> 162 | B20: =IFERROR(__xludf.DUMMYFUNCTION("""COMPUTED_VALUE"""),"Glossy Avocado") -> Glossy Avocado | C20: =IFERROR(__xludf.DUMMYFUNCTION("""COMPUTED_VALUE"""),19.0) -> 19 | D20: =IFERROR(__xludf.DUMMYFUNCTION("""COMPUTED_VALUE"""),"嫩亮酪梨") -> 嫩亮酪梨 | E20: =IMAGE("https://www.serebii.net/pokemonsleep/ingredients/"&SUBSTITUTE(LOWER(B20)," ","",)&".png") | F20: 100 | I20: 1.1 | J20: 和食譜Sheet對齊（Importrange），不需要維護者付出額外勞動，即可自動更新觀看全食譜數據。放棄了高端大氣上檔次的VBA，使用大國工匠手填公式（所以只有十個料理，你有本事就自己去填去改，又不難（
I21: 1 | J21: 優化了自己大腦。放棄了非常酷炫的意義不明的複雜公式。優化了用戶體驗，現在第一頁是個人檔案，只有F行的個人日產和預估幫獎數要自己填寫。
I32: 計算日產時，建議以網頁滿活力，去除幫獎技能（5%）計算。是否考慮持有和其他因素可自行判斷。
I33: 應用日產以網頁滿活力、持有無上限、食M且性格加食減經驗計算。在無幫獎環境約可視為接近最優的產值（PR99），所以更適合追求PR95的玩家衡量標準。
D34: 填寫你計算的料理名 | F34: 填寫你預估的幫獎數 | G34: 已有幫獎 | I34: 懶得全填上IFERROR，勞煩計算日產時填個正數，至少填個1，我不想這裡限制玩家，因為填0的確有填0的好處。
D35: 覺醒力量濃湯 | F35: 1 | G35: {=IFERROR( LET( r, MATCH(D35, '食譜'!$B$3:$B$1000, 0) + 2, ingredients, { INDEX('食譜'!$J:$J, r), INDEX('食譜'!$L:$L, r), INDEX('食譜'!$N:$N, r), INDEX('食譜'!$P:$P, r) }, SUMPRODUCT(--(XLOOKUP(ingredients, $D$2:$D$30, $G$2:$G$30, "") = "Y")) ), 0)} -> 1
D36: 居合斬壽喜燒咖哩 | F36: 5.1 | G36: {=IFERROR( LET( r, MATCH(D36, '食譜'!$B$3:$B$1000, 0) + 2, ingredients, { INDEX('食譜'!$J:$J, r), INDEX('食譜'!$L:$L, r), INDEX('食譜'!$N:$N, r), INDEX('食譜'!$P:$P, r) }, SUMPRODUCT(--(XLOOKUP(ingredients, $D$2:$D$30, $G$2:$G$30, "") = "Y")) ), 0)} -> 2
D37: 茂盛焗烤酪梨 | F37: 1 | G37: {=IFERROR( LET( r, MATCH(D37, '食譜'!$B$3:$B$1000, 0) + 2, ingredients, { INDEX('食譜'!$J:$J, r), INDEX('食譜'!$L:$L, r), INDEX('食譜'!$N:$N, r), INDEX('食譜'!$P:$P, r) }, SUMPRODUCT(--(XLOOKUP(ingredients, $D$2:$D$30, $G$2:$G$30, "") = "Y")) ), 0)} -> 1
D38: 重踏酪梨醬脆片 | F38: 0 | G38: {=IFERROR( LET( r, MATCH(D38, '食譜'!$B$3:$B$1000, 0) + 2, ingredients, { INDEX('食譜'!$J:$J, r), INDEX('食譜'!$L:$L, r), INDEX('食譜'!$N:$N, r), INDEX('食譜'!$P:$P, r) }, SUMPRODUCT(--(XLOOKUP(ingredients, $D$2:$D$30, $G$2:$G$30, "") = "Y")) ), 0)} -> 2
D39: 蘋果酸優格沙拉 | F39: 1 | G39: {=IFERROR( LET( r, MATCH(D39, '食譜'!$B$3:$B$1000, 0) + 2, ingredients, { INDEX('食譜'!$J:$J, r), INDEX('食譜'!$L:$L, r), INDEX('食譜'!$N:$N, r), INDEX('食譜'!$P:$P, r) }, SUMPRODUCT(--(XLOOKUP(ingredients, $D$2:$D$30, $G$2:$G$30, "") = "Y")) ), 0)} -> 1
D40: 不服輸咖啡沙拉 | F40: 2 | G40: {=IFERROR( LET( r, MATCH(D40, '食譜'!$B$3:$B$1000, 0) + 2, ingredients, { INDEX('食譜'!$J:$J, r), INDEX('食譜'!$L:$L, r), INDEX('食譜'!$N:$N, r), INDEX('食譜'!$P:$P, r) }, SUMPRODUCT(--(XLOOKUP(ingredients, $D$2:$D$30, $G$2:$G$30, "") = "Y")) ), 0)} -> 2
D41: 採蜜巧克力格子鬆餅 | F41: 1 | G41: {=IFERROR( LET( r, MATCH(D41, '食譜'!$B$3:$B$1000, 0) + 2, ingredients, { INDEX('食譜'!$J:$J, r), INDEX('食譜'!$L:$L, r), INDEX('食譜'!$N:$N, r), INDEX('食譜'!$P:$P, r) }, SUMPRODUCT(--(XLOOKUP(ingredients, $D$2:$D$30, $G$2:$G$30, "") = "Y")) ), 0)} -> 1
D42: 心跳加速鬼面鬆餅 | F42: 2 | G42: {=IFERROR( LET( r, MATCH(D42, '食譜'!$B$3:$B$1000, 0) + 2, ingredients, { INDEX('食譜'!$J:$J, r), INDEX('食譜'!$L:$L, r), INDEX('食譜'!$N:$N, r), INDEX('食譜'!$P:$P, r) }, SUMPRODUCT(--(XLOOKUP(ingredients, $D$2:$D$30, $G$2:$G$30, "") = "Y")) ), 0)} -> 0
D43: 土王閃電泡芙 | F43: 0 | G43: {=IFERROR( LET( r, MATCH(D43, '食譜'!$B$3:$B$1000, 0) + 2, ingredients, { INDEX('食譜'!$J:$J, r), INDEX('食譜'!$L:$L, r), INDEX('食譜'!$N:$N, r), INDEX('食譜'!$P:$P, r) }, SUMPRODUCT(--(XLOOKUP(ingredients, $D$2:$D$30, $G$2:$G$30, "") = "Y")) ), 0)} -> 0
D44: 電光香料可樂 | F44: 0 | G44: {=IFERROR( LET( r, MATCH(D44, '食譜'!$B$3:$B$1000, 0) + 2, ingredients, { INDEX('食譜'!$J:$J, r), INDEX('食譜'!$L:$L, r), INDEX('食譜'!$N:$N, r), INDEX('食譜'!$P:$P, r) }, SUMPRODUCT(--(XLOOKUP(ingredients, $D$2:$D$30, $G$2:$G$30, "") = "Y")) ), 0)} -> 2

Sheet 我的食材效率
A1: 食材基礎分 | B1: 英文名 | C1: ID | D1: 食材名 | E1: 食材圖 | F1: 我的日產（MP） | G1: 應用日產（AP） | H1: MP/AP | I1: 一餐需 | J1: 對應最高級料理為 | K1: 三餐需（BLD） | L1: MP/BLD | M1: AP/BLD
A2: =IFERROR(__xludf.DUMMYFUNCTION("IFERROR(SORT(FILTER(ing_table, INDEX(ing_table, 0, 1) <> """"), 1, TRUE))"),90.0) -> 90 | B2: =IFERROR(__xludf.DUMMYFUNCTION("""COMPUTED_VALUE"""),"Fancy Apple") -> Fancy Apple | C2: =IFERROR(__xludf.DUMMYFUNCTION("""COMPUTED_VALUE"""),5.0) -> 5 | D2: =IFERROR(__xludf.DUMMYFUNCTION("""COMPUTED_VALUE"""),"特選蘋果") -> 特選蘋果 | E2: =IFERROR(__xludf.DUMMYFUNCTION("""COMPUTED_VALUE"""),"") | F2: =IFERROR(__xludf.DUMMYFUNCTION("""COMPUTED_VALUE"""),82.96) -> 82.96 | G2: =IFERROR(VLOOKUP(D2, '應用日產（AP）'!A:C, 3, FALSE), 0) -> 163.61 | H2: =F2/G2 -> 0.50705947 | I2: =IFERROR(__xludf.DUMMYFUNCTION("IFERROR((MAX(FILTER({'食譜'!$K$3:$K$1000; '食譜'!$M$3:$M$1000; '食譜'!$O$3:$O$1000; '食譜'!$Q$3:$Q$1000}, {'食譜'!$J$3:$J$1000; '食譜'!$L$3:$L$1000; '食譜'!$N$3:$N$1000; '食譜'!$P$3:$P$1000} = $D2))), """")"),35.0) -> 35 | J2: =IFERROR(__xludf.DUMMYFUNCTION("IFERROR(INDEX(FILTER({'食譜'!$B$3:$B$1000; '食譜'!$B$3:$B$1000; '食譜'!$B$3:$B$1000; '食譜'!$B$3:$B$1000}, {'食譜'!$J$3:$J$1000; '食譜'!$L$3:$L$1000; '食譜'!$N$3:$N$1000; '食譜'!$P$3:$P$1000}=D2, {'食譜'!$K$3:$K$1000; '食譜'!$M$3:$M$1000; '食譜'!$O$3:$O$1000; '食譜'!$Q$3:$Q$1000"&"}=MAX(FILTER({'食譜'!$K$3:$K$1000; '食譜'!$M$3:$M$1000; '食譜'!$O$3:$O$1000; '食譜'!$Q$3:$Q$1000}, {'食譜'!$J$3:$J$1000; '食譜'!$L$3:$L$1000; '食譜'!$N$3:$N$1000; '食譜'!$P$3:$P$1000}=D2))), 1), """")"),"電光香料可樂") -> 電光香料可樂 | K2: =I2*3 -> 105 | L2: =F2/K2 -> 0.79009524 | M2: =G2/K2 -> 1.5581905
A3: =IFERROR(__xludf.DUMMYFUNCTION("""COMPUTED_VALUE"""),98.0) -> 98 | B3: =IFERROR(__xludf.DUMMYFUNCTION("""COMPUTED_VALUE"""),"Moomoo Milk") -> Moomoo Milk | C3: =IFERROR(__xludf.DUMMYFUNCTION("""COMPUTED_VALUE"""),8.0) -> 8 | D3: =IFERROR(__xludf.DUMMYFUNCTION("""COMPUTED_VALUE"""),"哞哞鮮奶") -> 哞哞鮮奶 | E3: =IFERROR(__xludf.DUMMYFUNCTION("""COMPUTED_VALUE"""),"") | F3: =IFERROR(__xludf.DUMMYFUNCTION("""COMPUTED_VALUE"""),120.82) -> 120.82 | G3: =IFERROR(VLOOKUP(D3, '應用日產（AP）'!A:C, 3, FALSE), 0) -> 161.87 | H3: =F3/G3 -> 0.74640143 | I3: =IFERROR(__xludf.DUMMYFUNCTION("IFERROR((MAX(FILTER({'食譜'!$K$3:$K$1000; '食譜'!$M$3:$M$1000; '食譜'!$O$3:$O$1000; '食譜'!$Q$3:$Q$1000}, {'食譜'!$J$3:$J$1000; '食譜'!$L$3:$L$1000; '食譜'!$N$3:$N$1000; '食譜'!$P$3:$P$1000} = $D3))), """")"),41.0) -> 41 | J3: =IFERROR(__xludf.DUMMYFUNCTION("IFERROR(INDEX(FILTER({'食譜'!$B$3:$B$1000; '食譜'!$B$3:$B$1000; '食譜'!$B$3:$B$1000; '食譜'!$B$3:$B$1000}, {'食譜'!$J$3:$J$1000; '食譜'!$L$3:$L$1000; '食譜'!$N$3:$N$1000; '食譜'!$P$3:$P$1000}=D3, {'食譜'!$K$3:$K$1000; '食譜'!$M$3:$M$1000; '食譜'!$O$3:$O$1000; '食譜'!$Q$3:$Q$1000"&"}=MAX(FILTER({'食譜'!$K$3:$K$1000; '食譜'!$M$3:$M$1000; '食譜'!$O$3:$O$1000; '食譜'!$Q$3:$Q$1000}, {'食譜'!$J$3:$J$1000; '食譜'!$L$3:$L$1000; '食譜'!$N$3:$N$1000; '食譜'!$P$3:$P$1000}=D3))), 1), """")"),"茂盛焗烤酪梨") -> 茂盛焗烤酪梨 | K3: =I3*3 -> 123 | L3: =F3/K3 -> 0.98227642 | M3: =G3/K3 -> 1.3160163
A4: =IFERROR(__xludf.DUMMYFUNCTION("""COMPUTED_VALUE"""),100.0) -> 100 | B4: =IFERROR(__xludf.DUMMYFUNCTION("""COMPUTED_VALUE"""),"Greengrass Soybeans") -> Greengrass Soybeans | C4: =IFERROR(__xludf.DUMMYFUNCTION("""COMPUTED_VALUE"""),15.0) -> 15 | D4: =IFERROR(__xludf.DUMMYFUNCTION("""COMPUTED_VALUE"""),"萌綠大豆") -> 萌綠大豆 | E4: =IFERROR(__xludf.DUMMYFUNCTION("""COMPUTED_VALUE"""),"") | F4: =IFERROR(__xludf.DUMMYFUNCTION("""COMPUTED_VALUE"""),109.12) -> 109.12 | G4: =IFERROR(VLOOKUP(D4, '應用日產（AP）'!A:C, 3, FALSE), 0) -> 148.65 | H4: =F4/G4 -> 0.73407333 | I4: =IFERROR(__xludf.DUMMYFUNCTION("IFERROR((MAX(FILTER({'食譜'!$K$3:$K$1000; '食譜'!$M$3:$M$1000; '食譜'!$O$3:$O$1000; '食譜'!$Q$3:$Q$1000}, {'食譜'!$J$3:$J$1000; '食譜'!$L$3:$L$1000; '食譜'!$N$3:$N$1000; '食譜'!$P$3:$P$1000} = $D4))), """")"),28.0) -> 28 | J4: =IFERROR(__xludf.DUMMYFUNCTION("IFERROR(INDEX(FILTER({'食譜'!$B$3:$B$1000; '食譜'!$B$3:$B$1000; '食譜'!$B$3:$B$1000; '食譜'!$B$3:$B$1000}, {'食譜'!$J$3:$J$1000; '食譜'!$L$3:$L$1000; '食譜'!$N$3:$N$1000; '食譜'!$P$3:$P$1000}=D4, {'食譜'!$K$3:$K$1000; '食譜'!$M$3:$M$1000; '食譜'!$O$3:$O$1000; '食譜'!$Q$3:$Q$1000"&"}=MAX(FILTER({'食譜'!$K$3:$K$1000; '食譜'!$M$3:$M$1000; '食譜'!$O$3:$O$1000; '食譜'!$Q$3:$Q$1000}, {'食譜'!$J$3:$J$1000; '食譜'!$L$3:$L$1000; '食譜'!$N$3:$N$1000; '食譜'!$P$3:$P$1000}=D4))), 1), """")"),"覺醒力量濃湯") -> 覺醒力量濃湯 | K4: =I4*3 -> 84 | L4: =F4/K4 -> 1.2990476 | M4: =G4/K4 -> 1.7696429
A5: =IFERROR(__xludf.DUMMYFUNCTION("""COMPUTED_VALUE"""),101.0) -> 101 | B5: =IFERROR(__xludf.DUMMYFUNCTION("""COMPUTED_VALUE"""),"Honey") -> Honey | C5: =IFERROR(__xludf.DUMMYFUNCTION("""COMPUTED_VALUE"""),9.0) -> 9 | D5: =IFERROR(__xludf.DUMMYFUNCTION("""COMPUTED_VALUE"""),"甜甜蜜") -> 甜甜蜜 | E5: =IFERROR(__xludf.DUMMYFUNCTION("""COMPUTED_VALUE"""),"") | F5: =IFERROR(__xludf.DUMMYFUNCTION("""COMPUTED_VALUE"""),146.31) -> 146.31 | G5: =IFERROR(VLOOKUP(D5, '應用日產（AP）'!A:C, 3, FALSE), 0) -> 156.57 | H5: =F5/G5 -> 0.9344702 | I5: =IFERROR(__xludf.DUMMYFUNCTION("IFERROR((MAX(FILTER({'食譜'!$K$3:$K$1000; '食譜'!$M$3:$M$1000; '食譜'!$O$3:$O$1000; '食譜'!$Q$3:$Q$1000}, {'食譜'!$J$3:$J$1000; '食譜'!$L$3:$L$1000; '食譜'!$N$3:$N$1000; '食譜'!$P$3:$P$1000} = $D5))), """")"),38.0) -> 38 | J5: =IFERROR(__xludf.DUMMYFUNCTION("IFERROR(INDEX(FILTER({'食譜'!$B$3:$B$1000; '食譜'!$B$3:$B$1000; '食譜'!$B$3:$B$1000; '食譜'!$B$3:$B$1000}, {'食譜'!$J$3:$J$1000; '食譜'!$L$3:$L$1000; '食譜'!$N$3:$N$1000; '食譜'!$P$3:$P$1000}=D5, {'食譜'!$K$3:$K$1000; '食譜'!$M$3:$M$1000; '食譜'!$O$3:$O$1000; '食譜'!$Q$3:$Q$1000"&"}=MAX(FILTER({'食譜'!$K$3:$K$1000; '食譜'!$M$3:$M$1000; '食譜'!$O$3:$O$1000; '食譜'!$Q$3:$Q$1000}, {'食譜'!$J$3:$J$1000; '食譜'!$L$3:$L$1000; '食譜'!$N$3:$N$1000; '食譜'!$P$3:$P$1000}=D5))), 1), """")"),"採蜜巧克力格子鬆餅") -> 採蜜巧克力格子鬆餅 | K5: =I5*3 -> 114 | L5: =F5/K5 -> 1.2834211 | M5: =G5/K5 -> 1.3734211
A6: =IFERROR(__xludf.DUMMYFUNCTION("""COMPUTED_VALUE"""),103.0) -> 103 | B6: =IFERROR(__xludf.DUMMYFUNCTION("""COMPUTED_VALUE"""),"Bean Sausage") -> Bean Sausage | C6: =IFERROR(__xludf.DUMMYFUNCTION("""COMPUTED_VALUE"""),7.0) -> 7 | D6: =IFERROR(__xludf.DUMMYFUNCTION("""COMPUTED_VALUE"""),"豆製肉") -> 豆製肉 | E6: =IFERROR(__xludf.DUMMYFUNCTION("""COMPUTED_VALUE"""),"") | F6: =IFERROR(__xludf.DUMMYFUNCTION("""COMPUTED_VALUE"""),105.53) -> 105.53 | G6: =IFERROR(VLOOKUP(D6, '應用日產（AP）'!A:C, 3, FALSE), 0) -> 157.5 | H6: =F6/G6 -> 0.67003175 | I6: =IFERROR(__xludf.DUMMYFUNCTION("IFERROR((MAX(FILTER({'食譜'!$K$3:$K$1000; '食譜'!$M$3:$M$1000; '食譜'!$O$3:$O$1000; '食譜'!$Q$3:$Q$1000}, {'食譜'!$J$3:$J$1000; '食譜'!$L$3:$L$1000; '食譜'!$N$3:$N$1000; '食譜'!$P$3:$P$1000} = $D6))), """")"),28.0) -> 28 | J6: =IFERROR(__xludf.DUMMYFUNCTION("IFERROR(INDEX(FILTER({'食譜'!$B$3:$B$1000; '食譜'!$B$3:$B$1000; '食譜'!$B$3:$B$1000; '食譜'!$B$3:$B$1000}, {'食譜'!$J$3:$J$1000; '食譜'!$L$3:$L$1000; '食譜'!$N$3:$N$1000; '食譜'!$P$3:$P$1000}=D6, {'食譜'!$K$3:$K$1000; '食譜'!$M$3:$M$1000; '食譜'!$O$3:$O$1000; '食譜'!$Q$3:$Q$1000"&"}=MAX(FILTER({'食譜'!$K$3:$K$1000; '食譜'!$M$3:$M$1000; '食譜'!$O$3:$O$1000; '食譜'!$Q$3:$Q$1000}, {'食譜'!$J$3:$J$1000; '食譜'!$L$3:$L$1000; '食譜'!$N$3:$N$1000; '食譜'!$P$3:$P$1000}=D6))), 1), """")"),"不服輸咖啡沙拉") -> 不服輸咖啡沙拉 | K6: =I6*3 -> 84 | L6: =F6/K6 -> 1.2563095 | M6: =G6/K6 -> 1.875
A7: =IFERROR(__xludf.DUMMYFUNCTION("""COMPUTED_VALUE"""),109.0) -> 109 | B7: =IFERROR(__xludf.DUMMYFUNCTION("""COMPUTED_VALUE"""),"Warming Ginger") -> Warming Ginger | C7: =IFERROR(__xludf.DUMMYFUNCTION("""COMPUTED_VALUE"""),11.0) -> 11 | D7: =IFERROR(__xludf.DUMMYFUNCTION("""COMPUTED_VALUE"""),"暖暖薑") -> 暖暖薑 | E7: =IFERROR(__xludf.DUMMYFUNCTION("""COMPUTED_VALUE"""),"") | F7: =IFERROR(__xludf.DUMMYFUNCTION("""COMPUTED_VALUE"""),115.87) -> 115.87 | G7: =IFERROR(VLOOKUP(D7, '應用日產（AP）'!A:C, 3, FALSE), 0) -> 162.39 | H7: =F7/G7 -> 0.71352916 | I7: =IFERROR(__xludf.DUMMYFUNCTION("IFERROR((MAX(FILTER({'食譜'!$K$3:$K$1000; '食譜'!$M$3:$M$1000; '食譜'!$O$3:$O$1000; '食譜'!$Q$3:$Q$1000}, {'食譜'!$J$3:$J$1000; '食譜'!$L$3:$L$1000; '食譜'!$N$3:$N$1000; '食譜'!$P$3:$P$1000} = $D7))), """")"),20.0) -> 20 | J7: =IFERROR(__xludf.DUMMYFUNCTION("IFERROR(INDEX(FILTER({'食譜'!$B$3:$B$1000; '食譜'!$B$3:$B$1000; '食譜'!$B$3:$B$1000; '食譜'!$B$3:$B$1000}, {'食譜'!$J$3:$J$1000; '食譜'!$L$3:$L$1000; '食譜'!$N$3:$N$1000; '食譜'!$P$3:$P$1000}=D7, {'食譜'!$K$3:$K$1000; '食譜'!$M$3:$M$1000; '食譜'!$O$3:$O$1000; '食譜'!$Q$3:$Q$1000"&"}=MAX(FILTER({'食譜'!$K$3:$K$1000; '食譜'!$M$3:$M$1000; '食譜'!$O$3:$O$1000; '食譜'!$Q$3:$Q$1000}, {'食譜'!$J$3:$J$1000; '食譜'!$L$3:$L$1000; '食譜'!$N$3:$N$1000; '食譜'!$P$3:$P$1000}=D7))), 1), """")"),"茶會玉米司康") -> 茶會玉米司康 | K7: =I7*3 -> 60 | L7: =F7/K7 -> 1.9311667 | M7: =G7/K7 -> 2.7065
A8: =IFERROR(__xludf.DUMMYFUNCTION("""COMPUTED_VALUE"""),110.0) -> 110 | B8: =IFERROR(__xludf.DUMMYFUNCTION("""COMPUTED_VALUE"""),"Snoozy Tomato") -> Snoozy Tomato | C8: =IFERROR(__xludf.DUMMYFUNCTION("""COMPUTED_VALUE"""),12.0) -> 12 | D8: =IFERROR(__xludf.DUMMYFUNCTION("""COMPUTED_VALUE"""),"好眠番茄") -> 好眠番茄 | E8: =IFERROR(__xludf.DUMMYFUNCTION("""COMPUTED_VALUE"""),"") | F8: =IFERROR(__xludf.DUMMYFUNCTION("""COMPUTED_VALUE"""),98.54) -> 98.54 | G8: =IFERROR(VLOOKUP(D8, '應用日產（AP）'!A:C, 3, FALSE), 0) -> 137.56 | H8: =F8/G8 -> 0.71634196 | I8: =IFERROR(__xludf.DUMMYFUNCTION("IFERROR((MAX(FILTER({'食譜'!$K$3:$K$1000; '食譜'!$M$3:$M$1000; '食譜'!$O$3:$O$1000; '食譜'!$Q$3:$Q$1000}, {'食譜'!$J$3:$J$1000; '食譜'!$L$3:$L$1000; '食譜'!$N$3:$N$1000; '食譜'!$P$3:$P$1000} = $D8))), """")"),29.0) -> 29 | J8: =IFERROR(__xludf.DUMMYFUNCTION("IFERROR(INDEX(FILTER({'食譜'!$B$3:$B$1000; '食譜'!$B$3:$B$1000; '食譜'!$B$3:$B$1000; '食譜'!$B$3:$B$1000}, {'食譜'!$J$3:$J$1000; '食譜'!$L$3:$L$1000; '食譜'!$N$3:$N$1000; '食譜'!$P$3:$P$1000}=D8, {'食譜'!$K$3:$K$1000; '食譜'!$M$3:$M$1000; '食譜'!$O$3:$O$1000; '食譜'!$Q$3:$Q$1000"&"}=MAX(FILTER({'食譜'!$K$3:$K$1000; '食譜'!$M$3:$M$1000; '食譜'!$O$3:$O$1000; '食譜'!$Q$3:$Q$1000}, {'食譜'!$J$3:$J$1000; '食譜'!$L$3:$L$1000; '食譜'!$N$3:$N$1000; '食譜'!$P$3:$P$1000}=D8))), 1), """")"),"心跳加速鬼面鬆餅") -> 心跳加速鬼面鬆餅 | K8: =I8*3 -> 87 | L8: =F8/K8 -> 1.1326437 | M8: =G8/K8 -> 1.5811494
A9: =IFERROR(__xludf.DUMMYFUNCTION("""COMPUTED_VALUE"""),115.0) -> 115 | B9: =IFERROR(__xludf.DUMMYFUNCTION("""COMPUTED_VALUE"""),"Fancy Egg") -> Fancy Egg | C9: =IFERROR(__xludf.DUMMYFUNCTION("""COMPUTED_VALUE"""),3.0) -> 3 | D9: =IFERROR(__xludf.DUMMYFUNCTION("""COMPUTED_VALUE"""),"特選蛋") -> 特選蛋 | E9: =IFERROR(__xludf.DUMMYFUNCTION("""COMPUTED_VALUE"""),"") | F9: =IFERROR(__xludf.DUMMYFUNCTION("""COMPUTED_VALUE"""),91.73) -> 91.73 | G9: =IFERROR(VLOOKUP(D9, '應用日產（AP）'!A:C, 3, FALSE), 0) -> 127.29 | H9: =F9/G9 -> 0.72063791 | I9: =IFERROR(__xludf.DUMMYFUNCTION("IFERROR((MAX(FILTER({'食譜'!$K$3:$K$1000; '食譜'!$M$3:$M$1000; '食譜'!$O$3:$O$1000; '食譜'!$Q$3:$Q$1000}, {'食譜'!$J$3:$J$1000; '食譜'!$L$3:$L$1000; '食譜'!$N$3:$N$1000; '食譜'!$P$3:$P$1000} = $D9))), """")"),35.0) -> 35 | J9: =IFERROR(__xludf.DUMMYFUNCTION("IFERROR(INDEX(FILTER({'食譜'!$B$3:$B$1000; '食譜'!$B$3:$B$1000; '食譜'!$B$3:$B$1000; '食譜'!$B$3:$B$1000}, {'食譜'!$J$3:$J$1000; '食譜'!$L$3:$L$1000; '食譜'!$N$3:$N$1000; '食譜'!$P$3:$P$1000}=D9, {'食譜'!$K$3:$K$1000; '食譜'!$M$3:$M$1000; '食譜'!$O$3:$O$1000; '食譜'!$Q$3:$Q$1000"&"}=MAX(FILTER({'食譜'!$K$3:$K$1000; '食譜'!$M$3:$M$1000; '食譜'!$O$3:$O$1000; '食譜'!$Q$3:$Q$1000}, {'食譜'!$J$3:$J$1000; '食譜'!$L$3:$L$1000; '食譜'!$N$3:$N$1000; '食譜'!$P$3:$P$1000}=D9))), 1), """")"),"蘋果酸優格沙拉") -> 蘋果酸優格沙拉 | K9: =I9*3 -> 105 | L9: =F9/K9 -> 0.87361905 | M9: =G9/K9 -> 1.2122857
A10: =IFERROR(__xludf.DUMMYFUNCTION("""COMPUTED_VALUE"""),121.0) -> 121 | B10: =IFERROR(__xludf.DUMMYFUNCTION("""COMPUTED_VALUE"""),"Pure Oil") -> Pure Oil | C10: =IFERROR(__xludf.DUMMYFUNCTION("""COMPUTED_VALUE"""),10.0) -> 10 | D10: =IFERROR(__xludf.DUMMYFUNCTION("""COMPUTED_VALUE"""),"純粹油") -> 純粹油 | E10: =IFERROR(__xludf.DUMMYFUNCTION("""COMPUTED_VALUE"""),"") | F10: =IFERROR(__xludf.DUMMYFUNCTION("""COMPUTED_VALUE"""),56.61) -> 56.61 | G10: =IFERROR(VLOOKUP(D10, '應用日產（AP）'!A:C, 3, FALSE), 0) -> 111.06 | H10: =F10/G10 -> 0.50972447 | I10: =IFERROR(__xludf.DUMMYFUNCTION("IFERROR((MAX(FILTER({'食譜'!$K$3:$K$1000; '食譜'!$M$3:$M$1000; '食譜'!$O$3:$O$1000; '食譜'!$Q$3:$Q$1000}, {'食譜'!$J$3:$J$1000; '食譜'!$L$3:$L$1000; '食譜'!$N$3:$N$1000; '食譜'!$P$3:$P$1000} = $D10))), """")"),32.0) -> 32 | J10: =IFERROR(__xludf.DUMMYFUNCTION("IFERROR(INDEX(FILTER({'食譜'!$B$3:$B$1000; '食譜'!$B$3:$B$1000; '食譜'!$B$3:$B$1000; '食譜'!$B$3:$B$1000}, {'食譜'!$J$3:$J$1000; '食譜'!$L$3:$L$1000; '食譜'!$N$3:$N$1000; '食譜'!$P$3:$P$1000}=D10, {'食譜'!$K$3:$K$1000; '食譜'!$M$3:$M$1000; '食譜'!$O$3:$O$1000; '食譜'!$Q$3:$Q$100"&"0}=MAX(FILTER({'食譜'!$K$3:$K$1000; '食譜'!$M$3:$M$1000; '食譜'!$O$3:$O$1000; '食譜'!$Q$3:$Q$1000}, {'食譜'!$J$3:$J$1000; '食譜'!$L$3:$L$1000; '食譜'!$N$3:$N$1000; '食譜'!$P$3:$P$1000}=D10))), 1), """")"),"茂盛焗烤酪梨") -> 茂盛焗烤酪梨 | K10: =I10*3 -> 96 | L10: =F10/K10 -> 0.5896875 | M10: =G10/K10 -> 1.156875
A11: =IFERROR(__xludf.DUMMYFUNCTION("""COMPUTED_VALUE"""),124.0) -> 124 | B11: =IFERROR(__xludf.DUMMYFUNCTION("""COMPUTED_VALUE"""),"Soft Potato") -> Soft Potato | C11: =IFERROR(__xludf.DUMMYFUNCTION("""COMPUTED_VALUE"""),4.0) -> 4 | D11: =IFERROR(__xludf.DUMMYFUNCTION("""COMPUTED_VALUE"""),"窩心洋芋") -> 窩心洋芋 | E11: =IFERROR(__xludf.DUMMYFUNCTION("""COMPUTED_VALUE"""),"") | F11: =IFERROR(__xludf.DUMMYFUNCTION("""COMPUTED_VALUE"""),90.57) -> 90.57 | G11: =IFERROR(VLOOKUP(D11, '應用日產（AP）'!A:C, 3, FALSE), 0) -> 120.45 | H11: =F11/G11 -> 0.75193026 | I11: =IFERROR(__xludf.DUMMYFUNCTION("IFERROR((MAX(FILTER({'食譜'!$K$3:$K$1000; '食譜'!$M$3:$M$1000; '食譜'!$O$3:$O$1000; '食譜'!$Q$3:$Q$1000}, {'食譜'!$J$3:$J$1000; '食譜'!$L$3:$L$1000; '食譜'!$N$3:$N$1000; '食譜'!$P$3:$P$1000} = $D11))), """")"),30.0) -> 30 | J11: =IFERROR(__xludf.DUMMYFUNCTION("IFERROR(INDEX(FILTER({'食譜'!$B$3:$B$1000; '食譜'!$B$3:$B$1000; '食譜'!$B$3:$B$1000; '食譜'!$B$3:$B$1000}, {'食譜'!$J$3:$J$1000; '食譜'!$L$3:$L$1000; '食譜'!$N$3:$N$1000; '食譜'!$P$3:$P$1000}=D11, {'食譜'!$K$3:$K$1000; '食譜'!$M$3:$M$1000; '食譜'!$O$3:$O$1000; '食譜'!$Q$3:$Q$100"&"0}=MAX(FILTER({'食譜'!$K$3:$K$1000; '食譜'!$M$3:$M$1000; '食譜'!$O$3:$O$1000; '食譜'!$Q$3:$Q$1000}, {'食譜'!$J$3:$J$1000; '食譜'!$L$3:$L$1000; '食譜'!$N$3:$N$1000; '食譜'!$P$3:$P$1000}=D11))), 1), """")"),"大塊滿滿熱水沙拉") -> 大塊滿滿熱水沙拉 | K11: =I11*3 -> 90 | L11: =F11/K11 -> 1.0063333 | M11: =G11/K11 -> 1.3383333
A12: =IFERROR(__xludf.DUMMYFUNCTION("""COMPUTED_VALUE"""),130.0) -> 130 | B12: =IFERROR(__xludf.DUMMYFUNCTION("""COMPUTED_VALUE"""),"Fiery Herb") -> Fiery Herb | C12: =IFERROR(__xludf.DUMMYFUNCTION("""COMPUTED_VALUE"""),6.0) -> 6 | D12: =IFERROR(__xludf.DUMMYFUNCTION("""COMPUTED_VALUE"""),"火辣香草") -> 火辣香草 | E12: =IFERROR(__xludf.DUMMYFUNCTION("""COMPUTED_VALUE"""),"") | F12: =IFERROR(__xludf.DUMMYFUNCTION("""COMPUTED_VALUE"""),112.91) -> 112.91 | G12: =IFERROR(VLOOKUP(D12, '應用日產（AP）'!A:C, 3, FALSE), 0) -> 168.36 | H12: =F12/G12 -> 0.67064623 | I12: =IFERROR(__xludf.DUMMYFUNCTION("IFERROR((MAX(FILTER({'食譜'!$K$3:$K$1000; '食譜'!$M$3:$M$1000; '食譜'!$O$3:$O$1000; '食譜'!$Q$3:$Q$1000}, {'食譜'!$J$3:$J$1000; '食譜'!$L$3:$L$1000; '食譜'!$N$3:$N$1000; '食譜'!$P$3:$P$1000} = $D12))), """")"),30.0) -> 30 | J12: =IFERROR(__xludf.DUMMYFUNCTION("IFERROR(INDEX(FILTER({'食譜'!$B$3:$B$1000; '食譜'!$B$3:$B$1000; '食譜'!$B$3:$B$1000; '食譜'!$B$3:$B$1000}, {'食譜'!$J$3:$J$1000; '食譜'!$L$3:$L$1000; '食譜'!$N$3:$N$1000; '食譜'!$P$3:$P$1000}=D12, {'食譜'!$K$3:$K$1000; '食譜'!$M$3:$M$1000; '食譜'!$O$3:$O$1000; '食譜'!$Q$3:$Q$100"&"0}=MAX(FILTER({'食譜'!$K$3:$K$1000; '食譜'!$M$3:$M$1000; '食譜'!$O$3:$O$1000; '食譜'!$Q$3:$Q$1000}, {'食譜'!$J$3:$J$1000; '食譜'!$L$3:$L$1000; '食譜'!$N$3:$N$1000; '食譜'!$P$3:$P$1000}=D12))), 1), """")"),"重踏酪梨醬脆片") -> 重踏酪梨醬脆片 | K12: =I12*3 -> 90 | L12: =F12/K12 -> 1.2545556 | M12: =G12/K12 -> 1.8706667
A13: =IFERROR(__xludf.DUMMYFUNCTION("""COMPUTED_VALUE"""),140.0) -> 140 | B13: =IFERROR(__xludf.DUMMYFUNCTION("""COMPUTED_VALUE"""),"Greengrass Corn") -> Greengrass Corn | C13: =IFERROR(__xludf.DUMMYFUNCTION("""COMPUTED_VALUE"""),16.0) -> 16 | D13: =IFERROR(__xludf.DUMMYFUNCTION("""COMPUTED_VALUE"""),"萌綠玉米") -> 萌綠玉米 | E13: =IFERROR(__xludf.DUMMYFUNCTION("""COMPUTED_VALUE"""),"") | F13: =IFERROR(__xludf.DUMMYFUNCTION("""COMPUTED_VALUE"""),120.13) -> 120.13 | G13: =IFERROR(VLOOKUP(D13, '應用日產（AP）'!A:C, 3, FALSE), 0) -> 134.79 | H13: =F13/G13 -> 0.89123822 | I13: =IFERROR(__xludf.DUMMYFUNCTION("IFERROR((MAX(FILTER({'食譜'!$K$3:$K$1000; '食譜'!$M$3:$M$1000; '食譜'!$O$3:$O$1000; '食譜'!$Q$3:$Q$1000}, {'食譜'!$J$3:$J$1000; '食譜'!$L$3:$L$1000; '食譜'!$N$3:$N$1000; '食譜'!$P$3:$P$1000} = $D13))), """")"),28.0) -> 28 | J13: =IFERROR(__xludf.DUMMYFUNCTION("IFERROR(INDEX(FILTER({'食譜'!$B$3:$B$1000; '食譜'!$B$3:$B$1000; '食譜'!$B$3:$B$1000; '食譜'!$B$3:$B$1000}, {'食譜'!$J$3:$J$1000; '食譜'!$L$3:$L$1000; '食譜'!$N$3:$N$1000; '食譜'!$P$3:$P$1000}=D13, {'食譜'!$K$3:$K$1000; '食譜'!$M$3:$M$1000; '食譜'!$O$3:$O$1000; '食譜'!$Q$3:$Q$100"&"0}=MAX(FILTER({'食譜'!$K$3:$K$1000; '食譜'!$M$3:$M$1000; '食譜'!$O$3:$O$1000; '食譜'!$Q$3:$Q$1000}, {'食譜'!$J$3:$J$1000; '食譜'!$L$3:$L$1000; '食譜'!$N$3:$N$1000; '食譜'!$P$3:$P$1000}=D13))), 1), """")"),"採蜜巧克力格子鬆餅") -> 採蜜巧克力格子鬆餅 | K13: =I13*3 -> 84 | L13: =F13/K13 -> 1.430119 | M13: =G13/K13 -> 1.6046429
A14: =IFERROR(__xludf.DUMMYFUNCTION("""COMPUTED_VALUE"""),151.0) -> 151 | B14: =IFERROR(__xludf.DUMMYFUNCTION("""COMPUTED_VALUE"""),"Soothing Cacao") -> Soothing Cacao | C14: =IFERROR(__xludf.DUMMYFUNCTION("""COMPUTED_VALUE"""),13.0) -> 13 | D14: =IFERROR(__xludf.DUMMYFUNCTION("""COMPUTED_VALUE"""),"放鬆可可") -> 放鬆可可 | E14: =IFERROR(__xludf.DUMMYFUNCTION("""COMPUTED_VALUE"""),"") | F14: =IFERROR(__xludf.DUMMYFUNCTION("""COMPUTED_VALUE"""),76.86) -> 76.86 | G14: =IFERROR(VLOOKUP(D14, '應用日產（AP）'!A:C, 3, FALSE), 0) -> 98.53 | H14: =F14/G14 -> 0.78006698 | I14: =IFERROR(__xludf.DUMMYFUNCTION("IFERROR((MAX(FILTER({'食譜'!$K$3:$K$1000; '食譜'!$M$3:$M$1000; '食譜'!$O$3:$O$1000; '食譜'!$Q$3:$Q$1000}, {'食譜'!$J$3:$J$1000; '食譜'!$L$3:$L$1000; '食譜'!$N$3:$N$1000; '食譜'!$P$3:$P$1000} = $D14))), """")"),30.0) -> 30 | J14: =IFERROR(__xludf.DUMMYFUNCTION("IFERROR(INDEX(FILTER({'食譜'!$B$3:$B$1000; '食譜'!$B$3:$B$1000; '食譜'!$B$3:$B$1000; '食譜'!$B$3:$B$1000}, {'食譜'!$J$3:$J$1000; '食譜'!$L$3:$L$1000; '食譜'!$N$3:$N$1000; '食譜'!$P$3:$P$1000}=D14, {'食譜'!$K$3:$K$1000; '食譜'!$M$3:$M$1000; '食譜'!$O$3:$O$1000; '食譜'!$Q$3:$Q$100"&"0}=MAX(FILTER({'食譜'!$K$3:$K$1000; '食譜'!$M$3:$M$1000; '食譜'!$O$3:$O$1000; '食譜'!$Q$3:$Q$1000}, {'食譜'!$J$3:$J$1000; '食譜'!$L$3:$L$1000; '食譜'!$N$3:$N$1000; '食譜'!$P$3:$P$1000}=D14))), 1), """")"),"土王閃電泡芙") -> 土王閃電泡芙 | K14: =I14*3 -> 90 | L14: =F14/K14 -> 0.854 | M14: =G14/K14 -> 1.0947778
A15: =IFERROR(__xludf.DUMMYFUNCTION("""COMPUTED_VALUE"""),153.0) -> 153 | B15: =IFERROR(__xludf.DUMMYFUNCTION("""COMPUTED_VALUE"""),"Rousing Coffee") -> Rousing Coffee | C15: =IFERROR(__xludf.DUMMYFUNCTION("""COMPUTED_VALUE"""),17.0) -> 17 | D15: =IFERROR(__xludf.DUMMYFUNCTION("""COMPUTED_VALUE"""),"醒腦咖啡豆") -> 醒腦咖啡豆 | E15: =IFERROR(__xludf.DUMMYFUNCTION("""COMPUTED_VALUE"""),"") | F15: =IFERROR(__xludf.DUMMYFUNCTION("""COMPUTED_VALUE"""),82.13) -> 82.13 | G15: =IFERROR(VLOOKUP(D15, '應用日產（AP）'!A:C, 3, FALSE), 0) -> 114.19 | H15: =F15/G15 -> 0.71923986 | I15: =IFERROR(__xludf.DUMMYFUNCTION("IFERROR((MAX(FILTER({'食譜'!$K$3:$K$1000; '食譜'!$M$3:$M$1000; '食譜'!$O$3:$O$1000; '食譜'!$Q$3:$Q$1000}, {'食譜'!$J$3:$J$1000; '食譜'!$L$3:$L$1000; '食譜'!$N$3:$N$1000; '食譜'!$P$3:$P$1000} = $D15))), """")"),28.0) -> 28 | J15: =IFERROR(__xludf.DUMMYFUNCTION("IFERROR(INDEX(FILTER({'食譜'!$B$3:$B$1000; '食譜'!$B$3:$B$1000; '食譜'!$B$3:$B$1000; '食譜'!$B$3:$B$1000}, {'食譜'!$J$3:$J$1000; '食譜'!$L$3:$L$1000; '食譜'!$N$3:$N$1000; '食譜'!$P$3:$P$1000}=D15, {'食譜'!$K$3:$K$1000; '食譜'!$M$3:$M$1000; '食譜'!$O$3:$O$1000; '食譜'!$Q$3:$Q$100"&"0}=MAX(FILTER({'食譜'!$K$3:$K$1000; '食譜'!$M$3:$M$1000; '食譜'!$O$3:$O$1000; '食譜'!$Q$3:$Q$1000}, {'食譜'!$J$3:$J$1000; '食譜'!$L$3:$L$1000; '食譜'!$N$3:$N$1000; '食譜'!$P$3:$P$1000}=D15))), 1), """")"),"不服輸咖啡沙拉") -> 不服輸咖啡沙拉 | K15: =I15*3 -> 84 | L15: =F15/K15 -> 0.9777381 | M15: =G15/K15 -> 1.3594048
A16: =IFERROR(__xludf.DUMMYFUNCTION("""COMPUTED_VALUE"""),162.0) -> 162 | B16: =IFERROR(__xludf.DUMMYFUNCTION("""COMPUTED_VALUE"""),"Glossy Avocado") -> Glossy Avocado | C16: =IFERROR(__xludf.DUMMYFUNCTION("""COMPUTED_VALUE"""),19.0) -> 19 | D16: =IFERROR(__xludf.DUMMYFUNCTION("""COMPUTED_VALUE"""),"嫩亮酪梨") -> 嫩亮酪梨 | E16: =IFERROR(__xludf.DUMMYFUNCTION("""COMPUTED_VALUE"""),"") | F16: =IFERROR(__xludf.DUMMYFUNCTION("""COMPUTED_VALUE"""),100.0) -> 100 | G16: =IFERROR(VLOOKUP(D16, '應用日產（AP）'!A:C, 3, FALSE), 0) -> 105.63 | H16: =F16/G16 -> 0.94670075 | I16: =IFERROR(__xludf.DUMMYFUNCTION("IFERROR((MAX(FILTER({'食譜'!$K$3:$K$1000; '食譜'!$M$3:$M$1000; '食譜'!$O$3:$O$1000; '食譜'!$Q$3:$Q$1000}, {'食譜'!$J$3:$J$1000; '食譜'!$L$3:$L$1000; '食譜'!$N$3:$N$1000; '食譜'!$P$3:$P$1000} = $D16))), """")"),28.0) -> 28 | J16: =IFERROR(__xludf.DUMMYFUNCTION("IFERROR(INDEX(FILTER({'食譜'!$B$3:$B$1000; '食譜'!$B$3:$B$1000; '食譜'!$B$3:$B$1000; '食譜'!$B$3:$B$1000}, {'食譜'!$J$3:$J$1000; '食譜'!$L$3:$L$1000; '食譜'!$N$3:$N$1000; '食譜'!$P$3:$P$1000}=D16, {'食譜'!$K$3:$K$1000; '食譜'!$M$3:$M$1000; '食譜'!$O$3:$O$1000; '食譜'!$Q$3:$Q$100"&"0}=MAX(FILTER({'食譜'!$K$3:$K$1000; '食譜'!$M$3:$M$1000; '食譜'!$O$3:$O$1000; '食譜'!$Q$3:$Q$1000}, {'食譜'!$J$3:$J$1000; '食譜'!$L$3:$L$1000; '食譜'!$N$3:$N$1000; '食譜'!$P$3:$P$1000}=D16))), 1), """")"),"重踏酪梨醬脆片") -> 重踏酪梨醬脆片 | K16: =I16*3 -> 84 | L16: =F16/K16 -> 1.1904762 | M16: =G16/K16 -> 1.2575
A17: =IFERROR(__xludf.DUMMYFUNCTION("""COMPUTED_VALUE"""),167.0) -> 167 | B17: =IFERROR(__xludf.DUMMYFUNCTION("""COMPUTED_VALUE"""),"Tasty Mushroom") -> Tasty Mushroom | C17: =IFERROR(__xludf.DUMMYFUNCTION("""COMPUTED_VALUE"""),2.0) -> 2 | D17: =IFERROR(__xludf.DUMMYFUNCTION("""COMPUTED_VALUE"""),"品鮮蘑菇") -> 品鮮蘑菇 | E17: =IFERROR(__xludf.DUMMYFUNCTION("""COMPUTED_VALUE"""),"") | F17: =IFERROR(__xludf.DUMMYFUNCTION("""COMPUTED_VALUE"""),46.76) -> 46.76 | G17: =IFERROR(VLOOKUP(D17, '應用日產（AP）'!A:C, 3, FALSE), 0) -> 92.67 | H17: =F17/G17 -> 0.50458617 | I17: =IFERROR(__xludf.DUMMYFUNCTION("IFERROR((MAX(FILTER({'食譜'!$K$3:$K$1000; '食譜'!$M$3:$M$1000; '食譜'!$O$3:$O$1000; '食譜'!$Q$3:$Q$1000}, {'食譜'!$J$3:$J$1000; '食譜'!$L$3:$L$1000; '食譜'!$N$3:$N$1000; '食譜'!$P$3:$P$1000} = $D17))), """")"),27.0) -> 27 | J17: =IFERROR(__xludf.DUMMYFUNCTION("IFERROR(INDEX(FILTER({'食譜'!$B$3:$B$1000; '食譜'!$B$3:$B$1000; '食譜'!$B$3:$B$1000; '食譜'!$B$3:$B$1000}, {'食譜'!$J$3:$J$1000; '食譜'!$L$3:$L$1000; '食譜'!$N$3:$N$1000; '食譜'!$P$3:$P$1000}=D17, {'食譜'!$K$3:$K$1000; '食譜'!$M$3:$M$1000; '食譜'!$O$3:$O$1000; '食譜'!$Q$3:$Q$100"&"0}=MAX(FILTER({'食譜'!$K$3:$K$1000; '食譜'!$M$3:$M$1000; '食譜'!$O$3:$O$1000; '食譜'!$Q$3:$Q$1000}, {'食譜'!$J$3:$J$1000; '食譜'!$L$3:$L$1000; '食譜'!$N$3:$N$1000; '食譜'!$P$3:$P$1000}=D17))), 1), """")"),"大塊滿滿熱水沙拉") -> 大塊滿滿熱水沙拉 | K17: =I17*3 -> 81 | L17: =F17/K17 -> 0.57728395 | M17: =G17/K17 -> 1.1440741
A18: =IFERROR(__xludf.DUMMYFUNCTION("""COMPUTED_VALUE"""),185.0) -> 185 | B18: =IFERROR(__xludf.DUMMYFUNCTION("""COMPUTED_VALUE"""),"Large Leek") -> Large Leek | C18: =IFERROR(__xludf.DUMMYFUNCTION("""COMPUTED_VALUE"""),1.0) -> 1 | D18: =IFERROR(__xludf.DUMMYFUNCTION("""COMPUTED_VALUE"""),"粗枝大蔥") -> 粗枝大蔥 | E18: =IFERROR(__xludf.DUMMYFUNCTION("""COMPUTED_VALUE"""),"") | F18: =IFERROR(__xludf.DUMMYFUNCTION("""COMPUTED_VALUE"""),54.58) -> 54.58 | G18: =IFERROR(VLOOKUP(D18, '應用日產（AP）'!A:C, 3, FALSE), 0) -> 87.81 | H18: =F18/G18 -> 0.6215693 | I18: =IFERROR(__xludf.DUMMYFUNCTION("IFERROR((MAX(FILTER({'食譜'!$K$3:$K$1000; '食譜'!$M$3:$M$1000; '食譜'!$O$3:$O$1000; '食譜'!$Q$3:$Q$1000}, {'食譜'!$J$3:$J$1000; '食譜'!$L$3:$L$1000; '食譜'!$N$3:$N$1000; '食譜'!$P$3:$P$1000} = $D18))), """")"),27.0) -> 27 | J18: =IFERROR(__xludf.DUMMYFUNCTION("IFERROR(INDEX(FILTER({'食譜'!$B$3:$B$1000; '食譜'!$B$3:$B$1000; '食譜'!$B$3:$B$1000; '食譜'!$B$3:$B$1000}, {'食譜'!$J$3:$J$1000; '食譜'!$L$3:$L$1000; '食譜'!$N$3:$N$1000; '食譜'!$P$3:$P$1000}=D18, {'食譜'!$K$3:$K$1000; '食譜'!$M$3:$M$1000; '食譜'!$O$3:$O$1000; '食譜'!$Q$3:$Q$100"&"0}=MAX(FILTER({'食譜'!$K$3:$K$1000; '食譜'!$M$3:$M$1000; '食譜'!$O$3:$O$1000; '食譜'!$Q$3:$Q$1000}, {'食譜'!$J$3:$J$1000; '食譜'!$L$3:$L$1000; '食譜'!$N$3:$N$1000; '食譜'!$P$3:$P$1000}=D18))), 1), """")"),"居合斬壽喜燒咖哩") -> 居合斬壽喜燒咖哩 | K18: =I18*3 -> 81 | L18: =F18/K18 -> 0.67382716 | M18: =G18/K18 -> 1.0840741
A19: =IFERROR(__xludf.DUMMYFUNCTION("""COMPUTED_VALUE"""),250.0) -> 250 | B19: =IFERROR(__xludf.DUMMYFUNCTION("""COMPUTED_VALUE"""),"Plump Pumpkin") -> Plump Pumpkin | C19: =IFERROR(__xludf.DUMMYFUNCTION("""COMPUTED_VALUE"""),18.0) -> 18 | D19: =IFERROR(__xludf.DUMMYFUNCTION("""COMPUTED_VALUE"""),"沉甸甸南瓜") -> 沉甸甸南瓜 | E19: =IFERROR(__xludf.DUMMYFUNCTION("""COMPUTED_VALUE"""),"") | F19: =IFERROR(__xludf.DUMMYFUNCTION("""COMPUTED_VALUE"""),1.0) -> 1 | G19: =IFERROR(VLOOKUP(D19, '應用日產（AP）'!A:C, 3, FALSE), 0) -> 63.05 | H19: =F19/G19 -> 0.015860428 | I19: =IFERROR(__xludf.DUMMYFUNCTION("IFERROR((MAX(FILTER({'食譜'!$K$3:$K$1000; '食譜'!$M$3:$M$1000; '食譜'!$O$3:$O$1000; '食譜'!$Q$3:$Q$1000}, {'食譜'!$J$3:$J$1000; '食譜'!$L$3:$L$1000; '食譜'!$N$3:$N$1000; '食譜'!$P$3:$P$1000} = $D19))), """")"),20.0) -> 20 | J19: =IFERROR(__xludf.DUMMYFUNCTION("IFERROR(INDEX(FILTER({'食譜'!$B$3:$B$1000; '食譜'!$B$3:$B$1000; '食譜'!$B$3:$B$1000; '食譜'!$B$3:$B$1000}, {'食譜'!$J$3:$J$1000; '食譜'!$L$3:$L$1000; '食譜'!$N$3:$N$1000; '食譜'!$P$3:$P$1000}=D19, {'食譜'!$K$3:$K$1000; '食譜'!$M$3:$M$1000; '食譜'!$O$3:$O$1000; '食譜'!$Q$3:$Q$100"&"0}=MAX(FILTER({'食譜'!$K$3:$K$1000; '食譜'!$M$3:$M$1000; '食譜'!$O$3:$O$1000; '食譜'!$Q$3:$Q$1000}, {'食譜'!$J$3:$J$1000; '食譜'!$L$3:$L$1000; '食譜'!$N$3:$N$1000; '食譜'!$P$3:$P$1000}=D19))), 1), """")"),"大塊滿滿熱水沙拉") -> 大塊滿滿熱水沙拉 | K19: =I19*3 -> 60 | L19: =F19/K19 -> 0.016666667 | M19: =G19/K19 -> 1.0508333
A20: =IFERROR(__xludf.DUMMYFUNCTION("""COMPUTED_VALUE"""),342.0) -> 342 | B20: =IFERROR(__xludf.DUMMYFUNCTION("""COMPUTED_VALUE"""),"Slowpoke Tail") -> Slowpoke Tail | C20: =IFERROR(__xludf.DUMMYFUNCTION("""COMPUTED_VALUE"""),14.0) -> 14 | D20: =IFERROR(__xludf.DUMMYFUNCTION("""COMPUTED_VALUE"""),"美味尾巴") -> 美味尾巴 | E20: =IFERROR(__xludf.DUMMYFUNCTION("""COMPUTED_VALUE"""),"") | F20: =IFERROR(__xludf.DUMMYFUNCTION("""COMPUTED_VALUE"""),1.0) -> 1 | G20: =IFERROR(VLOOKUP(D20, '應用日產（AP）'!A:C, 3, FALSE), 0) -> 17.35 | H20: =F20/G20 -> 0.057636888 | I20: =IFERROR(__xludf.DUMMYFUNCTION("IFERROR((MAX(FILTER({'食譜'!$K$3:$K$1000; '食譜'!$M$3:$M$1000; '食譜'!$O$3:$O$1000; '食譜'!$Q$3:$Q$1000}, {'食譜'!$J$3:$J$1000; '食譜'!$L$3:$L$1000; '食譜'!$N$3:$N$1000; '食譜'!$P$3:$P$1000} = $D20))), """")"),10.0) -> 10 | J20: =IFERROR(__xludf.DUMMYFUNCTION("IFERROR(INDEX(FILTER({'食譜'!$B$3:$B$1000; '食譜'!$B$3:$B$1000; '食譜'!$B$3:$B$1000; '食譜'!$B$3:$B$1000}, {'食譜'!$J$3:$J$1000; '食譜'!$L$3:$L$1000; '食譜'!$N$3:$N$1000; '食譜'!$P$3:$P$1000}=D20, {'食譜'!$K$3:$K$1000; '食譜'!$M$3:$M$1000; '食譜'!$O$3:$O$1000; '食譜'!$Q$3:$Q$100"&"0}=MAX(FILTER({'食譜'!$K$3:$K$1000; '食譜'!$M$3:$M$1000; '食譜'!$O$3:$O$1000; '食譜'!$Q$3:$Q$1000}, {'食譜'!$J$3:$J$1000; '食譜'!$L$3:$L$1000; '食譜'!$N$3:$N$1000; '食譜'!$P$3:$P$1000}=D20))), 1), """")"),"呆呆獸尾巴的胡椒沙拉") -> 呆呆獸尾巴的胡椒沙拉 | K20: =I20*3 -> 30 | L20: =F20/K20 -> 0.033333333 | M20: =G20/K20 -> 0.57833333

Sheet 我的料理效率
K2: 食材 | L2: 日產 | M2: 超產能力 | N2: 日佔位 | O2: 隊伍 | P2: 實際運作 | Q2: 爆擊修正 | T2: 已選擇料理 | U2: 已定義幫獎環境 | V2: MP隊伍總佔位 | W2: 料理效率
A3: AP/BLD | B3: BLD/AP | C3: Time | D3: AP | E3: BLD | I3: {=LET(last_row,IFERROR(LOOKUP(2,1/('我的食材檔案'!J2:J1000<>""),ROW('我的食材檔案'!J2:J1000)),2),ing_r,INDIRECT("'我的食材檔案'!D2:D"&last_row),ico_r,INDIRECT("'我的食材檔案'!A2:A"&last_row),IFERROR(INDEX(ico_r,MATCH(H3,ing_r,0)),""))} | J3: 需 | K3: 佔比 | L3: MP | M3: MP/BLD | N3: BLD/MP | O3: {="幫獎："& IFERROR(XLOOKUP(H8, T:T, U:U, "N/A"), "0")} -> 幫獎：1 | P3: Time | Q3: ="倍率："& $U$14 -> 倍率：0.1 | T3: {='我的食材隊檔案'!D35:D44} -> 覺醒力量濃湯 | U3: {='我的食材隊檔案'!F35:F44} -> 1 | V3: =IFERROR(O8, "") -> 3.4114181 | W3: =IFERROR(R8, "") -> 18438.461
A4: {=IFERROR(XLOOKUP($H8, '計算公式'!$B:$B, '計算公式'!E:E), "")} -> 1.7696429 | B4: {=IFERROR(XLOOKUP($H8, '計算公式'!$B:$B, '計算公式'!F:F), "")} -> 0.56508577 | C4: {=IFERROR(XLOOKUP($H8, '計算公式'!$B:$B, '計算公式'!G:G), "")} -> 13h 33m | D4: {=IFERROR(XLOOKUP($H$8, '計算公式'!$B:$B, '計算公式'!C:C), "")} -> 148.65 | E4: {=IFERROR(XLOOKUP($H8, '計算公式'!$B:$B, '計算公式'!D:D), "")} -> 84 | F4: {=IFERROR(XLOOKUP($G4, ing_name, ing_energy), "")} -> 100 | G4: {=IFERROR(XLOOKUP($H8, '食譜'!$B:$B, '食譜'!$J:$J), "")} -> 萌綠大豆 | H4: {=IFERROR(XLOOKUP(H8, '食譜'!B:B, '食譜'!A:A), "")} | I4: {=IFERROR(XLOOKUP($G4, ing_name, ing_ico), "")} | J4: {=IFERROR(XLOOKUP($H8, '食譜'!$B:$B, '食譜'!$K:$K), "")} -> 28 | K4: =J4*F4/$G$8 -> 0.23650646 | L4: {=IFERROR(XLOOKUP($G4, ing_name, my_prod), "")} -> 109.12 | M4: =L4/E4 -> 1.2990476 | N4: =E4/L4 -> 0.76979472 | O4: {=N4/(1/(1-(0.05)*IFERROR(XLOOKUP($H8, $T:$T, $U:$U, "N/A"), "")))} -> 0.73130499 | P4: =IFERROR(INT(O4*24)&"h "&INT(MOD(O4*24,1)*60)&"m", "") -> 17h 33m | T4: 居合斬壽喜燒咖哩 | U4: 5.1 | V4: =IFERROR(O18, "") -> 2.3762779 | W4: =IFERROR(R18, "") -> 28684.146
A5: {=IFERROR(XLOOKUP($H$8, '計算公式'!$B:$B, '計算公式'!J:J), "")} -> 1.8341333 | B5: {=IFERROR(XLOOKUP($H$8, '計算公式'!$B:$B, '計算公式'!K:K), "")} -> 0.54521663 | C5: {=IFERROR(XLOOKUP($H$8, '計算公式'!$B:$B, '計算公式'!L:L), "")} -> 13h 5m | D5: {=IFERROR(XLOOKUP($H$8, '計算公式'!$B:$B, '計算公式'!H:H), "")} -> 137.56 | E5: {=IFERROR(XLOOKUP($H$8, '計算公式'!$B:$B, '計算公式'!I:I), "")} -> 75 | F5: {=IFERROR(XLOOKUP($G5, ing_name, ing_energy), "")} -> 110 | G5: {=IFERROR(XLOOKUP($H8, '食譜'!$B:$B, '食譜'!$L:$L), "")} -> 好眠番茄 | I5: {=IFERROR(XLOOKUP($G5, ing_name, ing_ico), "")} | J5: {=IFERROR(XLOOKUP($H8, '食譜'!$B:$B, '食譜'!$M:$M), "")} -> 25 | K5: =J5*F5/$G$8 -> 0.23228313 | L5: {=IFERROR(XLOOKUP($G5, ing_name, my_prod), "")} -> 98.54 | M5: =L5/E5 -> 1.3138667 | N5: =E5/L5 -> 0.76111224 | O5: {=N5/(1/(1-(0.05)*IFERROR(XLOOKUP($H8, $T:$T, $U:$U, "N/A"), "")))} -> 0.72305663 | P5: =IFERROR(INT(O5*24)&"h "&INT(MOD(O5*24,1)*60)&"m", "") -> 17h 21m | T5: 茂盛焗烤酪梨 | U5: 1 | V5: =IFERROR(O28, "") -> 2.7617384 | W5: =IFERROR(R28, "") -> 29635.899
A6: {=IFERROR(XLOOKUP($H$8, '計算公式'!$B:$B, '計算公式'!O:O), "")} -> 1.3430435 | B6: {=IFERROR(XLOOKUP($H$8, '計算公式'!$B:$B, '計算公式'!P:P), "")} -> 0.74457753 | C6: {=IFERROR(XLOOKUP($H$8, '計算公式'!$B:$B, '計算公式'!Q:Q), "")} -> 17h 52m | D6: {=IFERROR(XLOOKUP($H$8, '計算公式'!$B:$B, '計算公式'!M:M), "")} -> 92.67 | E6: {=IFERROR(XLOOKUP($H$8, '計算公式'!$B:$B, '計算公式'!N:N), "")} -> 69 | F6: {=IFERROR(XLOOKUP($G6, ing_name, ing_energy), "")} -> 167 | G6: {=IFERROR(XLOOKUP($H8, '食譜'!$B:$B, '食譜'!$N:$N), "")} -> 品鮮蘑菇 | I6: {=IFERROR(XLOOKUP($G6, ing_name, ing_ico), "")} | J6: {=IFERROR(XLOOKUP($H8, '食譜'!$B:$B, '食譜'!$O:$O), "")} -> 23 | K6: =J6*F6/$G$8 -> 0.32443619 | L6: {=IFERROR(XLOOKUP($G6, ing_name, my_prod), "")} -> 46.76 | M6: =L6/E6 -> 0.67768116 | N6: =E6/L6 -> 1.4756202 | O6: {=N6/(1/(1-(0.05)*IFERROR(XLOOKUP($H8, $T:$T, $U:$U, "N/A"), "")))} -> 1.4018392 | P6: =IFERROR(INT(O6*24)&"h "&INT(MOD(O6*24,1)*60)&"m", "") -> 33h 38m | T6: 重踏酪梨醬脆片 | U6: 0 | V6: =IFERROR(O38, "") -> 2.5153125 | W6: =IFERROR(R38, "") -> 33011.643
A7: {=IFERROR(XLOOKUP($H$8, '計算公式'!$B:$B, '計算公式'!T:T), "")} -> 2.3789583 | B7: {=IFERROR(XLOOKUP($H$8, '計算公式'!$B:$B, '計算公式'!U:U), "")} -> 0.42035204 | C7: {=IFERROR(XLOOKUP($H$8, '計算公式'!$B:$B, '計算公式'!V:V), "")} -> 10h 5m | D7: {=IFERROR(XLOOKUP($H$8, '計算公式'!$B:$B, '計算公式'!R:R), "")} -> 114.19 | E7: {=IFERROR(XLOOKUP($H$8, '計算公式'!$B:$B, '計算公式'!S:S), "")} -> 48 | F7: {=IFERROR(XLOOKUP($G7, ing_name, ing_energy), "")} -> 153 | G7: {=IFERROR(XLOOKUP($H8, '食譜'!$B:$B, '食譜'!P:P), "")} -> 醒腦咖啡豆 | I7: {=IFERROR(XLOOKUP($G7, ing_name, ing_ico), "")} | J7: {=IFERROR(XLOOKUP($H8, '食譜'!$B:$B, '食譜'!$Q:$Q), "")} -> 16 | K7: =J7*F7/$G$8 -> 0.20677422 | L7: {=IFERROR(XLOOKUP($G7, ing_name, my_prod), "")} -> 82.13 | M7: =L7/E7 -> 1.7110417 | N7: =E7/L7 -> 0.5844393 | O7: {=N7/(1/(1-(0.05)*IFERROR(XLOOKUP($H8, $T:$T, $U:$U, "N/A"), "")))} -> 0.55521734 | P7: =IFERROR(INT(O7*24)&"h "&INT(MOD(O7*24,1)*60)&"m", "") -> 13h 19m | T7: 蘋果酸優格沙拉 | U7: 1 | V7: =IFERROR(O48, "") -> 2.9889112 | W7: =IFERROR(R48, "") -> 21301.034
G8: {=IFERROR(XLOOKUP($H8, '食譜'!$B:$B, '食譜'!$G:$G), "")} -> 11839 | H8: =T3 -> 覺醒力量濃湯 | J8: =SUM(J4:J7) -> 92 | K8: 1 | L8: {=IFERROR(XLOOKUP($G8, ing_name, my_prod), "")} | N8: =sum(N4:N7) -> 3.5909665 | O8: =N8/(1/(1-(0.05)*U7)) -> 3.4114181 | P8: =IFERROR(INT(O8*24)&"h "&INT(MOD(O8*24,1)*60)&"m", "") -> 81h 52m | Q8: {=IFERROR(XLOOKUP($H8, '食譜'!$B:$B, '食譜'!$H:$H), "")*(3+U14*3)} -> 62901.3 | R8: =Q8/O8 -> 18438.461 | T8: 不服輸咖啡沙拉 | U8: 2 | V8: =IFERROR(O58, "") -> 3.1340789 | W8: =IFERROR(R58, "") -> 21288.36
H9: {="料理能量："&IFERROR(XLOOKUP($H8, '食譜'!$B:$B, '食譜'!$H:$H), "")} -> 料理能量：19061 | N9: 總佔位 | O9: 倍率修正 | P9: 總需時 | Q9: 總料理能量 | R9: 料理效率 | T9: 採蜜巧克力格子鬆餅 | U9: 1 | V9: =IFERROR(O68, "") -> 3.0845257 | W9: =IFERROR(R68, "") -> 27264.224
T10: 心跳加速鬼面鬆餅 | U10: 2 | V10: =IFERROR(O78, "") -> 50.198697 | W10: =IFERROR(R78, "") -> 1601.0017
T11: 土王閃電泡芙 | U11: 0 | V11: =IFERROR(O88, "") -> 2.9599204 | W11: =IFERROR(R88, "") -> 23284.579
K12: 食材 | L12: 日產 | M12: 超產能力 | N12: 日佔位 | O12: 隊伍 | P12: 實際運作 | Q12: 爆擊修正 | T12: 電光香料可樂 | U12: 0 | V12: =IFERROR(O98, "") -> 3.761586 | W12: =IFERROR(R98, "") -> 15347.303
A13: AP/BLD | B13: BLD/AP | C13: Time | D13: AP | E13: BLD | I13: {=LET(last_row,IFERROR(LOOKUP(2,1/('我的食材檔案'!J12:J1010<>""),ROW('我的食材檔案'!J12:J1010)),2),ing_r,INDIRECT("'我的食材檔案'!D2:D"&last_row),ico_r,INDIRECT("'我的食材檔案'!A2:A"&last_row),IFERROR(INDEX(ico_r,MATCH(H13,ing_r,0)),""))} | J13: 需 | K13: 佔比 | L13: MP | M13: MP/BLD | N13: BLD/MP | O13: {="幫獎："& IFERROR(XLOOKUP(H18, T:T, U:U, "N/A"), "0")} -> 幫獎：5.1 | P13: Time | Q13: ="倍率："& $U$14 -> 倍率：0.1
A14: {=IFERROR(XLOOKUP($H18, '計算公式'!$B:$B, '計算公式'!E:E), "")} -> 1.0840741 | B14: {=IFERROR(XLOOKUP($H18, '計算公式'!$B:$B, '計算公式'!F:F), "")} -> 0.92244619 | C14: {=IFERROR(XLOOKUP($H18, '計算公式'!$B:$B, '計算公式'!G:G), "")} -> 22h 8m | D14: {=IFERROR(XLOOKUP($H$8, '計算公式'!$B:$B, '計算公式'!C:C), "")} -> 148.65 | E14: {=IFERROR(XLOOKUP($H18, '計算公式'!$B:$B, '計算公式'!D:D), "")} -> 81 | F14: {=IFERROR(XLOOKUP($G14, ing_name, ing_energy), "")} -> 185 | G14: {=IFERROR(XLOOKUP($H18, '食譜'!$B:$B, '食譜'!$J:$J), "")} -> 粗枝大蔥 | H14: {=IFERROR(XLOOKUP(H18, '食譜'!B:B, '食譜'!A:A), "")} | I14: {=IFERROR(XLOOKUP($G14, ing_name, ing_ico), "")} | J14: {=IFERROR(XLOOKUP($H18, '食譜'!$B:$B, '食譜'!$K:$K), "")} -> 27 | K14: =J14*F14/$G$8 -> 0.42191063 | L14: {=IFERROR(XLOOKUP($G14, ing_name, my_prod), "")} -> 54.58 | M14: =L14/E14 -> 0.67382716 | N14: =E14/L14 -> 1.4840601 | O14: {=N14/(1/(1-(0.05)*IFERROR(XLOOKUP($H18, $T:$T, $U:$U, "N/A"), "")))} -> 1.1056248 | P14: =IFERROR(INT(O14*24)&"h "&INT(MOD(O14*24,1)*60)&"m", "") -> 26h 32m | T14: 爆擊倍率 | U14: 0.1 | V14: AP隊伍總佔位 | W14: 料理效率
A15: {=IFERROR(XLOOKUP($H$8, '計算公式'!$B:$B, '計算公式'!J:J), "")} -> 1.8341333 | B15: {=IFERROR(XLOOKUP($H$8, '計算公式'!$B:$B, '計算公式'!K:K), "")} -> 0.54521663 | C15: {=IFERROR(XLOOKUP($H$8, '計算公式'!$B:$B, '計算公式'!L:L), "")} -> 13h 5m | D15: {=IFERROR(XLOOKUP($H$8, '計算公式'!$B:$B, '計算公式'!H:H), "")} -> 137.56 | E15: {=IFERROR(XLOOKUP($H$8, '計算公式'!$B:$B, '計算公式'!I:I), "")} -> 75 | F15: {=IFERROR(XLOOKUP($G15, ing_name, ing_energy), "")} -> 103 | G15: {=IFERROR(XLOOKUP($H18, '食譜'!$B:$B, '食譜'!$L:$L), "")} -> 豆製肉 | I15: {=IFERROR(XLOOKUP($G15, ing_name, ing_ico), "")} | J15: {=IFERROR(XLOOKUP($H18, '食譜'!$B:$B, '食譜'!$M:$M), "")} -> 26 | K15: =J15*F15/$G$8 -> 0.22620154 | L15: {=IFERROR(XLOOKUP($G15, ing_name, my_prod), "")} -> 105.53 | M15: =L15/E15 -> 1.4070667 | N15: =E15/L15 -> 0.71069838 | O15: {=N15/(1/(1-(0.05)*IFERROR(XLOOKUP($H18, $T:$T, $U:$U, "N/A"), "")))} -> 0.52947029 | P15: =IFERROR(INT(O15*24)&"h "&INT(MOD(O15*24,1)*60)&"m", "") -> 12h 42m | V15: {=IFERROR(XLOOKUP($T3, '計算公式'!$B:$B, '計算公式'!X:X), "")} -> 2.275232 | W15: =IFERROR(Q8, "")/V15 -> 27646.104
A16: {=IFERROR(XLOOKUP($H$8, '計算公式'!$B:$B, '計算公式'!O:O), "")} -> 1.3430435 | B16: {=IFERROR(XLOOKUP($H$8, '計算公式'!$B:$B, '計算公式'!P:P), "")} -> 0.74457753 | C16: {=IFERROR(XLOOKUP($H$8, '計算公式'!$B:$B, '計算公式'!Q:Q), "")} -> 17h 52m | D16: {=IFERROR(XLOOKUP($H$8, '計算公式'!$B:$B, '計算公式'!M:M), "")} -> 92.67 | E16: {=IFERROR(XLOOKUP($H$8, '計算公式'!$B:$B, '計算公式'!N:N), "")} -> 69 | F16: {=IFERROR(XLOOKUP($G16, ing_name, ing_energy), "")} -> 101 | G16: {=IFERROR(XLOOKUP($H18, '食譜'!$B:$B, '食譜'!$N:$N), "")} -> 甜甜蜜 | I16: {=IFERROR(XLOOKUP($G16, ing_name, ing_ico), "")} | J16: {=IFERROR(XLOOKUP($H18, '食譜'!$B:$B, '食譜'!$O:$O), "")} -> 26 | K16: =J16*F16/$G$8 -> 0.22180927 | L16: {=IFERROR(XLOOKUP($G16, ing_name, my_prod), "")} -> 146.31 | M16: =L16/E16 -> 2.1204348 | N16: =E16/L16 -> 0.47160139 | O16: {=N16/(1/(1-(0.05)*IFERROR(XLOOKUP($H18, $T:$T, $U:$U, "N/A"), "")))} -> 0.35134304 | P16: =IFERROR(INT(O16*24)&"h "&INT(MOD(O16*24,1)*60)&"m", "") -> 8h 25m | V16: {=IFERROR(XLOOKUP($T4, '計算公式'!$B:$B, '計算公式'!X:X), "")} -> 2.4343651 | W16: =IFERROR(Q18, "")/V15 -> 29958.044
A17: {=IFERROR(XLOOKUP($H$8, '計算公式'!$B:$B, '計算公式'!T:T), "")} -> 2.3789583 | B17: {=IFERROR(XLOOKUP($H$8, '計算公式'!$B:$B, '計算公式'!U:U), "")} -> 0.42035204 | C17: {=IFERROR(XLOOKUP($H$8, '計算公式'!$B:$B, '計算公式'!V:V), "")} -> 10h 5m | D17: {=IFERROR(XLOOKUP($H$8, '計算公式'!$B:$B, '計算公式'!R:R), "")} -> 114.19 | E17: {=IFERROR(XLOOKUP($H$8, '計算公式'!$B:$B, '計算公式'!S:S), "")} -> 48 | F17: {=IFERROR(XLOOKUP($G17, ing_name, ing_energy), "")} -> 115 | G17: {=IFERROR(XLOOKUP($H18, '食譜'!$B:$B, '食譜'!P:P), "")} -> 特選蛋 | I17: {=IFERROR(XLOOKUP($G17, ing_name, ing_ico), "")} | J17: {=IFERROR(XLOOKUP($H18, '食譜'!$B:$B, '食譜'!$Q:$Q), "")} -> 22 | K17: =J17*F17/$G$8 -> 0.21370048 | L17: {=IFERROR(XLOOKUP($G17, ing_name, my_prod), "")} -> 91.73 | M17: =L17/E17 -> 1.9110417 | N17: =E17/L17 -> 0.52327483 | O17: {=N17/(1/(1-(0.05)*IFERROR(XLOOKUP($H18, $T:$T, $U:$U, "N/A"), "")))} -> 0.38983975 | P17: =IFERROR(INT(O17*24)&"h "&INT(MOD(O17*24,1)*60)&"m", "") -> 9h 21m | V17: {=IFERROR(XLOOKUP($T5, '計算公式'!$B:$B, '計算公式'!X:X), "")} -> 2.7472212 | W17: =IFERROR(Q28, "")/V15 -> 35972.859
G18: {=IFERROR(XLOOKUP($H18, '食譜'!$B:$B, '食譜'!$G:$G), "")} -> 12829 | H18: =T4 -> 居合斬壽喜燒咖哩 | J18: =SUM(J14:J17) -> 101 | K18: 1 | L18: {=IFERROR(XLOOKUP($G18, ing_name, my_prod), "")} | N18: =sum(N14:N17) -> 3.1896347 | O18: =N18/(1/(1-(0.05)*U4)) -> 2.3762779 | P18: =IFERROR(INT(O18*24)&"h "&INT(MOD(O18*24,1)*60)&"m", "") -> 57h 1m | Q18: {=IFERROR(XLOOKUP($H18, '食譜'!$B:$B, '食譜'!$H:$H), "")*(3+U14*3)} -> 68161.5 | R18: =Q18/O18 -> 28684.146 | V18: {=IFERROR(XLOOKUP($T6, '計算公式'!$B:$B, '計算公式'!X:X), "")} -> 2.3302145 | W18: =IFERROR(Q38, "")/V15 -> 36495.004
H19: {="料理能量："&IFERROR(XLOOKUP($H18, '食譜'!$B:$B, '食譜'!$H:$H), "")} -> 料理能量：20655 | N19: 總佔位 | O19: 倍率修正 | P19: 總需時 | Q19: 總料理能量 | R19: 料理效率 | V19: {=IFERROR(XLOOKUP($T7, '計算公式'!$B:$B, '計算公式'!X:X), "")} -> 2.1735044 | W19: =IFERROR(Q48, "")/V15 -> 27982.597
V20: {=IFERROR(XLOOKUP($T8, '計算公式'!$B:$B, '計算公式'!X:X), "")} -> 2.411168 | W20: =IFERROR(Q58, "")/V15 -> 29324.219
V21: {=IFERROR(XLOOKUP($T9, '計算公式'!$B:$B, '計算公式'!X:X), "")} -> 2.7470476 | W21: =IFERROR(Q68, "")/V15 -> 36962.033
K22: 食材 | L22: 日產 | M22: 超產能力 | N22: 日佔位 | O22: 隊伍 | P22: 實際運作 | Q22: 爆擊修正 | V22: {=IFERROR(XLOOKUP($T10, '計算公式'!$B:$B, '計算公式'!X:X), "")} -> 2.6676962 | W22: =IFERROR(Q78, "")/V15 -> 35323.079
A23: AP/BLD | B23: BLD/AP | C23: Time | D23: AP | E23: BLD | I23: {=LET(last_row,IFERROR(LOOKUP(2,1/('我的食材檔案'!J22:J1020<>""),ROW('我的食材檔案'!J22:J1020)),2),ing_r,INDIRECT("'我的食材檔案'!D2:D"&last_row),ico_r,INDIRECT("'我的食材檔案'!A2:A"&last_row),IFERROR(INDEX(ico_r,MATCH(H23,ing_r,0)),""))} | J23: 需 | K23: 佔比 | L23: MP | M23: MP/BLD | N23: BLD/MP | O23: {="幫獎："& IFERROR(XLOOKUP(H28, T:T, U:U, "N/A"), "0")} -> 幫獎：1 | P23: Time | Q23: ="倍率："& $U$14 -> 倍率：0.1 | V23: {=IFERROR(XLOOKUP($T11, '計算公式'!$B:$B, '計算公式'!X:X), "")} -> 2.4473603 | W23: =IFERROR(Q88, "")/V15 -> 30291.636
A24: {=IFERROR(XLOOKUP($H28, '計算公式'!$B:$B, '計算公式'!E:E), "")} -> 1.6004545 | B24: {=IFERROR(XLOOKUP($H28, '計算公式'!$B:$B, '計算公式'!F:F), "")} -> 0.62482249 | C24: {=IFERROR(XLOOKUP($H28, '計算公式'!$B:$B, '計算公式'!G:G), "")} -> 14h 59m | D24: {=IFERROR(XLOOKUP($H$8, '計算公式'!$B:$B, '計算公式'!C:C), "")} -> 148.65 | E24: {=IFERROR(XLOOKUP($H28, '計算公式'!$B:$B, '計算公式'!D:D), "")} -> 66 | F24: {=IFERROR(XLOOKUP($G24, ing_name, ing_energy), "")} -> 162 | G24: {=IFERROR(XLOOKUP($H28, '食譜'!$B:$B, '食譜'!$J:$J), "")} -> 嫩亮酪梨 | H24: {=IFERROR(XLOOKUP(H28, '食譜'!B:B, '食譜'!A:A), "")} | I24: {=IFERROR(XLOOKUP($G24, ing_name, ing_ico), "")} | J24: {=IFERROR(XLOOKUP($H28, '食譜'!$B:$B, '食譜'!$K:$K), "")} -> 22 | K24: =J24*F24/$G$8 -> 0.30103894 | L24: {=IFERROR(XLOOKUP($G24, ing_name, my_prod), "")} -> 100 | M24: =L24/E24 -> 1.5151515 | N24: =E24/L24 -> 0.66 | O24: {=N24/(1/(1-(0.05)*IFERROR(XLOOKUP($H28, $T:$T, $U:$U, "N/A"), "")))} -> 0.627 | P24: =IFERROR(INT(O24*24)&"h "&INT(MOD(O24*24,1)*60)&"m", "") -> 15h 2m | V24: {=IFERROR(XLOOKUP($T12, '計算公式'!$B:$B, '計算公式'!X:X), "")} -> 2.0098084 | W24: =IFERROR(Q98, "")/V15 -> 25373.325
A25: {=IFERROR(XLOOKUP($H$8, '計算公式'!$B:$B, '計算公式'!J:J), "")} -> 1.8341333 | B25: {=IFERROR(XLOOKUP($H$8, '計算公式'!$B:$B, '計算公式'!K:K), "")} -> 0.54521663 | C25: {=IFERROR(XLOOKUP($H$8, '計算公式'!$B:$B, '計算公式'!L:L), "")} -> 13h 5m | D25: {=IFERROR(XLOOKUP($H$8, '計算公式'!$B:$B, '計算公式'!H:H), "")} -> 137.56 | E25: {=IFERROR(XLOOKUP($H$8, '計算公式'!$B:$B, '計算公式'!I:I), "")} -> 75 | F25: {=IFERROR(XLOOKUP($G25, ing_name, ing_energy), "")} -> 124 | G25: {=IFERROR(XLOOKUP($H28, '食譜'!$B:$B, '食譜'!$L:$L), "")} -> 窩心洋芋 | I25: {=IFERROR(XLOOKUP($G25, ing_name, ing_ico), "")} | J25: {=IFERROR(XLOOKUP($H28, '食譜'!$B:$B, '食譜'!$M:$M), "")} -> 20 | K25: =J25*F25/$G$8 -> 0.20947715 | L25: {=IFERROR(XLOOKUP($G25, ing_name, my_prod), "")} -> 90.57 | M25: =L25/E25 -> 1.2076 | N25: =E25/L25 -> 0.82808877 | O25: {=N25/(1/(1-(0.05)*IFERROR(XLOOKUP($H28, $T:$T, $U:$U, "N/A"), "")))} -> 0.78668433 | P25: =IFERROR(INT(O25*24)&"h "&INT(MOD(O25*24,1)*60)&"m", "") -> 18h 52m
A26: {=IFERROR(XLOOKUP($H$8, '計算公式'!$B:$B, '計算公式'!O:O), "")} -> 1.3430435 | B26: {=IFERROR(XLOOKUP($H$8, '計算公式'!$B:$B, '計算公式'!P:P), "")} -> 0.74457753 | C26: {=IFERROR(XLOOKUP($H$8, '計算公式'!$B:$B, '計算公式'!Q:Q), "")} -> 17h 52m | D26: {=IFERROR(XLOOKUP($H$8, '計算公式'!$B:$B, '計算公式'!M:M), "")} -> 92.67 | E26: {=IFERROR(XLOOKUP($H$8, '計算公式'!$B:$B, '計算公式'!N:N), "")} -> 69 | F26: {=IFERROR(XLOOKUP($G26, ing_name, ing_energy), "")} -> 98 | G26: {=IFERROR(XLOOKUP($H28, '食譜'!$B:$B, '食譜'!$N:$N), "")} -> 哞哞鮮奶 | I26: {=IFERROR(XLOOKUP($G26, ing_name, ing_ico), "")} | J26: {=IFERROR(XLOOKUP($H28, '食譜'!$B:$B, '食譜'!$O:$O), "")} -> 41 | K26: =J26*F26/$G$8 -> 0.33938677 | L26: {=IFERROR(XLOOKUP($G26, ing_name, my_prod), "")} -> 120.82 | M26: =L26/E26 -> 1.7510145 | N26: =E26/L26 -> 0.5710975 | O26: {=N26/(1/(1-(0.05)*IFERROR(XLOOKUP($H28, $T:$T, $U:$U, "N/A"), "")))} -> 0.54254263 | P26: =IFERROR(INT(O26*24)&"h "&INT(MOD(O26*24,1)*60)&"m", "") -> 13h 1m
A27: {=IFERROR(XLOOKUP($H$8, '計算公式'!$B:$B, '計算公式'!T:T), "")} -> 2.3789583 | B27: {=IFERROR(XLOOKUP($H$8, '計算公式'!$B:$B, '計算公式'!U:U), "")} -> 0.42035204 | C27: {=IFERROR(XLOOKUP($H$8, '計算公式'!$B:$B, '計算公式'!V:V), "")} -> 10h 5m | D27: {=IFERROR(XLOOKUP($H$8, '計算公式'!$B:$B, '計算公式'!R:R), "")} -> 114.19 | E27: {=IFERROR(XLOOKUP($H$8, '計算公式'!$B:$B, '計算公式'!S:S), "")} -> 48 | F27: {=IFERROR(XLOOKUP($G27, ing_name, ing_energy), "")} -> 121 | G27: {=IFERROR(XLOOKUP($H28, '食譜'!$B:$B, '食譜'!P:P), "")} -> 純粹油 | I27: {=IFERROR(XLOOKUP($G27, ing_name, ing_ico), "")} | J27: {=IFERROR(XLOOKUP($H28, '食譜'!$B:$B, '食譜'!$Q:$Q), "")} -> 32 | K27: =J27*F27/$G$8 -> 0.32705465 | L27: {=IFERROR(XLOOKUP($G27, ing_name, my_prod), "")} -> 56.61 | M27: =L27/E27 -> 1.179375 | N27: =E27/L27 -> 0.84790673 | O27: {=N27/(1/(1-(0.05)*IFERROR(XLOOKUP($H28, $T:$T, $U:$U, "N/A"), "")))} -> 0.80551139 | P27: =IFERROR(INT(O27*24)&"h "&INT(MOD(O27*24,1)*60)&"m", "") -> 19h 19m
G28: {=IFERROR(XLOOKUP($H28, '食譜'!$B:$B, '食譜'!$G:$G), "")} -> 13934 | H28: =T5 -> 茂盛焗烤酪梨 | J28: =SUM(J24:J27) -> 115 | K28: 1 | L28: {=IFERROR(XLOOKUP($G28, ing_name, my_prod), "")} | N28: =sum(N24:N27) -> 2.907093 | O28: =N28/(1/(1-(0.05)*U5)) -> 2.7617384 | P28: =IFERROR(INT(O28*24)&"h "&INT(MOD(O28*24,1)*60)&"m", "") -> 66h 16m | Q28: {=IFERROR(XLOOKUP($H28, '食譜'!$B:$B, '食譜'!$H:$H), "")*(3+U14*3)} -> 81846.6 | R28: =Q28/O28 -> 29635.899
H29: {="料理能量："&IFERROR(XLOOKUP($H28, '食譜'!$B:$B, '食譜'!$H:$H), "")} -> 料理能量：24802 | N29: 總佔位 | O29: 倍率修正 | P29: 總需時 | Q29: 總料理能量 | R29: 料理效率
K32: 食材 | L32: 日產 | M32: 超產能力 | N32: 日佔位 | O32: 隊伍 | P32: 實際運作 | Q32: 爆擊修正
A33: AP/BLD | B33: BLD/AP | C33: Time | D33: AP | E33: BLD | I33: {=LET(last_row,IFERROR(LOOKUP(2,1/('我的食材檔案'!J32:J1030<>""),ROW('我的食材檔案'!J32:J1030)),2),ing_r,INDIRECT("'我的食材檔案'!D2:D"&last_row),ico_r,INDIRECT("'我的食材檔案'!A2:A"&last_row),IFERROR(INDEX(ico_r,MATCH(H33,ing_r,0)),""))} | J33: 需 | K33: 佔比 | L33: MP | M33: MP/BLD | N33: BLD/MP | O33: {="幫獎："& IFERROR(XLOOKUP(H38, T:T, U:U, "N/A"), "0")} -> 幫獎：0 | P33: Time | Q33: ="倍率："& $U$14 -> 倍率：0.1
A34: {=IFERROR(XLOOKUP($H38, '計算公式'!$B:$B, '計算公式'!E:E), "")} -> 1.2575 | B34: {=IFERROR(XLOOKUP($H38, '計算公式'!$B:$B, '計算公式'!F:F), "")} -> 0.79522863 | C34: {=IFERROR(XLOOKUP($H38, '計算公式'!$B:$B, '計算公式'!G:G), "")} -> 19h 5m | D34: {=IFERROR(XLOOKUP($H$8, '計算公式'!$B:$B, '計算公式'!C:C), "")} -> 148.65 | E34: {=IFERROR(XLOOKUP($H38, '計算公式'!$B:$B, '計算公式'!D:D), "")} -> 84 | F34: {=IFERROR(XLOOKUP($G34, ing_name, ing_energy), "")} -> 162 | G34: {=IFERROR(XLOOKUP($H38, '食譜'!$B:$B, '食譜'!$J:$J), "")} -> 嫩亮酪梨 | H34: {=IFERROR(XLOOKUP(H38, '食譜'!B:B, '食譜'!A:A), "")} | I34: {=IFERROR(XLOOKUP($G34, ing_name, ing_ico), "")} | J34: {=IFERROR(XLOOKUP($H38, '食譜'!$B:$B, '食譜'!$K:$K), "")} -> 28 | K34: =J34*F34/$G$8 -> 0.38314047 | L34: {=IFERROR(XLOOKUP($G34, ing_name, my_prod), "")} -> 100 | M34: =L34/E34 -> 1.1904762 | N34: =E34/L34 -> 0.84 | O34: {=N34/(1/(1-(0.05)*IFERROR(XLOOKUP($H38, $T:$T, $U:$U, "N/A"), "")))} -> 0.84 | P34: =IFERROR(INT(O34*24)&"h "&INT(MOD(O34*24,1)*60)&"m", "") -> 20h 9m
A35: {=IFERROR(XLOOKUP($H$8, '計算公式'!$B:$B, '計算公式'!J:J), "")} -> 1.8341333 | B35: {=IFERROR(XLOOKUP($H$8, '計算公式'!$B:$B, '計算公式'!K:K), "")} -> 0.54521663 | C35: {=IFERROR(XLOOKUP($H$8, '計算公式'!$B:$B, '計算公式'!L:L), "")} -> 13h 5m | D35: {=IFERROR(XLOOKUP($H$8, '計算公式'!$B:$B, '計算公式'!H:H), "")} -> 137.56 | E35: {=IFERROR(XLOOKUP($H$8, '計算公式'!$B:$B, '計算公式'!I:I), "")} -> 75 | F35: {=IFERROR(XLOOKUP($G35, ing_name, ing_energy), "")} -> 140 | G35: {=IFERROR(XLOOKUP($H38, '食譜'!$B:$B, '食譜'!$L:$L), "")} -> 萌綠玉米 | I35: {=IFERROR(XLOOKUP($G35, ing_name, ing_ico), "")} | J35: {=IFERROR(XLOOKUP($H38, '食譜'!$B:$B, '食譜'!$M:$M), "")} -> 25 | K35: =J35*F35/$G$8 -> 0.29563308 | L35: {=IFERROR(XLOOKUP($G35, ing_name, my_prod), "")} -> 120.13 | M35: =L35/E35 -> 1.6017333 | N35: =E35/L35 -> 0.62432365 | O35: {=N35/(1/(1-(0.05)*IFERROR(XLOOKUP($H38, $T:$T, $U:$U, "N/A"), "")))} -> 0.62432365 | P35: =IFERROR(INT(O35*24)&"h "&INT(MOD(O35*24,1)*60)&"m", "") -> 14h 59m
A36: {=IFERROR(XLOOKUP($H$8, '計算公式'!$B:$B, '計算公式'!O:O), "")} -> 1.3430435 | B36: {=IFERROR(XLOOKUP($H$8, '計算公式'!$B:$B, '計算公式'!P:P), "")} -> 0.74457753 | C36: {=IFERROR(XLOOKUP($H$8, '計算公式'!$B:$B, '計算公式'!Q:Q), "")} -> 17h 52m | D36: {=IFERROR(XLOOKUP($H$8, '計算公式'!$B:$B, '計算公式'!M:M), "")} -> 92.67 | E36: {=IFERROR(XLOOKUP($H$8, '計算公式'!$B:$B, '計算公式'!N:N), "")} -> 69 | F36: {=IFERROR(XLOOKUP($G36, ing_name, ing_energy), "")} -> 130 | G36: {=IFERROR(XLOOKUP($H38, '食譜'!$B:$B, '食譜'!$N:$N), "")} -> 火辣香草 | I36: {=IFERROR(XLOOKUP($G36, ing_name, ing_ico), "")} | J36: {=IFERROR(XLOOKUP($H38, '食譜'!$B:$B, '食譜'!$O:$O), "")} -> 30 | K36: =J36*F36/$G$8 -> 0.32941971 | L36: {=IFERROR(XLOOKUP($G36, ing_name, my_prod), "")} -> 112.91 | M36: =L36/E36 -> 1.6363768 | N36: =E36/L36 -> 0.61110619 | O36: {=N36/(1/(1-(0.05)*IFERROR(XLOOKUP($H38, $T:$T, $U:$U, "N/A"), "")))} -> 0.61110619 | P36: =IFERROR(INT(O36*24)&"h "&INT(MOD(O36*24,1)*60)&"m", "") -> 14h 39m
